{
 "cells": [
  {
   "cell_type": "code",
   "execution_count": 1,
   "id": "50a471b0",
   "metadata": {},
   "outputs": [],
   "source": [
    "import numpy as np\n",
    "import pandas as pd\n",
    "\n",
    "from dash import Dash\n",
    "import dash_html_components as html\n",
    "import dash_core_components as dcc\n",
    "import dash_bootstrap_components as dbc\n",
    "import dash_table\n",
    "from dash.dependencies import Input,Output,State\n",
    "import plotly.express as px\n",
    "import plotly.graph_objects as go\n",
    "import dash"
   ]
  },
  {
   "cell_type": "code",
   "execution_count": 2,
   "id": "7e9f9147",
   "metadata": {},
   "outputs": [],
   "source": [
    "df_weather = pd.read_csv('C:/Users/admin/Desktop/Project/weather_a.csv')\n",
    "df_data = pd.read_csv('C:/Users/admin/Desktop/Project/buy_0531.csv')\n",
    "df_data['index'] = np.arange(df_data.date.size)"
   ]
  },
  {
   "cell_type": "code",
   "execution_count": 40,
   "id": "c27f0756",
   "metadata": {},
   "outputs": [
    {
     "data": {
      "text/plain": [
       "1.33"
      ]
     },
     "execution_count": 40,
     "metadata": {},
     "output_type": "execute_result"
    }
   ],
   "source": [
    "a = 1.333\n",
    "np.round(a,2)"
   ]
  },
  {
   "cell_type": "code",
   "execution_count": 3,
   "id": "13bf1d89",
   "metadata": {},
   "outputs": [],
   "source": [
    "age_dropdown = dcc.Dropdown(\n",
    "    id = 'age-dropdown',\n",
    "    options = [{'label': i, 'value': i} for i in sorted(df_data.age.unique())],\n",
    "    style = {'color':'black'}\n",
    "    #placeholder = '연령을 입력하세요'\n",
    ")\n",
    "sex_dropdown = dcc.Dropdown(\n",
    "    id = 'sex-dropdown',\n",
    "    options = [{'label':i, 'value':i} for i in sorted(df_data.sex.unique())],\n",
    "    style = {'color':'black'}\n",
    "    #placeholder = '성별을 입력하세요'\n",
    ")\n",
    "tem_dropdown = dcc.Dropdown(\n",
    "    id = 'tem-dropdown',\n",
    "    options = [\n",
    "        {'label':'-10℃ 미만','value':'-10℃ 미만'},\n",
    "        {'label':'-10℃ 이상 -5℃ 미만','value':'-10℃ 이상 -5℃ 미만'},\n",
    "        {'label':'-5℃ 이상 0℃ 미만','value':'-5℃ 이상 0℃ 미만'},\n",
    "        {'label':'0℃ 이상 5℃ 미만','value':'0℃ 이상 5℃ 미만'},\n",
    "        {'label':'5℃ 이상 10℃ 미만','value':'5℃ 이상 10℃ 미만'},\n",
    "        {'label':'10℃ 이상 15℃ 미만','value':'10℃ 이상 15℃ 미만'},\n",
    "        {'label':'15℃ 이상 20℃ 미만','value':'15℃ 이상 20℃ 미만'},\n",
    "        {'label':'20℃ 이상 25℃ 미만','value':'20℃ 이상 25℃ 미만'},\n",
    "        {'label':'25℃ 이상 30℃ 미만','value':'25℃ 이상 30℃ 미만'},\n",
    "        {'label':'30℃ 이상','value':'30℃ 이상'},\n",
    "    ],\n",
    "    #options = [{'label':i,'value':i} for i in df_weather.tem_range.unique()],\n",
    "    style = {'color':'black'}\n",
    "    #placeholder = '기온을 입력하세요'\n",
    ")\n",
    "dust_dropdown = dcc.Dropdown(\n",
    "    id = 'dust-dropdown',\n",
    "    options = [\n",
    "        {'label':'매우나쁨','value':'매우나쁨'},\n",
    "        {'label':'나쁨','value':'나쁨'},\n",
    "        {'label':'보통','value':'보통'},\n",
    "        {'label':'좋음','value':'좋음'}\n",
    "    ],\n",
    "    #options = [{'label':i, 'value':i} for i in df_weather.dust_a.unique()],\n",
    "    style = {'color':'black'}\n",
    "    #placeholder = '미세먼지를 입력하세요'\n",
    ")\n",
    "hum_dropdown = dcc.Dropdown(\n",
    "    id = 'hum-dropdown',\n",
    "    options = [\n",
    "        {'label':'20% 미만','value':'20% 미만'},\n",
    "        {'label':'20% 이상 30% 미만','value':'20% 이상 30% 미만'},\n",
    "        {'label':'30% 이상 40% 미만','value':'30% 이상 40% 미만'},\n",
    "        {'label':'40% 이상 50% 미만','value':'40% 이상 50% 미만'},\n",
    "        {'label':'50% 이상 60% 미만','value':'50% 이상 60% 미만'},\n",
    "        {'label':'60% 이상 70% 미만','value':'60% 이상 70% 미만'},\n",
    "        {'label':'70% 이상 80% 미만','value':'70% 이상 80% 미만'},\n",
    "        {'label':'80% 이상 90% 미만','value':'80% 이상 90% 미만'},\n",
    "        {'label':'90% 이상','value':'90% 이상'}\n",
    "    ],\n",
    "    #options = [{'label':i,'value':i} for i in df_weather.hum_a.unique()],\n",
    "    style = {'color':'black'}\n",
    "    #placeholder = '습도를 입력하세요'\n",
    ")\n",
    "big_radioitem = dcc.RadioItems(\n",
    "    id = 'big-radioitem',\n",
    "    options =  [{'label':i,'value':i} for i in df_data.big.unique()],\n",
    "    style = {'color':'white'}\n",
    ")\n",
    "line_graph = dcc.Graph(\n",
    "    id = 'line-graph'\n",
    ")\n",
    "line_graph2 = dcc.Graph(\n",
    "    id = 'line-graph2'\n",
    ")\n",
    "middle_dropdown = dcc.Dropdown(\n",
    "    id = 'middle-dropdown',\n",
    "    options = [{'label':i,'value':i} for i in df_data.middle.unique()],\n",
    "    style = {'color':'black'}\n",
    ")\n",
    "pie_graph = dcc.Graph(\n",
    "    id = 'pie-graph'\n",
    ")\n",
    "pie_graph2 = dcc.Graph(\n",
    "    id = 'pie-graph2'\n",
    ")"
   ]
  },
  {
   "cell_type": "code",
   "execution_count": 4,
   "id": "a0a70993",
   "metadata": {},
   "outputs": [],
   "source": [
    "controls = dbc.Card(\n",
    "    [\n",
    "        dbc.FormGroup(\n",
    "            [\n",
    "                dbc.Label(\"기온\"),\n",
    "                tem_dropdown   \n",
    "            ]\n",
    "        ),\n",
    "        dbc.FormGroup(\n",
    "            [\n",
    "                dbc.Label(\"습도\"),\n",
    "                hum_dropdown   \n",
    "            ]\n",
    "        ),\n",
    "        dbc.FormGroup(\n",
    "            [\n",
    "                dbc.Label(\"미세먼지\"),\n",
    "                dust_dropdown   \n",
    "            ]\n",
    "        ),\n",
    "        dbc.FormGroup(\n",
    "            [\n",
    "                dbc.Label(\"나이\"),\n",
    "                age_dropdown   \n",
    "            ]\n",
    "        ),\n",
    "        dbc.FormGroup(\n",
    "            [\n",
    "                dbc.Label(\"성별\"),\n",
    "                sex_dropdown        \n",
    "            ]\n",
    "        )\n",
    "    ],\n",
    "    body=True,\n",
    "    color=\"black\",\n",
    "    inverse=True\n",
    ")\n",
    "controls2 = dbc.Card(\n",
    "    [\n",
    "        dbc.FormGroup(\n",
    "            [\n",
    "                dbc.Label(\"상품유형\"),\n",
    "                big_radioitem       \n",
    "            ]\n",
    "        ),\n",
    "        dbc.FormGroup(\n",
    "            [\n",
    "                dbc.Label(\"날씨/연령/성별에 따른 상품 수요\"),\n",
    "                pie_graph\n",
    "            ]\n",
    "        )\n",
    "    ],\n",
    "    body = True,\n",
    "    color = 'black',\n",
    "    inverse = True\n",
    ")\n",
    "controls3 = dbc.Card(\n",
    "    [\n",
    "        dbc.FormGroup(\n",
    "            [\n",
    "                dbc.Label('상품선택'),\n",
    "                middle_dropdown\n",
    "            ]\n",
    "        ),\n",
    "        dbc.FormGroup(\n",
    "            [\n",
    "                dbc.Label('날씨에 따른 제품의 소분류별 판매 비율'),\n",
    "                pie_graph2\n",
    "            ]\n",
    "        )\n",
    "    ],\n",
    "    body = True,\n",
    "    color = 'black',\n",
    "    inverse = True\n",
    ")"
   ]
  },
  {
   "cell_type": "code",
   "execution_count": 5,
   "id": "a8b8b702",
   "metadata": {},
   "outputs": [
    {
     "data": {
      "text/html": [
       "<div>\n",
       "<style scoped>\n",
       "    .dataframe tbody tr th:only-of-type {\n",
       "        vertical-align: middle;\n",
       "    }\n",
       "\n",
       "    .dataframe tbody tr th {\n",
       "        vertical-align: top;\n",
       "    }\n",
       "\n",
       "    .dataframe thead th {\n",
       "        text-align: right;\n",
       "    }\n",
       "</style>\n",
       "<table border=\"1\" class=\"dataframe\">\n",
       "  <thead>\n",
       "    <tr style=\"text-align: right;\">\n",
       "      <th></th>\n",
       "      <th>판매량</th>\n",
       "      <th>여부</th>\n",
       "    </tr>\n",
       "  </thead>\n",
       "  <tbody>\n",
       "    <tr>\n",
       "      <td>qty</td>\n",
       "      <td>332.675561</td>\n",
       "      <td>판매</td>\n",
       "    </tr>\n",
       "    <tr>\n",
       "      <td>qty_r</td>\n",
       "      <td>136395.324439</td>\n",
       "      <td>비판매</td>\n",
       "    </tr>\n",
       "  </tbody>\n",
       "</table>\n",
       "</div>"
      ],
      "text/plain": [
       "                 판매량   여부\n",
       "qty       332.675561   판매\n",
       "qty_r  136395.324439  비판매"
      ]
     },
     "execution_count": 5,
     "metadata": {},
     "output_type": "execute_result"
    }
   ],
   "source": [
    "area = df_weather.loc[(df_weather.tem_range == '-5℃ 이상 0℃ 미만') & (df_weather.dust_a == '좋음') & (df_weather.hum_a == '40% 이상 50% 미만'),'area'].unique()\n",
    "date = df_weather.loc[(df_weather.tem_range == '-5℃ 이상 0℃ 미만') & (df_weather.dust_a == '좋음') & (df_weather.hum_a == '40% 이상 50% 미만'),'date']\n",
    "index = df_data.loc[df_data.date.isin(date),'index']\n",
    "area_m = np.append(area, np.array(['middle']))\n",
    "data1 = df_data[area_m].loc[index].groupby('middle').sum().reset_index()\n",
    "data1['qty'] = data1.sum(axis=1)\n",
    "a = df_data.loc[:,['qty','middle']].groupby('middle').sum()\n",
    "b = np.array(data1.loc[:,'middle'])\n",
    "aa = a.loc[b,['qty']].reset_index()\n",
    "data1['qty_r'] = aa.qty - data1.qty\n",
    "middle = df_data.loc[(df_data.middle == '가습기'),'middle']\n",
    "data2 = data1.loc[data1.middle=='가습기',['qty','qty_r']]\n",
    "data3 = data2.T\n",
    "data3['판매여부']=['판매','비판매']\n",
    "data3.columns = ['판매량','여부']\n",
    "data4 = data3.T\n",
    "#data3.여부 = ['판매량','']\n",
    "data3"
   ]
  },
  {
   "cell_type": "code",
   "execution_count": 18,
   "id": "d5d32045",
   "metadata": {},
   "outputs": [],
   "source": [
    "app = dash.Dash(__name__,external_stylesheets=[dbc.themes.BOOTSTRAP])\n",
    "app.layout = dbc.Container(\n",
    "    [\n",
    "        html.Br(),\n",
    "        html.H3('날씨에 따른 연령별/성별 소비트렌드', style={\"textAlign\": \"center\", 'color': 'white'}),\n",
    "        html.Hr(),\n",
    "        dbc.Row(\n",
    "            [\n",
    "                dbc.Col(controls, md=2),\n",
    "                dbc.Col(controls2, md = 7),\n",
    "                dbc.Col(controls3, md = 3)\n",
    "            ]\n",
    "        ),\n",
    "        dbc.Row(\n",
    "            [\n",
    "                dbc.Col(line_graph, md=6),\n",
    "                dbc.Col(line_graph2, md=6)\n",
    "            ]\n",
    "        \n",
    "        )\n",
    "    ],\n",
    "    fluid=True,\n",
    "    style = {'background-color':'black'}\n",
    ")"
   ]
  },
  {
   "cell_type": "code",
   "execution_count": 19,
   "id": "cac80b03",
   "metadata": {},
   "outputs": [],
   "source": [
    "@app.callback(\n",
    "    Output('pie-graph','figure'),\n",
    "    [Input('tem-dropdown','value'),\n",
    "    Input('dust-dropdown','value'),\n",
    "    Input('hum-dropdown','value'),\n",
    "    Input('age-dropdown','value'),\n",
    "    Input('sex-dropdown','value'),\n",
    "    Input('big-radioitem','value')]\n",
    ")\n",
    "def pie_graph_total(tem,dust,hum,age,sex,big):\n",
    "    date = df_weather.loc[(df_weather.tem_range == tem) & (df_weather.dust_a == dust) \\\n",
    "                          & (df_weather.hum_a == hum),'date']\n",
    "    area = df_weather.loc[(df_weather.tem_range == tem) & (df_weather.dust_a == dust) \\\n",
    "                          & (df_weather.hum_a == hum),'area'].unique()\n",
    "    area_add = np.append(area, np.array(['middle','age','sex','big']))\n",
    "    index = df_data.loc[df_data.date.isin(date),'index']\n",
    "    data = df_data[area_add].loc[index]\n",
    "    data['qty'] = data.sum(axis=1)\n",
    "    data1 = data.loc[(data.age == age) & (data.sex == sex) & (data.big == big), \\\n",
    "                     ['middle','qty']].groupby('middle').sum().reset_index()\n",
    "    fig = px.pie(data1, values=data1.qty, names=data1.middle ,\n",
    "                color_discrete_sequence=px.colors.sequential.RdBu,\n",
    "                template = 'plotly_dark')    \n",
    "    return fig\n",
    "\n",
    "\n",
    "@app.callback(\n",
    "    Output('line-graph','figure'),\n",
    "    [Input('tem-dropdown','value'),\n",
    "    Input('dust-dropdown','value'),\n",
    "    Input('hum-dropdown','value'),\n",
    "    Input('age-dropdown','value'),\n",
    "    Input('big-radioitem','value')]\n",
    ")\n",
    "def bar_graph_age(tem,dust,hum,age,big):\n",
    "    date = df_weather.loc[(df_weather.tem_range == tem) & (df_weather.dust_a == dust) & \\\n",
    "                          (df_weather.hum_a == hum),'date']\n",
    "    area = df_weather.loc[(df_weather.tem_range == tem) & (df_weather.dust_a == dust) & \\\n",
    "                          (df_weather.hum_a == hum),'area'].unique()\n",
    "    area_add = np.append(area, np.array(['middle','age','big']))\n",
    "    index = df_data.loc[df_data.date.isin(date),'index']\n",
    "    data = df_data[area_add].loc[index]\n",
    "    data['qty'] = data.sum(axis=1)\n",
    "    data1 = data.loc[(data.age == age) & (data.big == big),['middle','qty']].groupby('middle').sum().reset_index()\n",
    "    fig = px.bar(data1, x=data1.middle, y=data1.qty, template = 'plotly_dark', text = data1.qty)\n",
    "    colors = ['#b22222','#191970','#ffffff','#ffe4c4','#b0e0e6','#800000','#4169e1','#ffa07a'] * 4\n",
    "    fig.update_traces(marker_color = colors)\n",
    "    fig.update_traces(texttemplate='%{text:.2s}', textposition='outside')\n",
    "    fig.update_layout(uniformtext_minsize=6, uniformtext_mode='show')\n",
    "    fig.update_layout(title=\"날씨에 따른 연령별 소비트렌드\", \n",
    "                  font_family=\"San Serif\",\n",
    "                  titlefont={'size': 16},\n",
    "                  legend=dict(\n",
    "                  orientation=\"v\", y=1, yanchor=\"top\", x=1.25, xanchor=\"left\")\n",
    "                  ).update_xaxes(categoryorder='total descending')\n",
    "    fig.update_xaxes(title_text = '상품')\n",
    "    fig.update_yaxes(title_text = '구매건수')\n",
    "    return fig\n",
    "\n",
    "@app.callback(\n",
    "    Output('line-graph2','figure'),\n",
    "    [Input('tem-dropdown','value'),\n",
    "    Input('dust-dropdown','value'),\n",
    "    Input('hum-dropdown','value'),\n",
    "    Input('sex-dropdown','value'),\n",
    "    Input('big-radioitem','value')]\n",
    ")\n",
    "def bar_graph_sex(tem,dust,hum,sex,big):\n",
    "    date = df_weather.loc[(df_weather.tem_range == tem) & (df_weather.dust_a == dust) & \\\n",
    "                          (df_weather.hum_a == hum),'date']\n",
    "    area = df_weather.loc[(df_weather.tem_range == tem) & (df_weather.dust_a == dust) & \\\n",
    "                          (df_weather.hum_a == hum),'area'].unique()\n",
    "    area_add = np.append(area, np.array(['middle','sex','big']))\n",
    "    index = df_data.loc[df_data.date.isin(date),'index']\n",
    "    data = df_data[area_add].loc[index]\n",
    "    data['qty'] = data.sum(axis=1)\n",
    "    data1 = data.loc[(data.sex == sex) & (data.big == big),['middle','qty']].groupby('middle').sum().reset_index()\n",
    "    fig = px.bar(data1, x=data1.middle, y=data1.qty, template = 'plotly_dark', text = data1.qty)\n",
    "    colors = ['#b22222','#191970','#ffffff','#ffe4c4','#b0e0e6','#800000','#4169e1','#ffa07a'] * 4\n",
    "    fig.update_traces(marker_color = colors)\n",
    "    fig.update_traces(texttemplate='%{text:.2s}', textposition='outside')\n",
    "    fig.update_layout(uniformtext_minsize=6, uniformtext_mode='show')\n",
    "    fig.update_layout(title=\"날씨에 따른 성별 소비트렌드\", \n",
    "                  font_family=\"San Serif\",\n",
    "                  titlefont={'size': 16},\n",
    "                  legend=dict(\n",
    "                  orientation=\"v\", y=1, yanchor=\"top\", x=1.25, xanchor=\"left\")\n",
    "                  ).update_xaxes(categoryorder='total descending')\n",
    "    fig.update_xaxes(title_text = '상품')\n",
    "    fig.update_yaxes(title_text = '구매건수')\n",
    "    return fig\n",
    "\n",
    "@app.callback(\n",
    "    Output('pie-graph2','figure'),\n",
    "    [Input('tem-dropdown','value'),\n",
    "    Input('dust-dropdown','value'),\n",
    "    Input('hum-dropdown','value'),\n",
    "    Input('middle-dropdown','value')]\n",
    ")\n",
    "def pie_graph_product(tem,dust,hum,middle):\n",
    "    area = df_weather.loc[(df_weather.tem_range == tem) & (df_weather.dust_a == dust) & (df_weather.hum_a == hum),'area'].unique()\n",
    "    date = df_weather.loc[(df_weather.tem_range == tem) & (df_weather.dust_a == dust) & (df_weather.hum_a == hum),'date']\n",
    "    area_add = np.append(area, np.array(['middle']))\n",
    "    index = df_data.loc[df_data.date.isin(date),'index']\n",
    "    data = df_data[area_add].loc[index]\n",
    "    data['qty'] = data.sum(axis=1)\n",
    "    data1 = data.loc[:,['middle','qty']].groupby('middle').sum().reset_index()\n",
    "    a = df_data.loc[:,['qty','middle']].groupby('middle').sum()\n",
    "    b = np.array(data1.loc[:,'middle'])\n",
    "    aa = a.loc[b,['qty']].reset_index()\n",
    "    data1['qty_r'] = aa.qty - data1.qty\n",
    "    data2 = data1.loc[data1.middle==middle,['qty','qty_r']]\n",
    "    data3 = data2.T\n",
    "    data3['판매여부']=['판매량',' ']\n",
    "    data3.columns = ['판매량','여부']\n",
    "    fig = px.pie(data3, values=data3.판매량, names=data3.여부,\n",
    "                 color_discrete_map={'비판매':'#0000cd','판매':'#00bfff'},\n",
    "                 template = 'plotly_dark', hole = .7)\n",
    "    #fig.update_traces(textposition='inside', textinfo='percent+label')\n",
    "    fig.update_layout(annotations=[dict(text=str(np.round(data3.판매량[0]/(data3.판매량[1]+data3.판매량[0])*100,1)) + '%', x=0.5, y=0.5, \\\n",
    "                                        font_size=20, showarrow=False)])\n",
    "    fig.update_layout(showlegend=False)\n",
    "    return fig"
   ]
  },
  {
   "cell_type": "code",
   "execution_count": 20,
   "id": "68911acc",
   "metadata": {
    "collapsed": true,
    "jupyter": {
     "outputs_hidden": true
    }
   },
   "outputs": [
    {
     "name": "stdout",
     "output_type": "stream",
     "text": [
      "Dash is running on http://192.168.0.129:7777/\n",
      "\n",
      "Dash is running on http://192.168.0.129:7777/\n",
      "\n",
      "Dash is running on http://192.168.0.129:7777/\n",
      "\n",
      "Dash is running on http://192.168.0.129:7777/\n",
      "\n",
      "Dash is running on http://192.168.0.129:7777/\n",
      "\n",
      " * Serving Flask app \"__main__\" (lazy loading)\n",
      " * Environment: production\n",
      "   WARNING: This is a development server. Do not use it in a production deployment.\n",
      "   Use a production WSGI server instead.\n",
      " * Debug mode: off\n"
     ]
    },
    {
     "name": "stderr",
     "output_type": "stream",
     "text": [
      " * Running on http://192.168.0.129:7777/ (Press CTRL+C to quit)\n",
      "192.168.0.129 - - [03/Jun/2021 16:29:55] \"GET / HTTP/1.1\" 200 -\n",
      "192.168.0.129 - - [03/Jun/2021 16:29:55] \"GET /_dash-layout HTTP/1.1\" 200 -\n",
      "192.168.0.129 - - [03/Jun/2021 16:29:55] \"GET /_dash-dependencies HTTP/1.1\" 200 -\n",
      "192.168.0.129 - - [03/Jun/2021 16:29:55] \"GET /_favicon.ico?v=1.20.0 HTTP/1.1\" 200 -\n"
     ]
    },
    {
     "name": "stdout",
     "output_type": "stream",
     "text": [
      "Exception on /_dash-update-component [POST]\n",
      "Traceback (most recent call last):\n",
      "  File \"C:\\Users\\admin\\Anaconda3\\lib\\site-packages\\flask\\app.py\", line 2446, in wsgi_app\n",
      "    response = self.full_dispatch_request()\n",
      "  File \"C:\\Users\\admin\\Anaconda3\\lib\\site-packages\\flask\\app.py\", line 1951, in full_dispatch_request\n",
      "    rv = self.handle_user_exception(e)\n",
      "  File \"C:\\Users\\admin\\Anaconda3\\lib\\site-packages\\flask\\app.py\", line 1820, in handle_user_exception\n",
      "    reraise(exc_type, exc_value, tb)\n",
      "  File \"C:\\Users\\admin\\Anaconda3\\lib\\site-packages\\flask\\_compat.py\", line 39, in reraise\n",
      "    raise value\n",
      "  File \"C:\\Users\\admin\\Anaconda3\\lib\\site-packages\\flask\\app.py\", line 1949, in full_dispatch_request\n",
      "    rv = self.dispatch_request()\n",
      "  File \"C:\\Users\\admin\\Anaconda3\\lib\\site-packages\\flask\\app.py\", line 1935, in dispatch_request\n",
      "    return self.view_functions[rule.endpoint](**req.view_args)\n",
      "  File \"C:\\Users\\admin\\Anaconda3\\lib\\site-packages\\dash\\dash.py\", line 1079, in dispatch\n",
      "    response.set_data(func(*args, outputs_list=outputs_list))\n",
      "  File \"C:\\Users\\admin\\Anaconda3\\lib\\site-packages\\dash\\dash.py\", line 1010, in add_context\n",
      "    output_value = func(*args, **kwargs)  # %% callback invoked %%\n",
      "  File \"<ipython-input-19-a827d4c88365>\", line 43, in bar_graph_age\n",
      "    fig = px.bar(data1, x=data1.middle, y=data1.qty, template = 'plotly_dark', text = data1.qty)\n",
      "  File \"C:\\Users\\admin\\Anaconda3\\lib\\site-packages\\plotly\\express\\_chart_types.py\", line 354, in bar\n",
      "    layout_patch=dict(barmode=barmode),\n",
      "  File \"C:\\Users\\admin\\Anaconda3\\lib\\site-packages\\plotly\\express\\_core.py\", line 1861, in make_figure\n",
      "    args = build_dataframe(args, constructor)\n",
      "  File \"C:\\Users\\admin\\Anaconda3\\lib\\site-packages\\plotly\\express\\_core.py\", line 1300, in build_dataframe\n",
      "    \"Cannot accept list of column references or list of columns for both `x` and `y`.\"\n",
      "ValueError: Cannot accept list of column references or list of columns for both `x` and `y`.\n"
     ]
    },
    {
     "name": "stderr",
     "output_type": "stream",
     "text": [
      "192.168.0.129 - - [03/Jun/2021 16:29:56] \"POST /_dash-update-component HTTP/1.1\" 200 -\n"
     ]
    },
    {
     "name": "stdout",
     "output_type": "stream",
     "text": [
      "Exception on /_dash-update-component [POST]\n",
      "Traceback (most recent call last):\n",
      "  File \"C:\\Users\\admin\\Anaconda3\\lib\\site-packages\\flask\\app.py\", line 2446, in wsgi_app\n",
      "    response = self.full_dispatch_request()\n",
      "  File \"C:\\Users\\admin\\Anaconda3\\lib\\site-packages\\flask\\app.py\", line 1951, in full_dispatch_request\n",
      "    rv = self.handle_user_exception(e)\n",
      "  File \"C:\\Users\\admin\\Anaconda3\\lib\\site-packages\\flask\\app.py\", line 1820, in handle_user_exception\n",
      "    reraise(exc_type, exc_value, tb)\n",
      "  File \"C:\\Users\\admin\\Anaconda3\\lib\\site-packages\\flask\\_compat.py\", line 39, in reraise\n",
      "    raise value\n",
      "  File \"C:\\Users\\admin\\Anaconda3\\lib\\site-packages\\flask\\app.py\", line 1949, in full_dispatch_request\n",
      "    rv = self.dispatch_request()\n",
      "  File \"C:\\Users\\admin\\Anaconda3\\lib\\site-packages\\flask\\app.py\", line 1935, in dispatch_request\n",
      "    return self.view_functions[rule.endpoint](**req.view_args)\n",
      "  File \"C:\\Users\\admin\\Anaconda3\\lib\\site-packages\\dash\\dash.py\", line 1079, in dispatch\n",
      "    response.set_data(func(*args, outputs_list=outputs_list))\n",
      "  File \"C:\\Users\\admin\\Anaconda3\\lib\\site-packages\\dash\\dash.py\", line 1010, in add_context\n",
      "    output_value = func(*args, **kwargs)  # %% callback invoked %%\n",
      "  File \"<ipython-input-19-a827d4c88365>\", line 43, in bar_graph_age\n",
      "    fig = px.bar(data1, x=data1.middle, y=data1.qty, template = 'plotly_dark', text = data1.qty)\n",
      "  File \"C:\\Users\\admin\\Anaconda3\\lib\\site-packages\\plotly\\express\\_chart_types.py\", line 354, in bar\n",
      "    layout_patch=dict(barmode=barmode),\n",
      "  File \"C:\\Users\\admin\\Anaconda3\\lib\\site-packages\\plotly\\express\\_core.py\", line 1861, in make_figure\n",
      "    args = build_dataframe(args, constructor)\n",
      "  File \"C:\\Users\\admin\\Anaconda3\\lib\\site-packages\\plotly\\express\\_core.py\", line 1300, in build_dataframe\n",
      "    \"Cannot accept list of column references or list of columns for both `x` and `y`.\"\n",
      "ValueError: Cannot accept list of column references or list of columns for both `x` and `y`.\n",
      "Exception on /_dash-update-component [POST]\n",
      "Traceback (most recent call last):\n",
      "  File \"C:\\Users\\admin\\Anaconda3\\lib\\site-packages\\flask\\app.py\", line 2446, in wsgi_app\n",
      "    response = self.full_dispatch_request()\n",
      "  File \"C:\\Users\\admin\\Anaconda3\\lib\\site-packages\\flask\\app.py\", line 1951, in full_dispatch_request\n",
      "    rv = self.handle_user_exception(e)\n",
      "  File \"C:\\Users\\admin\\Anaconda3\\lib\\site-packages\\flask\\app.py\", line 1820, in handle_user_exception\n",
      "    reraise(exc_type, exc_value, tb)\n",
      "  File \"C:\\Users\\admin\\Anaconda3\\lib\\site-packages\\flask\\_compat.py\", line 39, in reraise\n",
      "    raise value\n",
      "  File \"C:\\Users\\admin\\Anaconda3\\lib\\site-packages\\flask\\app.py\", line 1949, in full_dispatch_request\n",
      "    rv = self.dispatch_request()\n",
      "  File \"C:\\Users\\admin\\Anaconda3\\lib\\site-packages\\flask\\app.py\", line 1935, in dispatch_request\n",
      "    return self.view_functions[rule.endpoint](**req.view_args)\n",
      "  File \"C:\\Users\\admin\\Anaconda3\\lib\\site-packages\\dash\\dash.py\", line 1079, in dispatch\n",
      "    response.set_data(func(*args, outputs_list=outputs_list))\n",
      "  File \"C:\\Users\\admin\\Anaconda3\\lib\\site-packages\\dash\\dash.py\", line 1010, in add_context\n",
      "    output_value = func(*args, **kwargs)  # %% callback invoked %%\n",
      "  File \"<ipython-input-19-a827d4c88365>\", line 43, in bar_graph_age\n",
      "    fig = px.bar(data1, x=data1.middle, y=data1.qty, template = 'plotly_dark', text = data1.qty)\n",
      "  File \"C:\\Users\\admin\\Anaconda3\\lib\\site-packages\\plotly\\express\\_chart_types.py\", line 354, in bar\n",
      "    layout_patch=dict(barmode=barmode),\n",
      "  File \"C:\\Users\\admin\\Anaconda3\\lib\\site-packages\\plotly\\express\\_core.py\", line 1861, in make_figure\n",
      "    args = build_dataframe(args, constructor)\n",
      "  File \"C:\\Users\\admin\\Anaconda3\\lib\\site-packages\\plotly\\express\\_core.py\", line 1300, in build_dataframe\n",
      "    \"Cannot accept list of column references or list of columns for both `x` and `y`.\"\n",
      "ValueError: Cannot accept list of column references or list of columns for both `x` and `y`.\n",
      "Exception on /_dash-update-component [POST]\n",
      "Traceback (most recent call last):\n",
      "  File \"C:\\Users\\admin\\Anaconda3\\lib\\site-packages\\flask\\app.py\", line 2446, in wsgi_app\n",
      "    response = self.full_dispatch_request()\n",
      "  File \"C:\\Users\\admin\\Anaconda3\\lib\\site-packages\\flask\\app.py\", line 1951, in full_dispatch_request\n",
      "    rv = self.handle_user_exception(e)\n",
      "  File \"C:\\Users\\admin\\Anaconda3\\lib\\site-packages\\flask\\app.py\", line 1820, in handle_user_exception\n",
      "    reraise(exc_type, exc_value, tb)\n",
      "  File \"C:\\Users\\admin\\Anaconda3\\lib\\site-packages\\flask\\_compat.py\", line 39, in reraise\n",
      "    raise value\n",
      "  File \"C:\\Users\\admin\\Anaconda3\\lib\\site-packages\\flask\\app.py\", line 1949, in full_dispatch_request\n",
      "    rv = self.dispatch_request()\n",
      "  File \"C:\\Users\\admin\\Anaconda3\\lib\\site-packages\\flask\\app.py\", line 1935, in dispatch_request\n",
      "    return self.view_functions[rule.endpoint](**req.view_args)\n",
      "  File \"C:\\Users\\admin\\Anaconda3\\lib\\site-packages\\dash\\dash.py\", line 1079, in dispatch\n",
      "    response.set_data(func(*args, outputs_list=outputs_list))\n",
      "  File \"C:\\Users\\admin\\Anaconda3\\lib\\site-packages\\dash\\dash.py\", line 1010, in add_context\n",
      "    output_value = func(*args, **kwargs)  # %% callback invoked %%\n",
      "  File \"<ipython-input-19-a827d4c88365>\", line 74, in bar_graph_sex\n",
      "    fig = px.bar(data1, x=data1.middle, y=data1.qty, template = 'plotly_dark', text = data1.qty)\n",
      "  File \"C:\\Users\\admin\\Anaconda3\\lib\\site-packages\\plotly\\express\\_chart_types.py\", line 354, in bar\n",
      "    layout_patch=dict(barmode=barmode),\n",
      "  File \"C:\\Users\\admin\\Anaconda3\\lib\\site-packages\\plotly\\express\\_core.py\", line 1861, in make_figure\n",
      "    args = build_dataframe(args, constructor)\n",
      "  File \"C:\\Users\\admin\\Anaconda3\\lib\\site-packages\\plotly\\express\\_core.py\", line 1300, in build_dataframe\n",
      "    \"Cannot accept list of column references or list of columns for both `x` and `y`.\"\n",
      "ValueError: Cannot accept list of column references or list of columns for both `x` and `y`.\n",
      "Exception on /_dash-update-component [POST]\n",
      "Traceback (most recent call last):\n",
      "  File \"C:\\Users\\admin\\Anaconda3\\lib\\site-packages\\flask\\app.py\", line 2446, in wsgi_app\n",
      "    response = self.full_dispatch_request()\n",
      "  File \"C:\\Users\\admin\\Anaconda3\\lib\\site-packages\\flask\\app.py\", line 1951, in full_dispatch_request\n",
      "    rv = self.handle_user_exception(e)\n",
      "  File \"C:\\Users\\admin\\Anaconda3\\lib\\site-packages\\flask\\app.py\", line 1820, in handle_user_exception\n",
      "    reraise(exc_type, exc_value, tb)\n",
      "  File \"C:\\Users\\admin\\Anaconda3\\lib\\site-packages\\flask\\_compat.py\", line 39, in reraise\n",
      "    raise value\n",
      "  File \"C:\\Users\\admin\\Anaconda3\\lib\\site-packages\\flask\\app.py\", line 1949, in full_dispatch_request\n",
      "    rv = self.dispatch_request()\n",
      "  File \"C:\\Users\\admin\\Anaconda3\\lib\\site-packages\\flask\\app.py\", line 1935, in dispatch_request\n",
      "    return self.view_functions[rule.endpoint](**req.view_args)\n",
      "  File \"C:\\Users\\admin\\Anaconda3\\lib\\site-packages\\dash\\dash.py\", line 1079, in dispatch\n",
      "    response.set_data(func(*args, outputs_list=outputs_list))\n",
      "  File \"C:\\Users\\admin\\Anaconda3\\lib\\site-packages\\dash\\dash.py\", line 1010, in add_context\n",
      "    output_value = func(*args, **kwargs)  # %% callback invoked %%\n",
      "  File \"<ipython-input-19-a827d4c88365>\", line 43, in bar_graph_age\n",
      "    fig = px.bar(data1, x=data1.middle, y=data1.qty, template = 'plotly_dark', text = data1.qty)\n",
      "  File \"C:\\Users\\admin\\Anaconda3\\lib\\site-packages\\plotly\\express\\_chart_types.py\", line 354, in bar\n",
      "    layout_patch=dict(barmode=barmode),\n",
      "  File \"C:\\Users\\admin\\Anaconda3\\lib\\site-packages\\plotly\\express\\_core.py\", line 1861, in make_figure\n",
      "    args = build_dataframe(args, constructor)\n",
      "  File \"C:\\Users\\admin\\Anaconda3\\lib\\site-packages\\plotly\\express\\_core.py\", line 1300, in build_dataframe\n",
      "    \"Cannot accept list of column references or list of columns for both `x` and `y`.\"\n",
      "ValueError: Cannot accept list of column references or list of columns for both `x` and `y`.\n",
      "Exception on /_dash-update-component [POST]\n",
      "Traceback (most recent call last):\n",
      "  File \"C:\\Users\\admin\\Anaconda3\\lib\\site-packages\\flask\\app.py\", line 2446, in wsgi_app\n",
      "    response = self.full_dispatch_request()\n",
      "  File \"C:\\Users\\admin\\Anaconda3\\lib\\site-packages\\flask\\app.py\", line 1951, in full_dispatch_request\n",
      "    rv = self.handle_user_exception(e)\n",
      "  File \"C:\\Users\\admin\\Anaconda3\\lib\\site-packages\\flask\\app.py\", line 1820, in handle_user_exception\n",
      "    reraise(exc_type, exc_value, tb)\n",
      "  File \"C:\\Users\\admin\\Anaconda3\\lib\\site-packages\\flask\\_compat.py\", line 39, in reraise\n",
      "    raise value\n",
      "  File \"C:\\Users\\admin\\Anaconda3\\lib\\site-packages\\flask\\app.py\", line 1949, in full_dispatch_request\n",
      "    rv = self.dispatch_request()\n",
      "  File \"C:\\Users\\admin\\Anaconda3\\lib\\site-packages\\flask\\app.py\", line 1935, in dispatch_request\n",
      "    return self.view_functions[rule.endpoint](**req.view_args)\n",
      "  File \"C:\\Users\\admin\\Anaconda3\\lib\\site-packages\\dash\\dash.py\", line 1079, in dispatch\n",
      "    response.set_data(func(*args, outputs_list=outputs_list))\n",
      "  File \"C:\\Users\\admin\\Anaconda3\\lib\\site-packages\\dash\\dash.py\", line 1010, in add_context\n",
      "    output_value = func(*args, **kwargs)  # %% callback invoked %%\n",
      "  File \"<ipython-input-19-a827d4c88365>\", line 74, in bar_graph_sex\n",
      "    fig = px.bar(data1, x=data1.middle, y=data1.qty, template = 'plotly_dark', text = data1.qty)\n",
      "  File \"C:\\Users\\admin\\Anaconda3\\lib\\site-packages\\plotly\\express\\_chart_types.py\", line 354, in bar\n",
      "    layout_patch=dict(barmode=barmode),\n",
      "  File \"C:\\Users\\admin\\Anaconda3\\lib\\site-packages\\plotly\\express\\_core.py\", line 1861, in make_figure\n",
      "    args = build_dataframe(args, constructor)\n",
      "  File \"C:\\Users\\admin\\Anaconda3\\lib\\site-packages\\plotly\\express\\_core.py\", line 1300, in build_dataframe\n",
      "    \"Cannot accept list of column references or list of columns for both `x` and `y`.\"\n",
      "ValueError: Cannot accept list of column references or list of columns for both `x` and `y`.\n",
      "Exception on /_dash-update-component [POST]\n",
      "Traceback (most recent call last):\n",
      "  File \"C:\\Users\\admin\\Anaconda3\\lib\\site-packages\\flask\\app.py\", line 2446, in wsgi_app\n",
      "    response = self.full_dispatch_request()\n",
      "  File \"C:\\Users\\admin\\Anaconda3\\lib\\site-packages\\flask\\app.py\", line 1951, in full_dispatch_request\n",
      "    rv = self.handle_user_exception(e)\n",
      "  File \"C:\\Users\\admin\\Anaconda3\\lib\\site-packages\\flask\\app.py\", line 1820, in handle_user_exception\n",
      "    reraise(exc_type, exc_value, tb)\n",
      "  File \"C:\\Users\\admin\\Anaconda3\\lib\\site-packages\\flask\\_compat.py\", line 39, in reraise\n",
      "    raise value\n",
      "  File \"C:\\Users\\admin\\Anaconda3\\lib\\site-packages\\flask\\app.py\", line 1949, in full_dispatch_request\n",
      "    rv = self.dispatch_request()\n",
      "  File \"C:\\Users\\admin\\Anaconda3\\lib\\site-packages\\flask\\app.py\", line 1935, in dispatch_request\n",
      "    return self.view_functions[rule.endpoint](**req.view_args)\n",
      "  File \"C:\\Users\\admin\\Anaconda3\\lib\\site-packages\\dash\\dash.py\", line 1079, in dispatch\n",
      "    response.set_data(func(*args, outputs_list=outputs_list))\n",
      "  File \"C:\\Users\\admin\\Anaconda3\\lib\\site-packages\\dash\\dash.py\", line 1010, in add_context\n",
      "    output_value = func(*args, **kwargs)  # %% callback invoked %%\n",
      "  File \"<ipython-input-19-a827d4c88365>\", line 43, in bar_graph_age\n",
      "    fig = px.bar(data1, x=data1.middle, y=data1.qty, template = 'plotly_dark', text = data1.qty)\n",
      "  File \"C:\\Users\\admin\\Anaconda3\\lib\\site-packages\\plotly\\express\\_chart_types.py\", line 354, in bar\n",
      "    layout_patch=dict(barmode=barmode),\n",
      "  File \"C:\\Users\\admin\\Anaconda3\\lib\\site-packages\\plotly\\express\\_core.py\", line 1861, in make_figure\n",
      "    args = build_dataframe(args, constructor)\n",
      "  File \"C:\\Users\\admin\\Anaconda3\\lib\\site-packages\\plotly\\express\\_core.py\", line 1300, in build_dataframe\n",
      "    \"Cannot accept list of column references or list of columns for both `x` and `y`.\"\n",
      "ValueError: Cannot accept list of column references or list of columns for both `x` and `y`.\n",
      "Exception on /_dash-update-component [POST]\n",
      "Traceback (most recent call last):\n",
      "  File \"C:\\Users\\admin\\Anaconda3\\lib\\site-packages\\flask\\app.py\", line 2446, in wsgi_app\n",
      "    response = self.full_dispatch_request()\n",
      "  File \"C:\\Users\\admin\\Anaconda3\\lib\\site-packages\\flask\\app.py\", line 1951, in full_dispatch_request\n",
      "    rv = self.handle_user_exception(e)\n",
      "  File \"C:\\Users\\admin\\Anaconda3\\lib\\site-packages\\flask\\app.py\", line 1820, in handle_user_exception\n",
      "    reraise(exc_type, exc_value, tb)\n",
      "  File \"C:\\Users\\admin\\Anaconda3\\lib\\site-packages\\flask\\_compat.py\", line 39, in reraise\n",
      "    raise value\n",
      "  File \"C:\\Users\\admin\\Anaconda3\\lib\\site-packages\\flask\\app.py\", line 1949, in full_dispatch_request\n",
      "    rv = self.dispatch_request()\n",
      "  File \"C:\\Users\\admin\\Anaconda3\\lib\\site-packages\\flask\\app.py\", line 1935, in dispatch_request\n",
      "    return self.view_functions[rule.endpoint](**req.view_args)\n",
      "  File \"C:\\Users\\admin\\Anaconda3\\lib\\site-packages\\dash\\dash.py\", line 1079, in dispatch\n",
      "    response.set_data(func(*args, outputs_list=outputs_list))\n",
      "  File \"C:\\Users\\admin\\Anaconda3\\lib\\site-packages\\dash\\dash.py\", line 1010, in add_context\n",
      "    output_value = func(*args, **kwargs)  # %% callback invoked %%\n",
      "  File \"<ipython-input-19-a827d4c88365>\", line 74, in bar_graph_sex\n",
      "    fig = px.bar(data1, x=data1.middle, y=data1.qty, template = 'plotly_dark', text = data1.qty)\n",
      "  File \"C:\\Users\\admin\\Anaconda3\\lib\\site-packages\\plotly\\express\\_chart_types.py\", line 354, in bar\n",
      "    layout_patch=dict(barmode=barmode),\n",
      "  File \"C:\\Users\\admin\\Anaconda3\\lib\\site-packages\\plotly\\express\\_core.py\", line 1861, in make_figure\n",
      "    args = build_dataframe(args, constructor)\n",
      "  File \"C:\\Users\\admin\\Anaconda3\\lib\\site-packages\\plotly\\express\\_core.py\", line 1300, in build_dataframe\n",
      "    \"Cannot accept list of column references or list of columns for both `x` and `y`.\"\n",
      "ValueError: Cannot accept list of column references or list of columns for both `x` and `y`.\n"
     ]
    },
    {
     "name": "stderr",
     "output_type": "stream",
     "text": [
      "192.168.0.129 - - [03/Jun/2021 16:29:56] \"POST /_dash-update-component HTTP/1.1\" 500 -\n"
     ]
    },
    {
     "name": "stdout",
     "output_type": "stream",
     "text": [
      "Exception on /_dash-update-component [POST]\n",
      "Traceback (most recent call last):\n",
      "  File \"C:\\Users\\admin\\Anaconda3\\lib\\site-packages\\flask\\app.py\", line 2446, in wsgi_app\n",
      "    response = self.full_dispatch_request()\n",
      "  File \"C:\\Users\\admin\\Anaconda3\\lib\\site-packages\\flask\\app.py\", line 1951, in full_dispatch_request\n",
      "    rv = self.handle_user_exception(e)\n",
      "  File \"C:\\Users\\admin\\Anaconda3\\lib\\site-packages\\flask\\app.py\", line 1820, in handle_user_exception\n",
      "    reraise(exc_type, exc_value, tb)\n",
      "  File \"C:\\Users\\admin\\Anaconda3\\lib\\site-packages\\flask\\_compat.py\", line 39, in reraise\n",
      "    raise value\n",
      "  File \"C:\\Users\\admin\\Anaconda3\\lib\\site-packages\\flask\\app.py\", line 1949, in full_dispatch_request\n",
      "    rv = self.dispatch_request()\n",
      "  File \"C:\\Users\\admin\\Anaconda3\\lib\\site-packages\\flask\\app.py\", line 1935, in dispatch_request\n",
      "    return self.view_functions[rule.endpoint](**req.view_args)\n",
      "  File \"C:\\Users\\admin\\Anaconda3\\lib\\site-packages\\dash\\dash.py\", line 1079, in dispatch\n",
      "    response.set_data(func(*args, outputs_list=outputs_list))\n",
      "  File \"C:\\Users\\admin\\Anaconda3\\lib\\site-packages\\dash\\dash.py\", line 1010, in add_context\n",
      "    output_value = func(*args, **kwargs)  # %% callback invoked %%\n",
      "  File \"<ipython-input-19-a827d4c88365>\", line 74, in bar_graph_sex\n",
      "    fig = px.bar(data1, x=data1.middle, y=data1.qty, template = 'plotly_dark', text = data1.qty)\n",
      "  File \"C:\\Users\\admin\\Anaconda3\\lib\\site-packages\\plotly\\express\\_chart_types.py\", line 354, in bar\n",
      "    layout_patch=dict(barmode=barmode),\n",
      "  File \"C:\\Users\\admin\\Anaconda3\\lib\\site-packages\\plotly\\express\\_core.py\", line 1861, in make_figure\n",
      "    args = build_dataframe(args, constructor)\n",
      "  File \"C:\\Users\\admin\\Anaconda3\\lib\\site-packages\\plotly\\express\\_core.py\", line 1300, in build_dataframe\n",
      "    \"Cannot accept list of column references or list of columns for both `x` and `y`.\"\n",
      "ValueError: Cannot accept list of column references or list of columns for both `x` and `y`.\n",
      "Exception on /_dash-update-component [POST]\n",
      "Traceback (most recent call last):\n",
      "  File \"C:\\Users\\admin\\Anaconda3\\lib\\site-packages\\flask\\app.py\", line 2446, in wsgi_app\n",
      "    response = self.full_dispatch_request()\n",
      "  File \"C:\\Users\\admin\\Anaconda3\\lib\\site-packages\\flask\\app.py\", line 1951, in full_dispatch_request\n",
      "    rv = self.handle_user_exception(e)\n",
      "  File \"C:\\Users\\admin\\Anaconda3\\lib\\site-packages\\flask\\app.py\", line 1820, in handle_user_exception\n",
      "    reraise(exc_type, exc_value, tb)\n",
      "  File \"C:\\Users\\admin\\Anaconda3\\lib\\site-packages\\flask\\_compat.py\", line 39, in reraise\n",
      "    raise value\n",
      "  File \"C:\\Users\\admin\\Anaconda3\\lib\\site-packages\\flask\\app.py\", line 1949, in full_dispatch_request\n",
      "    rv = self.dispatch_request()\n",
      "  File \"C:\\Users\\admin\\Anaconda3\\lib\\site-packages\\flask\\app.py\", line 1935, in dispatch_request\n",
      "    return self.view_functions[rule.endpoint](**req.view_args)\n",
      "  File \"C:\\Users\\admin\\Anaconda3\\lib\\site-packages\\dash\\dash.py\", line 1079, in dispatch\n",
      "    response.set_data(func(*args, outputs_list=outputs_list))\n",
      "  File \"C:\\Users\\admin\\Anaconda3\\lib\\site-packages\\dash\\dash.py\", line 1010, in add_context\n",
      "    output_value = func(*args, **kwargs)  # %% callback invoked %%\n",
      "  File \"<ipython-input-19-a827d4c88365>\", line 74, in bar_graph_sex\n",
      "    fig = px.bar(data1, x=data1.middle, y=data1.qty, template = 'plotly_dark', text = data1.qty)\n",
      "  File \"C:\\Users\\admin\\Anaconda3\\lib\\site-packages\\plotly\\express\\_chart_types.py\", line 354, in bar\n",
      "    layout_patch=dict(barmode=barmode),\n",
      "  File \"C:\\Users\\admin\\Anaconda3\\lib\\site-packages\\plotly\\express\\_core.py\", line 1861, in make_figure\n",
      "    args = build_dataframe(args, constructor)\n",
      "  File \"C:\\Users\\admin\\Anaconda3\\lib\\site-packages\\plotly\\express\\_core.py\", line 1300, in build_dataframe\n",
      "    \"Cannot accept list of column references or list of columns for both `x` and `y`.\"\n",
      "ValueError: Cannot accept list of column references or list of columns for both `x` and `y`.\n"
     ]
    },
    {
     "name": "stderr",
     "output_type": "stream",
     "text": [
      "192.168.0.129 - - [03/Jun/2021 16:29:56] \"POST /_dash-update-component HTTP/1.1\" 500 -\n"
     ]
    },
    {
     "name": "stdout",
     "output_type": "stream",
     "text": [
      "Exception on /_dash-update-component [POST]\n",
      "Traceback (most recent call last):\n",
      "  File \"C:\\Users\\admin\\Anaconda3\\lib\\site-packages\\flask\\app.py\", line 2446, in wsgi_app\n",
      "    response = self.full_dispatch_request()\n",
      "  File \"C:\\Users\\admin\\Anaconda3\\lib\\site-packages\\flask\\app.py\", line 1951, in full_dispatch_request\n",
      "    rv = self.handle_user_exception(e)\n",
      "  File \"C:\\Users\\admin\\Anaconda3\\lib\\site-packages\\flask\\app.py\", line 1820, in handle_user_exception\n",
      "    reraise(exc_type, exc_value, tb)\n",
      "  File \"C:\\Users\\admin\\Anaconda3\\lib\\site-packages\\flask\\_compat.py\", line 39, in reraise\n",
      "    raise value\n",
      "  File \"C:\\Users\\admin\\Anaconda3\\lib\\site-packages\\flask\\app.py\", line 1949, in full_dispatch_request\n",
      "    rv = self.dispatch_request()\n",
      "  File \"C:\\Users\\admin\\Anaconda3\\lib\\site-packages\\flask\\app.py\", line 1935, in dispatch_request\n",
      "    return self.view_functions[rule.endpoint](**req.view_args)\n",
      "  File \"C:\\Users\\admin\\Anaconda3\\lib\\site-packages\\dash\\dash.py\", line 1079, in dispatch\n",
      "    response.set_data(func(*args, outputs_list=outputs_list))\n",
      "  File \"C:\\Users\\admin\\Anaconda3\\lib\\site-packages\\dash\\dash.py\", line 1010, in add_context\n",
      "    output_value = func(*args, **kwargs)  # %% callback invoked %%\n",
      "  File \"<ipython-input-19-a827d4c88365>\", line 111, in pie_graph_product\n",
      "    data3.columns = ['판매량','여부']\n",
      "  File \"C:\\Users\\admin\\Anaconda3\\lib\\site-packages\\pandas\\core\\generic.py\", line 5192, in __setattr__\n",
      "    return object.__setattr__(self, name, value)\n",
      "  File \"pandas\\_libs\\properties.pyx\", line 67, in pandas._libs.properties.AxisProperty.__set__\n",
      "  File \"C:\\Users\\admin\\Anaconda3\\lib\\site-packages\\pandas\\core\\generic.py\", line 690, in _set_axis\n",
      "    self._data.set_axis(axis, labels)\n",
      "  File \"C:\\Users\\admin\\Anaconda3\\lib\\site-packages\\pandas\\core\\internals\\managers.py\", line 183, in set_axis\n",
      "    \"values have {new} elements\".format(old=old_len, new=new_len)\n",
      "ValueError: Length mismatch: Expected axis has 1 elements, new values have 2 elements\n",
      "Exception on /_dash-update-component [POST]\n",
      "Traceback (most recent call last):\n",
      "  File \"C:\\Users\\admin\\Anaconda3\\lib\\site-packages\\flask\\app.py\", line 2446, in wsgi_app\n",
      "    response = self.full_dispatch_request()\n",
      "  File \"C:\\Users\\admin\\Anaconda3\\lib\\site-packages\\flask\\app.py\", line 1951, in full_dispatch_request\n",
      "    rv = self.handle_user_exception(e)\n",
      "  File \"C:\\Users\\admin\\Anaconda3\\lib\\site-packages\\flask\\app.py\", line 1820, in handle_user_exception\n",
      "    reraise(exc_type, exc_value, tb)\n",
      "  File \"C:\\Users\\admin\\Anaconda3\\lib\\site-packages\\flask\\_compat.py\", line 39, in reraise\n",
      "    raise value\n",
      "  File \"C:\\Users\\admin\\Anaconda3\\lib\\site-packages\\flask\\app.py\", line 1949, in full_dispatch_request\n",
      "    rv = self.dispatch_request()\n",
      "  File \"C:\\Users\\admin\\Anaconda3\\lib\\site-packages\\flask\\app.py\", line 1935, in dispatch_request\n",
      "    return self.view_functions[rule.endpoint](**req.view_args)\n",
      "  File \"C:\\Users\\admin\\Anaconda3\\lib\\site-packages\\dash\\dash.py\", line 1079, in dispatch\n",
      "    response.set_data(func(*args, outputs_list=outputs_list))\n",
      "  File \"C:\\Users\\admin\\Anaconda3\\lib\\site-packages\\dash\\dash.py\", line 1010, in add_context\n",
      "    output_value = func(*args, **kwargs)  # %% callback invoked %%\n",
      "  File \"<ipython-input-19-a827d4c88365>\", line 111, in pie_graph_product\n",
      "    data3.columns = ['판매량','여부']\n",
      "  File \"C:\\Users\\admin\\Anaconda3\\lib\\site-packages\\pandas\\core\\generic.py\", line 5192, in __setattr__\n",
      "    return object.__setattr__(self, name, value)\n",
      "  File \"pandas\\_libs\\properties.pyx\", line 67, in pandas._libs.properties.AxisProperty.__set__\n",
      "  File \"C:\\Users\\admin\\Anaconda3\\lib\\site-packages\\pandas\\core\\generic.py\", line 690, in _set_axis\n",
      "    self._data.set_axis(axis, labels)\n",
      "  File \"C:\\Users\\admin\\Anaconda3\\lib\\site-packages\\pandas\\core\\internals\\managers.py\", line 183, in set_axis\n",
      "    \"values have {new} elements\".format(old=old_len, new=new_len)\n",
      "ValueError: Length mismatch: Expected axis has 1 elements, new values have 2 elements\n",
      "Exception on /_dash-update-component [POST]\n",
      "Traceback (most recent call last):\n",
      "  File \"C:\\Users\\admin\\Anaconda3\\lib\\site-packages\\flask\\app.py\", line 2446, in wsgi_app\n",
      "    response = self.full_dispatch_request()\n",
      "  File \"C:\\Users\\admin\\Anaconda3\\lib\\site-packages\\flask\\app.py\", line 1951, in full_dispatch_request\n",
      "    rv = self.handle_user_exception(e)\n",
      "  File \"C:\\Users\\admin\\Anaconda3\\lib\\site-packages\\flask\\app.py\", line 1820, in handle_user_exception\n",
      "    reraise(exc_type, exc_value, tb)\n",
      "  File \"C:\\Users\\admin\\Anaconda3\\lib\\site-packages\\flask\\_compat.py\", line 39, in reraise\n",
      "    raise value\n",
      "  File \"C:\\Users\\admin\\Anaconda3\\lib\\site-packages\\flask\\app.py\", line 1949, in full_dispatch_request\n",
      "    rv = self.dispatch_request()\n",
      "  File \"C:\\Users\\admin\\Anaconda3\\lib\\site-packages\\flask\\app.py\", line 1935, in dispatch_request\n",
      "    return self.view_functions[rule.endpoint](**req.view_args)\n",
      "  File \"C:\\Users\\admin\\Anaconda3\\lib\\site-packages\\dash\\dash.py\", line 1079, in dispatch\n",
      "    response.set_data(func(*args, outputs_list=outputs_list))\n",
      "  File \"C:\\Users\\admin\\Anaconda3\\lib\\site-packages\\dash\\dash.py\", line 1010, in add_context\n",
      "    output_value = func(*args, **kwargs)  # %% callback invoked %%\n",
      "  File \"<ipython-input-19-a827d4c88365>\", line 111, in pie_graph_product\n",
      "    data3.columns = ['판매량','여부']\n",
      "  File \"C:\\Users\\admin\\Anaconda3\\lib\\site-packages\\pandas\\core\\generic.py\", line 5192, in __setattr__\n",
      "    return object.__setattr__(self, name, value)\n",
      "  File \"pandas\\_libs\\properties.pyx\", line 67, in pandas._libs.properties.AxisProperty.__set__\n",
      "  File \"C:\\Users\\admin\\Anaconda3\\lib\\site-packages\\pandas\\core\\generic.py\", line 690, in _set_axis\n",
      "    self._data.set_axis(axis, labels)\n",
      "  File \"C:\\Users\\admin\\Anaconda3\\lib\\site-packages\\pandas\\core\\internals\\managers.py\", line 183, in set_axis\n",
      "    \"values have {new} elements\".format(old=old_len, new=new_len)\n",
      "ValueError: Length mismatch: Expected axis has 1 elements, new values have 2 elements\n",
      "Exception on /_dash-update-component [POST]\n",
      "Traceback (most recent call last):\n",
      "  File \"C:\\Users\\admin\\Anaconda3\\lib\\site-packages\\flask\\app.py\", line 2446, in wsgi_app\n",
      "    response = self.full_dispatch_request()\n",
      "  File \"C:\\Users\\admin\\Anaconda3\\lib\\site-packages\\flask\\app.py\", line 1951, in full_dispatch_request\n",
      "    rv = self.handle_user_exception(e)\n",
      "  File \"C:\\Users\\admin\\Anaconda3\\lib\\site-packages\\flask\\app.py\", line 1820, in handle_user_exception\n",
      "    reraise(exc_type, exc_value, tb)\n",
      "  File \"C:\\Users\\admin\\Anaconda3\\lib\\site-packages\\flask\\_compat.py\", line 39, in reraise\n",
      "    raise value\n",
      "  File \"C:\\Users\\admin\\Anaconda3\\lib\\site-packages\\flask\\app.py\", line 1949, in full_dispatch_request\n",
      "    rv = self.dispatch_request()\n",
      "  File \"C:\\Users\\admin\\Anaconda3\\lib\\site-packages\\flask\\app.py\", line 1935, in dispatch_request\n",
      "    return self.view_functions[rule.endpoint](**req.view_args)\n",
      "  File \"C:\\Users\\admin\\Anaconda3\\lib\\site-packages\\dash\\dash.py\", line 1079, in dispatch\n",
      "    response.set_data(func(*args, outputs_list=outputs_list))\n",
      "  File \"C:\\Users\\admin\\Anaconda3\\lib\\site-packages\\dash\\dash.py\", line 1010, in add_context\n",
      "    output_value = func(*args, **kwargs)  # %% callback invoked %%\n",
      "  File \"<ipython-input-19-a827d4c88365>\", line 111, in pie_graph_product\n",
      "    data3.columns = ['판매량','여부']\n",
      "  File \"C:\\Users\\admin\\Anaconda3\\lib\\site-packages\\pandas\\core\\generic.py\", line 5192, in __setattr__\n",
      "    return object.__setattr__(self, name, value)\n",
      "  File \"pandas\\_libs\\properties.pyx\", line 67, in pandas._libs.properties.AxisProperty.__set__\n",
      "  File \"C:\\Users\\admin\\Anaconda3\\lib\\site-packages\\pandas\\core\\generic.py\", line 690, in _set_axis\n",
      "    self._data.set_axis(axis, labels)\n",
      "  File \"C:\\Users\\admin\\Anaconda3\\lib\\site-packages\\pandas\\core\\internals\\managers.py\", line 183, in set_axis\n",
      "    \"values have {new} elements\".format(old=old_len, new=new_len)\n",
      "ValueError: Length mismatch: Expected axis has 1 elements, new values have 2 elements\n",
      "Exception on /_dash-update-component [POST]\n",
      "Traceback (most recent call last):\n",
      "  File \"C:\\Users\\admin\\Anaconda3\\lib\\site-packages\\flask\\app.py\", line 2446, in wsgi_app\n",
      "    response = self.full_dispatch_request()\n",
      "  File \"C:\\Users\\admin\\Anaconda3\\lib\\site-packages\\flask\\app.py\", line 1951, in full_dispatch_request\n",
      "    rv = self.handle_user_exception(e)\n",
      "  File \"C:\\Users\\admin\\Anaconda3\\lib\\site-packages\\flask\\app.py\", line 1820, in handle_user_exception\n",
      "    reraise(exc_type, exc_value, tb)\n",
      "  File \"C:\\Users\\admin\\Anaconda3\\lib\\site-packages\\flask\\_compat.py\", line 39, in reraise\n",
      "    raise value\n",
      "  File \"C:\\Users\\admin\\Anaconda3\\lib\\site-packages\\flask\\app.py\", line 1949, in full_dispatch_request\n",
      "    rv = self.dispatch_request()\n",
      "  File \"C:\\Users\\admin\\Anaconda3\\lib\\site-packages\\flask\\app.py\", line 1935, in dispatch_request\n",
      "    return self.view_functions[rule.endpoint](**req.view_args)\n",
      "  File \"C:\\Users\\admin\\Anaconda3\\lib\\site-packages\\dash\\dash.py\", line 1079, in dispatch\n",
      "    response.set_data(func(*args, outputs_list=outputs_list))\n",
      "  File \"C:\\Users\\admin\\Anaconda3\\lib\\site-packages\\dash\\dash.py\", line 1010, in add_context\n",
      "    output_value = func(*args, **kwargs)  # %% callback invoked %%\n",
      "  File \"<ipython-input-19-a827d4c88365>\", line 111, in pie_graph_product\n",
      "    data3.columns = ['판매량','여부']\n",
      "  File \"C:\\Users\\admin\\Anaconda3\\lib\\site-packages\\pandas\\core\\generic.py\", line 5192, in __setattr__\n",
      "    return object.__setattr__(self, name, value)\n",
      "  File \"pandas\\_libs\\properties.pyx\", line 67, in pandas._libs.properties.AxisProperty.__set__\n",
      "  File \"C:\\Users\\admin\\Anaconda3\\lib\\site-packages\\pandas\\core\\generic.py\", line 690, in _set_axis\n",
      "    self._data.set_axis(axis, labels)\n",
      "  File \"C:\\Users\\admin\\Anaconda3\\lib\\site-packages\\pandas\\core\\internals\\managers.py\", line 183, in set_axis\n",
      "    \"values have {new} elements\".format(old=old_len, new=new_len)\n",
      "ValueError: Length mismatch: Expected axis has 1 elements, new values have 2 elements\n"
     ]
    },
    {
     "name": "stderr",
     "output_type": "stream",
     "text": [
      "192.168.0.129 - - [03/Jun/2021 16:29:56] \"POST /_dash-update-component HTTP/1.1\" 500 -\n",
      "192.168.0.129 - - [03/Jun/2021 16:29:57] \"POST /_dash-update-component HTTP/1.1\" 200 -\n"
     ]
    },
    {
     "name": "stdout",
     "output_type": "stream",
     "text": [
      "Exception on /_dash-update-component [POST]\n",
      "Traceback (most recent call last):\n",
      "  File \"C:\\Users\\admin\\Anaconda3\\lib\\site-packages\\flask\\app.py\", line 2446, in wsgi_app\n",
      "    response = self.full_dispatch_request()\n",
      "  File \"C:\\Users\\admin\\Anaconda3\\lib\\site-packages\\flask\\app.py\", line 1951, in full_dispatch_request\n",
      "    rv = self.handle_user_exception(e)\n",
      "  File \"C:\\Users\\admin\\Anaconda3\\lib\\site-packages\\flask\\app.py\", line 1820, in handle_user_exception\n",
      "    reraise(exc_type, exc_value, tb)\n",
      "  File \"C:\\Users\\admin\\Anaconda3\\lib\\site-packages\\flask\\_compat.py\", line 39, in reraise\n",
      "    raise value\n",
      "  File \"C:\\Users\\admin\\Anaconda3\\lib\\site-packages\\flask\\app.py\", line 1949, in full_dispatch_request\n",
      "    rv = self.dispatch_request()\n",
      "  File \"C:\\Users\\admin\\Anaconda3\\lib\\site-packages\\flask\\app.py\", line 1935, in dispatch_request\n",
      "    return self.view_functions[rule.endpoint](**req.view_args)\n",
      "  File \"C:\\Users\\admin\\Anaconda3\\lib\\site-packages\\dash\\dash.py\", line 1079, in dispatch\n",
      "    response.set_data(func(*args, outputs_list=outputs_list))\n",
      "  File \"C:\\Users\\admin\\Anaconda3\\lib\\site-packages\\dash\\dash.py\", line 1010, in add_context\n",
      "    output_value = func(*args, **kwargs)  # %% callback invoked %%\n",
      "  File \"<ipython-input-19-a827d4c88365>\", line 74, in bar_graph_sex\n",
      "    fig = px.bar(data1, x=data1.middle, y=data1.qty, template = 'plotly_dark', text = data1.qty)\n",
      "  File \"C:\\Users\\admin\\Anaconda3\\lib\\site-packages\\plotly\\express\\_chart_types.py\", line 354, in bar\n",
      "    layout_patch=dict(barmode=barmode),\n",
      "  File \"C:\\Users\\admin\\Anaconda3\\lib\\site-packages\\plotly\\express\\_core.py\", line 1861, in make_figure\n",
      "    args = build_dataframe(args, constructor)\n",
      "  File \"C:\\Users\\admin\\Anaconda3\\lib\\site-packages\\plotly\\express\\_core.py\", line 1300, in build_dataframe\n",
      "    \"Cannot accept list of column references or list of columns for both `x` and `y`.\"\n",
      "ValueError: Cannot accept list of column references or list of columns for both `x` and `y`.\n",
      "Exception on /_dash-update-component [POST]\n",
      "Traceback (most recent call last):\n",
      "  File \"C:\\Users\\admin\\Anaconda3\\lib\\site-packages\\flask\\app.py\", line 2446, in wsgi_app\n",
      "    response = self.full_dispatch_request()\n",
      "  File \"C:\\Users\\admin\\Anaconda3\\lib\\site-packages\\flask\\app.py\", line 1951, in full_dispatch_request\n",
      "    rv = self.handle_user_exception(e)\n",
      "  File \"C:\\Users\\admin\\Anaconda3\\lib\\site-packages\\flask\\app.py\", line 1820, in handle_user_exception\n",
      "    reraise(exc_type, exc_value, tb)\n",
      "  File \"C:\\Users\\admin\\Anaconda3\\lib\\site-packages\\flask\\_compat.py\", line 39, in reraise\n",
      "    raise value\n",
      "  File \"C:\\Users\\admin\\Anaconda3\\lib\\site-packages\\flask\\app.py\", line 1949, in full_dispatch_request\n",
      "    rv = self.dispatch_request()\n",
      "  File \"C:\\Users\\admin\\Anaconda3\\lib\\site-packages\\flask\\app.py\", line 1935, in dispatch_request\n",
      "    return self.view_functions[rule.endpoint](**req.view_args)\n",
      "  File \"C:\\Users\\admin\\Anaconda3\\lib\\site-packages\\dash\\dash.py\", line 1079, in dispatch\n",
      "    response.set_data(func(*args, outputs_list=outputs_list))\n",
      "  File \"C:\\Users\\admin\\Anaconda3\\lib\\site-packages\\dash\\dash.py\", line 1010, in add_context\n",
      "    output_value = func(*args, **kwargs)  # %% callback invoked %%\n",
      "  File \"<ipython-input-19-a827d4c88365>\", line 74, in bar_graph_sex\n",
      "    fig = px.bar(data1, x=data1.middle, y=data1.qty, template = 'plotly_dark', text = data1.qty)\n",
      "  File \"C:\\Users\\admin\\Anaconda3\\lib\\site-packages\\plotly\\express\\_chart_types.py\", line 354, in bar\n",
      "    layout_patch=dict(barmode=barmode),\n",
      "  File \"C:\\Users\\admin\\Anaconda3\\lib\\site-packages\\plotly\\express\\_core.py\", line 1861, in make_figure\n",
      "    args = build_dataframe(args, constructor)\n",
      "  File \"C:\\Users\\admin\\Anaconda3\\lib\\site-packages\\plotly\\express\\_core.py\", line 1300, in build_dataframe\n",
      "    \"Cannot accept list of column references or list of columns for both `x` and `y`.\"\n",
      "ValueError: Cannot accept list of column references or list of columns for both `x` and `y`.\n",
      "Exception on /_dash-update-component [POST]\n",
      "Traceback (most recent call last):\n",
      "  File \"C:\\Users\\admin\\Anaconda3\\lib\\site-packages\\flask\\app.py\", line 2446, in wsgi_app\n",
      "    response = self.full_dispatch_request()\n",
      "  File \"C:\\Users\\admin\\Anaconda3\\lib\\site-packages\\flask\\app.py\", line 1951, in full_dispatch_request\n",
      "    rv = self.handle_user_exception(e)\n",
      "  File \"C:\\Users\\admin\\Anaconda3\\lib\\site-packages\\flask\\app.py\", line 1820, in handle_user_exception\n",
      "    reraise(exc_type, exc_value, tb)\n",
      "  File \"C:\\Users\\admin\\Anaconda3\\lib\\site-packages\\flask\\_compat.py\", line 39, in reraise\n",
      "    raise value\n",
      "  File \"C:\\Users\\admin\\Anaconda3\\lib\\site-packages\\flask\\app.py\", line 1949, in full_dispatch_request\n",
      "    rv = self.dispatch_request()\n",
      "  File \"C:\\Users\\admin\\Anaconda3\\lib\\site-packages\\flask\\app.py\", line 1935, in dispatch_request\n",
      "    return self.view_functions[rule.endpoint](**req.view_args)\n",
      "  File \"C:\\Users\\admin\\Anaconda3\\lib\\site-packages\\dash\\dash.py\", line 1079, in dispatch\n",
      "    response.set_data(func(*args, outputs_list=outputs_list))\n",
      "  File \"C:\\Users\\admin\\Anaconda3\\lib\\site-packages\\dash\\dash.py\", line 1010, in add_context\n",
      "    output_value = func(*args, **kwargs)  # %% callback invoked %%\n",
      "  File \"<ipython-input-19-a827d4c88365>\", line 74, in bar_graph_sex\n",
      "    fig = px.bar(data1, x=data1.middle, y=data1.qty, template = 'plotly_dark', text = data1.qty)\n",
      "  File \"C:\\Users\\admin\\Anaconda3\\lib\\site-packages\\plotly\\express\\_chart_types.py\", line 354, in bar\n",
      "    layout_patch=dict(barmode=barmode),\n",
      "  File \"C:\\Users\\admin\\Anaconda3\\lib\\site-packages\\plotly\\express\\_core.py\", line 1861, in make_figure\n",
      "    args = build_dataframe(args, constructor)\n",
      "  File \"C:\\Users\\admin\\Anaconda3\\lib\\site-packages\\plotly\\express\\_core.py\", line 1300, in build_dataframe\n",
      "    \"Cannot accept list of column references or list of columns for both `x` and `y`.\"\n",
      "ValueError: Cannot accept list of column references or list of columns for both `x` and `y`.\n",
      "Exception on /_dash-update-component [POST]\n",
      "Traceback (most recent call last):\n",
      "  File \"C:\\Users\\admin\\Anaconda3\\lib\\site-packages\\flask\\app.py\", line 2446, in wsgi_app\n",
      "    response = self.full_dispatch_request()\n",
      "  File \"C:\\Users\\admin\\Anaconda3\\lib\\site-packages\\flask\\app.py\", line 1951, in full_dispatch_request\n",
      "    rv = self.handle_user_exception(e)\n",
      "  File \"C:\\Users\\admin\\Anaconda3\\lib\\site-packages\\flask\\app.py\", line 1820, in handle_user_exception\n",
      "    reraise(exc_type, exc_value, tb)\n",
      "  File \"C:\\Users\\admin\\Anaconda3\\lib\\site-packages\\flask\\_compat.py\", line 39, in reraise\n",
      "    raise value\n",
      "  File \"C:\\Users\\admin\\Anaconda3\\lib\\site-packages\\flask\\app.py\", line 1949, in full_dispatch_request\n",
      "    rv = self.dispatch_request()\n",
      "  File \"C:\\Users\\admin\\Anaconda3\\lib\\site-packages\\flask\\app.py\", line 1935, in dispatch_request\n",
      "    return self.view_functions[rule.endpoint](**req.view_args)\n",
      "  File \"C:\\Users\\admin\\Anaconda3\\lib\\site-packages\\dash\\dash.py\", line 1079, in dispatch\n",
      "    response.set_data(func(*args, outputs_list=outputs_list))\n",
      "  File \"C:\\Users\\admin\\Anaconda3\\lib\\site-packages\\dash\\dash.py\", line 1010, in add_context\n",
      "    output_value = func(*args, **kwargs)  # %% callback invoked %%\n",
      "  File \"<ipython-input-19-a827d4c88365>\", line 43, in bar_graph_age\n",
      "    fig = px.bar(data1, x=data1.middle, y=data1.qty, template = 'plotly_dark', text = data1.qty)\n",
      "  File \"C:\\Users\\admin\\Anaconda3\\lib\\site-packages\\plotly\\express\\_chart_types.py\", line 354, in bar\n",
      "    layout_patch=dict(barmode=barmode),\n",
      "  File \"C:\\Users\\admin\\Anaconda3\\lib\\site-packages\\plotly\\express\\_core.py\", line 1861, in make_figure\n",
      "    args = build_dataframe(args, constructor)\n",
      "  File \"C:\\Users\\admin\\Anaconda3\\lib\\site-packages\\plotly\\express\\_core.py\", line 1300, in build_dataframe\n",
      "    \"Cannot accept list of column references or list of columns for both `x` and `y`.\"\n",
      "ValueError: Cannot accept list of column references or list of columns for both `x` and `y`.\n",
      "Exception on /_dash-update-component [POST]\n",
      "Traceback (most recent call last):\n",
      "  File \"C:\\Users\\admin\\Anaconda3\\lib\\site-packages\\flask\\app.py\", line 2446, in wsgi_app\n",
      "    response = self.full_dispatch_request()\n",
      "  File \"C:\\Users\\admin\\Anaconda3\\lib\\site-packages\\flask\\app.py\", line 1951, in full_dispatch_request\n",
      "    rv = self.handle_user_exception(e)\n",
      "  File \"C:\\Users\\admin\\Anaconda3\\lib\\site-packages\\flask\\app.py\", line 1820, in handle_user_exception\n",
      "    reraise(exc_type, exc_value, tb)\n",
      "  File \"C:\\Users\\admin\\Anaconda3\\lib\\site-packages\\flask\\_compat.py\", line 39, in reraise\n",
      "    raise value\n",
      "  File \"C:\\Users\\admin\\Anaconda3\\lib\\site-packages\\flask\\app.py\", line 1949, in full_dispatch_request\n",
      "    rv = self.dispatch_request()\n",
      "  File \"C:\\Users\\admin\\Anaconda3\\lib\\site-packages\\flask\\app.py\", line 1935, in dispatch_request\n",
      "    return self.view_functions[rule.endpoint](**req.view_args)\n",
      "  File \"C:\\Users\\admin\\Anaconda3\\lib\\site-packages\\dash\\dash.py\", line 1079, in dispatch\n",
      "    response.set_data(func(*args, outputs_list=outputs_list))\n",
      "  File \"C:\\Users\\admin\\Anaconda3\\lib\\site-packages\\dash\\dash.py\", line 1010, in add_context\n",
      "    output_value = func(*args, **kwargs)  # %% callback invoked %%\n",
      "  File \"<ipython-input-19-a827d4c88365>\", line 74, in bar_graph_sex\n",
      "    fig = px.bar(data1, x=data1.middle, y=data1.qty, template = 'plotly_dark', text = data1.qty)\n",
      "  File \"C:\\Users\\admin\\Anaconda3\\lib\\site-packages\\plotly\\express\\_chart_types.py\", line 354, in bar\n",
      "    layout_patch=dict(barmode=barmode),\n",
      "  File \"C:\\Users\\admin\\Anaconda3\\lib\\site-packages\\plotly\\express\\_core.py\", line 1861, in make_figure\n",
      "    args = build_dataframe(args, constructor)\n",
      "  File \"C:\\Users\\admin\\Anaconda3\\lib\\site-packages\\plotly\\express\\_core.py\", line 1300, in build_dataframe\n",
      "    \"Cannot accept list of column references or list of columns for both `x` and `y`.\"\n",
      "ValueError: Cannot accept list of column references or list of columns for both `x` and `y`.\n",
      "Exception on /_dash-update-component [POST]\n",
      "Traceback (most recent call last):\n",
      "  File \"C:\\Users\\admin\\Anaconda3\\lib\\site-packages\\flask\\app.py\", line 2446, in wsgi_app\n",
      "    response = self.full_dispatch_request()\n",
      "  File \"C:\\Users\\admin\\Anaconda3\\lib\\site-packages\\flask\\app.py\", line 1951, in full_dispatch_request\n",
      "    rv = self.handle_user_exception(e)\n",
      "  File \"C:\\Users\\admin\\Anaconda3\\lib\\site-packages\\flask\\app.py\", line 1820, in handle_user_exception\n",
      "    reraise(exc_type, exc_value, tb)\n",
      "  File \"C:\\Users\\admin\\Anaconda3\\lib\\site-packages\\flask\\_compat.py\", line 39, in reraise\n",
      "    raise value\n",
      "  File \"C:\\Users\\admin\\Anaconda3\\lib\\site-packages\\flask\\app.py\", line 1949, in full_dispatch_request\n",
      "    rv = self.dispatch_request()\n",
      "  File \"C:\\Users\\admin\\Anaconda3\\lib\\site-packages\\flask\\app.py\", line 1935, in dispatch_request\n",
      "    return self.view_functions[rule.endpoint](**req.view_args)\n",
      "  File \"C:\\Users\\admin\\Anaconda3\\lib\\site-packages\\dash\\dash.py\", line 1079, in dispatch\n",
      "    response.set_data(func(*args, outputs_list=outputs_list))\n",
      "  File \"C:\\Users\\admin\\Anaconda3\\lib\\site-packages\\dash\\dash.py\", line 1010, in add_context\n",
      "    output_value = func(*args, **kwargs)  # %% callback invoked %%\n",
      "  File \"<ipython-input-19-a827d4c88365>\", line 43, in bar_graph_age\n",
      "    fig = px.bar(data1, x=data1.middle, y=data1.qty, template = 'plotly_dark', text = data1.qty)\n",
      "  File \"C:\\Users\\admin\\Anaconda3\\lib\\site-packages\\plotly\\express\\_chart_types.py\", line 354, in bar\n",
      "    layout_patch=dict(barmode=barmode),\n",
      "  File \"C:\\Users\\admin\\Anaconda3\\lib\\site-packages\\plotly\\express\\_core.py\", line 1861, in make_figure\n",
      "    args = build_dataframe(args, constructor)\n",
      "  File \"C:\\Users\\admin\\Anaconda3\\lib\\site-packages\\plotly\\express\\_core.py\", line 1300, in build_dataframe\n",
      "    \"Cannot accept list of column references or list of columns for both `x` and `y`.\"\n",
      "ValueError: Cannot accept list of column references or list of columns for both `x` and `y`.\n",
      "Exception on /_dash-update-component [POST]\n",
      "Traceback (most recent call last):\n",
      "  File \"C:\\Users\\admin\\Anaconda3\\lib\\site-packages\\flask\\app.py\", line 2446, in wsgi_app\n",
      "    response = self.full_dispatch_request()\n",
      "  File \"C:\\Users\\admin\\Anaconda3\\lib\\site-packages\\flask\\app.py\", line 1951, in full_dispatch_request\n",
      "    rv = self.handle_user_exception(e)\n",
      "  File \"C:\\Users\\admin\\Anaconda3\\lib\\site-packages\\flask\\app.py\", line 1820, in handle_user_exception\n",
      "    reraise(exc_type, exc_value, tb)\n",
      "  File \"C:\\Users\\admin\\Anaconda3\\lib\\site-packages\\flask\\_compat.py\", line 39, in reraise\n",
      "    raise value\n",
      "  File \"C:\\Users\\admin\\Anaconda3\\lib\\site-packages\\flask\\app.py\", line 1949, in full_dispatch_request\n",
      "    rv = self.dispatch_request()\n",
      "  File \"C:\\Users\\admin\\Anaconda3\\lib\\site-packages\\flask\\app.py\", line 1935, in dispatch_request\n",
      "    return self.view_functions[rule.endpoint](**req.view_args)\n",
      "  File \"C:\\Users\\admin\\Anaconda3\\lib\\site-packages\\dash\\dash.py\", line 1079, in dispatch\n",
      "    response.set_data(func(*args, outputs_list=outputs_list))\n",
      "  File \"C:\\Users\\admin\\Anaconda3\\lib\\site-packages\\dash\\dash.py\", line 1010, in add_context\n",
      "    output_value = func(*args, **kwargs)  # %% callback invoked %%\n",
      "  File \"<ipython-input-19-a827d4c88365>\", line 43, in bar_graph_age\n",
      "    fig = px.bar(data1, x=data1.middle, y=data1.qty, template = 'plotly_dark', text = data1.qty)\n",
      "  File \"C:\\Users\\admin\\Anaconda3\\lib\\site-packages\\plotly\\express\\_chart_types.py\", line 354, in bar\n",
      "    layout_patch=dict(barmode=barmode),\n",
      "  File \"C:\\Users\\admin\\Anaconda3\\lib\\site-packages\\plotly\\express\\_core.py\", line 1861, in make_figure\n",
      "    args = build_dataframe(args, constructor)\n",
      "  File \"C:\\Users\\admin\\Anaconda3\\lib\\site-packages\\plotly\\express\\_core.py\", line 1300, in build_dataframe\n",
      "    \"Cannot accept list of column references or list of columns for both `x` and `y`.\"\n",
      "ValueError: Cannot accept list of column references or list of columns for both `x` and `y`.\n",
      "Exception on /_dash-update-component [POST]\n",
      "Traceback (most recent call last):\n",
      "  File \"C:\\Users\\admin\\Anaconda3\\lib\\site-packages\\flask\\app.py\", line 2446, in wsgi_app\n",
      "    response = self.full_dispatch_request()\n",
      "  File \"C:\\Users\\admin\\Anaconda3\\lib\\site-packages\\flask\\app.py\", line 1951, in full_dispatch_request\n",
      "    rv = self.handle_user_exception(e)\n",
      "  File \"C:\\Users\\admin\\Anaconda3\\lib\\site-packages\\flask\\app.py\", line 1820, in handle_user_exception\n",
      "    reraise(exc_type, exc_value, tb)\n",
      "  File \"C:\\Users\\admin\\Anaconda3\\lib\\site-packages\\flask\\_compat.py\", line 39, in reraise\n",
      "    raise value\n",
      "  File \"C:\\Users\\admin\\Anaconda3\\lib\\site-packages\\flask\\app.py\", line 1949, in full_dispatch_request\n",
      "    rv = self.dispatch_request()\n",
      "  File \"C:\\Users\\admin\\Anaconda3\\lib\\site-packages\\flask\\app.py\", line 1935, in dispatch_request\n",
      "    return self.view_functions[rule.endpoint](**req.view_args)\n",
      "  File \"C:\\Users\\admin\\Anaconda3\\lib\\site-packages\\dash\\dash.py\", line 1079, in dispatch\n",
      "    response.set_data(func(*args, outputs_list=outputs_list))\n",
      "  File \"C:\\Users\\admin\\Anaconda3\\lib\\site-packages\\dash\\dash.py\", line 1010, in add_context\n",
      "    output_value = func(*args, **kwargs)  # %% callback invoked %%\n",
      "  File \"<ipython-input-19-a827d4c88365>\", line 74, in bar_graph_sex\n",
      "    fig = px.bar(data1, x=data1.middle, y=data1.qty, template = 'plotly_dark', text = data1.qty)\n",
      "  File \"C:\\Users\\admin\\Anaconda3\\lib\\site-packages\\plotly\\express\\_chart_types.py\", line 354, in bar\n",
      "    layout_patch=dict(barmode=barmode),\n",
      "  File \"C:\\Users\\admin\\Anaconda3\\lib\\site-packages\\plotly\\express\\_core.py\", line 1861, in make_figure\n",
      "    args = build_dataframe(args, constructor)\n",
      "  File \"C:\\Users\\admin\\Anaconda3\\lib\\site-packages\\plotly\\express\\_core.py\", line 1300, in build_dataframe\n",
      "    \"Cannot accept list of column references or list of columns for both `x` and `y`.\"\n",
      "ValueError: Cannot accept list of column references or list of columns for both `x` and `y`.\n",
      "Exception on /_dash-update-component [POST]\n",
      "Traceback (most recent call last):\n",
      "  File \"C:\\Users\\admin\\Anaconda3\\lib\\site-packages\\flask\\app.py\", line 2446, in wsgi_app\n",
      "    response = self.full_dispatch_request()\n",
      "  File \"C:\\Users\\admin\\Anaconda3\\lib\\site-packages\\flask\\app.py\", line 1951, in full_dispatch_request\n",
      "    rv = self.handle_user_exception(e)\n",
      "  File \"C:\\Users\\admin\\Anaconda3\\lib\\site-packages\\flask\\app.py\", line 1820, in handle_user_exception\n",
      "    reraise(exc_type, exc_value, tb)\n",
      "  File \"C:\\Users\\admin\\Anaconda3\\lib\\site-packages\\flask\\_compat.py\", line 39, in reraise\n",
      "    raise value\n",
      "  File \"C:\\Users\\admin\\Anaconda3\\lib\\site-packages\\flask\\app.py\", line 1949, in full_dispatch_request\n",
      "    rv = self.dispatch_request()\n",
      "  File \"C:\\Users\\admin\\Anaconda3\\lib\\site-packages\\flask\\app.py\", line 1935, in dispatch_request\n",
      "    return self.view_functions[rule.endpoint](**req.view_args)\n",
      "  File \"C:\\Users\\admin\\Anaconda3\\lib\\site-packages\\dash\\dash.py\", line 1079, in dispatch\n",
      "    response.set_data(func(*args, outputs_list=outputs_list))\n",
      "  File \"C:\\Users\\admin\\Anaconda3\\lib\\site-packages\\dash\\dash.py\", line 1010, in add_context\n",
      "    output_value = func(*args, **kwargs)  # %% callback invoked %%\n",
      "  File \"<ipython-input-19-a827d4c88365>\", line 43, in bar_graph_age\n",
      "    fig = px.bar(data1, x=data1.middle, y=data1.qty, template = 'plotly_dark', text = data1.qty)\n",
      "  File \"C:\\Users\\admin\\Anaconda3\\lib\\site-packages\\plotly\\express\\_chart_types.py\", line 354, in bar\n",
      "    layout_patch=dict(barmode=barmode),\n",
      "  File \"C:\\Users\\admin\\Anaconda3\\lib\\site-packages\\plotly\\express\\_core.py\", line 1861, in make_figure\n",
      "    args = build_dataframe(args, constructor)\n",
      "  File \"C:\\Users\\admin\\Anaconda3\\lib\\site-packages\\plotly\\express\\_core.py\", line 1300, in build_dataframe\n",
      "    \"Cannot accept list of column references or list of columns for both `x` and `y`.\"\n",
      "ValueError: Cannot accept list of column references or list of columns for both `x` and `y`.\n"
     ]
    },
    {
     "name": "stderr",
     "output_type": "stream",
     "text": [
      "192.168.0.129 - - [03/Jun/2021 16:29:57] \"POST /_dash-update-component HTTP/1.1\" 500 -\n"
     ]
    },
    {
     "name": "stdout",
     "output_type": "stream",
     "text": [
      "Exception on /_dash-update-component [POST]\n",
      "Traceback (most recent call last):\n",
      "  File \"C:\\Users\\admin\\Anaconda3\\lib\\site-packages\\flask\\app.py\", line 2446, in wsgi_app\n",
      "    response = self.full_dispatch_request()\n",
      "  File \"C:\\Users\\admin\\Anaconda3\\lib\\site-packages\\flask\\app.py\", line 1951, in full_dispatch_request\n",
      "    rv = self.handle_user_exception(e)\n",
      "  File \"C:\\Users\\admin\\Anaconda3\\lib\\site-packages\\flask\\app.py\", line 1820, in handle_user_exception\n",
      "    reraise(exc_type, exc_value, tb)\n",
      "  File \"C:\\Users\\admin\\Anaconda3\\lib\\site-packages\\flask\\_compat.py\", line 39, in reraise\n",
      "    raise value\n",
      "  File \"C:\\Users\\admin\\Anaconda3\\lib\\site-packages\\flask\\app.py\", line 1949, in full_dispatch_request\n",
      "    rv = self.dispatch_request()\n",
      "  File \"C:\\Users\\admin\\Anaconda3\\lib\\site-packages\\flask\\app.py\", line 1935, in dispatch_request\n",
      "    return self.view_functions[rule.endpoint](**req.view_args)\n",
      "  File \"C:\\Users\\admin\\Anaconda3\\lib\\site-packages\\dash\\dash.py\", line 1079, in dispatch\n",
      "    response.set_data(func(*args, outputs_list=outputs_list))\n",
      "  File \"C:\\Users\\admin\\Anaconda3\\lib\\site-packages\\dash\\dash.py\", line 1010, in add_context\n",
      "    output_value = func(*args, **kwargs)  # %% callback invoked %%\n",
      "  File \"<ipython-input-19-a827d4c88365>\", line 43, in bar_graph_age\n",
      "    fig = px.bar(data1, x=data1.middle, y=data1.qty, template = 'plotly_dark', text = data1.qty)\n",
      "  File \"C:\\Users\\admin\\Anaconda3\\lib\\site-packages\\plotly\\express\\_chart_types.py\", line 354, in bar\n",
      "    layout_patch=dict(barmode=barmode),\n",
      "  File \"C:\\Users\\admin\\Anaconda3\\lib\\site-packages\\plotly\\express\\_core.py\", line 1861, in make_figure\n",
      "    args = build_dataframe(args, constructor)\n",
      "  File \"C:\\Users\\admin\\Anaconda3\\lib\\site-packages\\plotly\\express\\_core.py\", line 1300, in build_dataframe\n",
      "    \"Cannot accept list of column references or list of columns for both `x` and `y`.\"\n",
      "ValueError: Cannot accept list of column references or list of columns for both `x` and `y`.\n"
     ]
    },
    {
     "name": "stderr",
     "output_type": "stream",
     "text": [
      "192.168.0.129 - - [03/Jun/2021 16:29:57] \"POST /_dash-update-component HTTP/1.1\" 500 -\n"
     ]
    },
    {
     "name": "stdout",
     "output_type": "stream",
     "text": [
      "Exception on /_dash-update-component [POST]\n",
      "Traceback (most recent call last):\n",
      "  File \"C:\\Users\\admin\\Anaconda3\\lib\\site-packages\\flask\\app.py\", line 2446, in wsgi_app\n",
      "    response = self.full_dispatch_request()\n",
      "  File \"C:\\Users\\admin\\Anaconda3\\lib\\site-packages\\flask\\app.py\", line 1951, in full_dispatch_request\n",
      "    rv = self.handle_user_exception(e)\n",
      "  File \"C:\\Users\\admin\\Anaconda3\\lib\\site-packages\\flask\\app.py\", line 1820, in handle_user_exception\n",
      "    reraise(exc_type, exc_value, tb)\n",
      "  File \"C:\\Users\\admin\\Anaconda3\\lib\\site-packages\\flask\\_compat.py\", line 39, in reraise\n",
      "    raise value\n",
      "  File \"C:\\Users\\admin\\Anaconda3\\lib\\site-packages\\flask\\app.py\", line 1949, in full_dispatch_request\n",
      "    rv = self.dispatch_request()\n",
      "  File \"C:\\Users\\admin\\Anaconda3\\lib\\site-packages\\flask\\app.py\", line 1935, in dispatch_request\n",
      "    return self.view_functions[rule.endpoint](**req.view_args)\n",
      "  File \"C:\\Users\\admin\\Anaconda3\\lib\\site-packages\\dash\\dash.py\", line 1079, in dispatch\n",
      "    response.set_data(func(*args, outputs_list=outputs_list))\n",
      "  File \"C:\\Users\\admin\\Anaconda3\\lib\\site-packages\\dash\\dash.py\", line 1010, in add_context\n",
      "    output_value = func(*args, **kwargs)  # %% callback invoked %%\n",
      "  File \"<ipython-input-19-a827d4c88365>\", line 111, in pie_graph_product\n",
      "    data3.columns = ['판매량','여부']\n",
      "  File \"C:\\Users\\admin\\Anaconda3\\lib\\site-packages\\pandas\\core\\generic.py\", line 5192, in __setattr__\n",
      "    return object.__setattr__(self, name, value)\n",
      "  File \"pandas\\_libs\\properties.pyx\", line 67, in pandas._libs.properties.AxisProperty.__set__\n",
      "  File \"C:\\Users\\admin\\Anaconda3\\lib\\site-packages\\pandas\\core\\generic.py\", line 690, in _set_axis\n",
      "    self._data.set_axis(axis, labels)\n",
      "  File \"C:\\Users\\admin\\Anaconda3\\lib\\site-packages\\pandas\\core\\internals\\managers.py\", line 183, in set_axis\n",
      "    \"values have {new} elements\".format(old=old_len, new=new_len)\n",
      "ValueError: Length mismatch: Expected axis has 1 elements, new values have 2 elements\n",
      "Exception on /_dash-update-component [POST]\n",
      "Traceback (most recent call last):\n",
      "  File \"C:\\Users\\admin\\Anaconda3\\lib\\site-packages\\flask\\app.py\", line 2446, in wsgi_app\n",
      "    response = self.full_dispatch_request()\n",
      "  File \"C:\\Users\\admin\\Anaconda3\\lib\\site-packages\\flask\\app.py\", line 1951, in full_dispatch_request\n",
      "    rv = self.handle_user_exception(e)\n",
      "  File \"C:\\Users\\admin\\Anaconda3\\lib\\site-packages\\flask\\app.py\", line 1820, in handle_user_exception\n",
      "    reraise(exc_type, exc_value, tb)\n",
      "  File \"C:\\Users\\admin\\Anaconda3\\lib\\site-packages\\flask\\_compat.py\", line 39, in reraise\n",
      "    raise value\n",
      "  File \"C:\\Users\\admin\\Anaconda3\\lib\\site-packages\\flask\\app.py\", line 1949, in full_dispatch_request\n",
      "    rv = self.dispatch_request()\n",
      "  File \"C:\\Users\\admin\\Anaconda3\\lib\\site-packages\\flask\\app.py\", line 1935, in dispatch_request\n",
      "    return self.view_functions[rule.endpoint](**req.view_args)\n",
      "  File \"C:\\Users\\admin\\Anaconda3\\lib\\site-packages\\dash\\dash.py\", line 1079, in dispatch\n",
      "    response.set_data(func(*args, outputs_list=outputs_list))\n",
      "  File \"C:\\Users\\admin\\Anaconda3\\lib\\site-packages\\dash\\dash.py\", line 1010, in add_context\n",
      "    output_value = func(*args, **kwargs)  # %% callback invoked %%\n",
      "  File \"<ipython-input-19-a827d4c88365>\", line 111, in pie_graph_product\n",
      "    data3.columns = ['판매량','여부']\n",
      "  File \"C:\\Users\\admin\\Anaconda3\\lib\\site-packages\\pandas\\core\\generic.py\", line 5192, in __setattr__\n",
      "    return object.__setattr__(self, name, value)\n",
      "  File \"pandas\\_libs\\properties.pyx\", line 67, in pandas._libs.properties.AxisProperty.__set__\n",
      "  File \"C:\\Users\\admin\\Anaconda3\\lib\\site-packages\\pandas\\core\\generic.py\", line 690, in _set_axis\n",
      "    self._data.set_axis(axis, labels)\n",
      "  File \"C:\\Users\\admin\\Anaconda3\\lib\\site-packages\\pandas\\core\\internals\\managers.py\", line 183, in set_axis\n",
      "    \"values have {new} elements\".format(old=old_len, new=new_len)\n",
      "ValueError: Length mismatch: Expected axis has 1 elements, new values have 2 elements\n",
      "Exception on /_dash-update-component [POST]\n",
      "Traceback (most recent call last):\n",
      "  File \"C:\\Users\\admin\\Anaconda3\\lib\\site-packages\\flask\\app.py\", line 2446, in wsgi_app\n",
      "    response = self.full_dispatch_request()\n",
      "  File \"C:\\Users\\admin\\Anaconda3\\lib\\site-packages\\flask\\app.py\", line 1951, in full_dispatch_request\n",
      "    rv = self.handle_user_exception(e)\n",
      "  File \"C:\\Users\\admin\\Anaconda3\\lib\\site-packages\\flask\\app.py\", line 1820, in handle_user_exception\n",
      "    reraise(exc_type, exc_value, tb)\n",
      "  File \"C:\\Users\\admin\\Anaconda3\\lib\\site-packages\\flask\\_compat.py\", line 39, in reraise\n",
      "    raise value\n",
      "  File \"C:\\Users\\admin\\Anaconda3\\lib\\site-packages\\flask\\app.py\", line 1949, in full_dispatch_request\n",
      "    rv = self.dispatch_request()\n",
      "  File \"C:\\Users\\admin\\Anaconda3\\lib\\site-packages\\flask\\app.py\", line 1935, in dispatch_request\n",
      "    return self.view_functions[rule.endpoint](**req.view_args)\n",
      "  File \"C:\\Users\\admin\\Anaconda3\\lib\\site-packages\\dash\\dash.py\", line 1079, in dispatch\n",
      "    response.set_data(func(*args, outputs_list=outputs_list))\n",
      "  File \"C:\\Users\\admin\\Anaconda3\\lib\\site-packages\\dash\\dash.py\", line 1010, in add_context\n",
      "    output_value = func(*args, **kwargs)  # %% callback invoked %%\n",
      "  File \"<ipython-input-19-a827d4c88365>\", line 111, in pie_graph_product\n",
      "    data3.columns = ['판매량','여부']\n",
      "  File \"C:\\Users\\admin\\Anaconda3\\lib\\site-packages\\pandas\\core\\generic.py\", line 5192, in __setattr__\n",
      "    return object.__setattr__(self, name, value)\n",
      "  File \"pandas\\_libs\\properties.pyx\", line 67, in pandas._libs.properties.AxisProperty.__set__\n",
      "  File \"C:\\Users\\admin\\Anaconda3\\lib\\site-packages\\pandas\\core\\generic.py\", line 690, in _set_axis\n",
      "    self._data.set_axis(axis, labels)\n",
      "  File \"C:\\Users\\admin\\Anaconda3\\lib\\site-packages\\pandas\\core\\internals\\managers.py\", line 183, in set_axis\n",
      "    \"values have {new} elements\".format(old=old_len, new=new_len)\n",
      "ValueError: Length mismatch: Expected axis has 1 elements, new values have 2 elements\n",
      "Exception on /_dash-update-component [POST]\n",
      "Traceback (most recent call last):\n",
      "  File \"C:\\Users\\admin\\Anaconda3\\lib\\site-packages\\flask\\app.py\", line 2446, in wsgi_app\n",
      "    response = self.full_dispatch_request()\n",
      "  File \"C:\\Users\\admin\\Anaconda3\\lib\\site-packages\\flask\\app.py\", line 1951, in full_dispatch_request\n",
      "    rv = self.handle_user_exception(e)\n",
      "  File \"C:\\Users\\admin\\Anaconda3\\lib\\site-packages\\flask\\app.py\", line 1820, in handle_user_exception\n",
      "    reraise(exc_type, exc_value, tb)\n",
      "  File \"C:\\Users\\admin\\Anaconda3\\lib\\site-packages\\flask\\_compat.py\", line 39, in reraise\n",
      "    raise value\n",
      "  File \"C:\\Users\\admin\\Anaconda3\\lib\\site-packages\\flask\\app.py\", line 1949, in full_dispatch_request\n",
      "    rv = self.dispatch_request()\n",
      "  File \"C:\\Users\\admin\\Anaconda3\\lib\\site-packages\\flask\\app.py\", line 1935, in dispatch_request\n",
      "    return self.view_functions[rule.endpoint](**req.view_args)\n",
      "  File \"C:\\Users\\admin\\Anaconda3\\lib\\site-packages\\dash\\dash.py\", line 1079, in dispatch\n",
      "    response.set_data(func(*args, outputs_list=outputs_list))\n",
      "  File \"C:\\Users\\admin\\Anaconda3\\lib\\site-packages\\dash\\dash.py\", line 1010, in add_context\n",
      "    output_value = func(*args, **kwargs)  # %% callback invoked %%\n",
      "  File \"<ipython-input-19-a827d4c88365>\", line 111, in pie_graph_product\n",
      "    data3.columns = ['판매량','여부']\n",
      "  File \"C:\\Users\\admin\\Anaconda3\\lib\\site-packages\\pandas\\core\\generic.py\", line 5192, in __setattr__\n",
      "    return object.__setattr__(self, name, value)\n",
      "  File \"pandas\\_libs\\properties.pyx\", line 67, in pandas._libs.properties.AxisProperty.__set__\n",
      "  File \"C:\\Users\\admin\\Anaconda3\\lib\\site-packages\\pandas\\core\\generic.py\", line 690, in _set_axis\n",
      "    self._data.set_axis(axis, labels)\n",
      "  File \"C:\\Users\\admin\\Anaconda3\\lib\\site-packages\\pandas\\core\\internals\\managers.py\", line 183, in set_axis\n",
      "    \"values have {new} elements\".format(old=old_len, new=new_len)\n",
      "ValueError: Length mismatch: Expected axis has 1 elements, new values have 2 elements\n",
      "Exception on /_dash-update-component [POST]\n",
      "Traceback (most recent call last):\n",
      "  File \"C:\\Users\\admin\\Anaconda3\\lib\\site-packages\\flask\\app.py\", line 2446, in wsgi_app\n",
      "    response = self.full_dispatch_request()\n",
      "  File \"C:\\Users\\admin\\Anaconda3\\lib\\site-packages\\flask\\app.py\", line 1951, in full_dispatch_request\n",
      "    rv = self.handle_user_exception(e)\n",
      "  File \"C:\\Users\\admin\\Anaconda3\\lib\\site-packages\\flask\\app.py\", line 1820, in handle_user_exception\n",
      "    reraise(exc_type, exc_value, tb)\n",
      "  File \"C:\\Users\\admin\\Anaconda3\\lib\\site-packages\\flask\\_compat.py\", line 39, in reraise\n",
      "    raise value\n",
      "  File \"C:\\Users\\admin\\Anaconda3\\lib\\site-packages\\flask\\app.py\", line 1949, in full_dispatch_request\n",
      "    rv = self.dispatch_request()\n",
      "  File \"C:\\Users\\admin\\Anaconda3\\lib\\site-packages\\flask\\app.py\", line 1935, in dispatch_request\n",
      "    return self.view_functions[rule.endpoint](**req.view_args)\n",
      "  File \"C:\\Users\\admin\\Anaconda3\\lib\\site-packages\\dash\\dash.py\", line 1079, in dispatch\n",
      "    response.set_data(func(*args, outputs_list=outputs_list))\n",
      "  File \"C:\\Users\\admin\\Anaconda3\\lib\\site-packages\\dash\\dash.py\", line 1010, in add_context\n",
      "    output_value = func(*args, **kwargs)  # %% callback invoked %%\n",
      "  File \"<ipython-input-19-a827d4c88365>\", line 111, in pie_graph_product\n",
      "    data3.columns = ['판매량','여부']\n",
      "  File \"C:\\Users\\admin\\Anaconda3\\lib\\site-packages\\pandas\\core\\generic.py\", line 5192, in __setattr__\n",
      "    return object.__setattr__(self, name, value)\n",
      "  File \"pandas\\_libs\\properties.pyx\", line 67, in pandas._libs.properties.AxisProperty.__set__\n",
      "  File \"C:\\Users\\admin\\Anaconda3\\lib\\site-packages\\pandas\\core\\generic.py\", line 690, in _set_axis\n",
      "    self._data.set_axis(axis, labels)\n",
      "  File \"C:\\Users\\admin\\Anaconda3\\lib\\site-packages\\pandas\\core\\internals\\managers.py\", line 183, in set_axis\n",
      "    \"values have {new} elements\".format(old=old_len, new=new_len)\n",
      "ValueError: Length mismatch: Expected axis has 1 elements, new values have 2 elements\n"
     ]
    },
    {
     "name": "stderr",
     "output_type": "stream",
     "text": [
      "192.168.0.129 - - [03/Jun/2021 16:29:57] \"POST /_dash-update-component HTTP/1.1\" 500 -\n",
      "192.168.0.129 - - [03/Jun/2021 16:29:58] \"POST /_dash-update-component HTTP/1.1\" 200 -\n"
     ]
    },
    {
     "name": "stdout",
     "output_type": "stream",
     "text": [
      "Exception on /_dash-update-component [POST]\n",
      "Traceback (most recent call last):\n",
      "  File \"C:\\Users\\admin\\Anaconda3\\lib\\site-packages\\flask\\app.py\", line 2446, in wsgi_app\n",
      "    response = self.full_dispatch_request()\n",
      "  File \"C:\\Users\\admin\\Anaconda3\\lib\\site-packages\\flask\\app.py\", line 1951, in full_dispatch_request\n",
      "    rv = self.handle_user_exception(e)\n",
      "  File \"C:\\Users\\admin\\Anaconda3\\lib\\site-packages\\flask\\app.py\", line 1820, in handle_user_exception\n",
      "    reraise(exc_type, exc_value, tb)\n",
      "  File \"C:\\Users\\admin\\Anaconda3\\lib\\site-packages\\flask\\_compat.py\", line 39, in reraise\n",
      "    raise value\n",
      "  File \"C:\\Users\\admin\\Anaconda3\\lib\\site-packages\\flask\\app.py\", line 1949, in full_dispatch_request\n",
      "    rv = self.dispatch_request()\n",
      "  File \"C:\\Users\\admin\\Anaconda3\\lib\\site-packages\\flask\\app.py\", line 1935, in dispatch_request\n",
      "    return self.view_functions[rule.endpoint](**req.view_args)\n",
      "  File \"C:\\Users\\admin\\Anaconda3\\lib\\site-packages\\dash\\dash.py\", line 1079, in dispatch\n",
      "    response.set_data(func(*args, outputs_list=outputs_list))\n",
      "  File \"C:\\Users\\admin\\Anaconda3\\lib\\site-packages\\dash\\dash.py\", line 1010, in add_context\n",
      "    output_value = func(*args, **kwargs)  # %% callback invoked %%\n",
      "  File \"<ipython-input-19-a827d4c88365>\", line 43, in bar_graph_age\n",
      "    fig = px.bar(data1, x=data1.middle, y=data1.qty, template = 'plotly_dark', text = data1.qty)\n",
      "  File \"C:\\Users\\admin\\Anaconda3\\lib\\site-packages\\plotly\\express\\_chart_types.py\", line 354, in bar\n",
      "    layout_patch=dict(barmode=barmode),\n",
      "  File \"C:\\Users\\admin\\Anaconda3\\lib\\site-packages\\plotly\\express\\_core.py\", line 1861, in make_figure\n",
      "    args = build_dataframe(args, constructor)\n",
      "  File \"C:\\Users\\admin\\Anaconda3\\lib\\site-packages\\plotly\\express\\_core.py\", line 1300, in build_dataframe\n",
      "    \"Cannot accept list of column references or list of columns for both `x` and `y`.\"\n",
      "ValueError: Cannot accept list of column references or list of columns for both `x` and `y`.\n",
      "Exception on /_dash-update-component [POST]\n",
      "Traceback (most recent call last):\n",
      "  File \"C:\\Users\\admin\\Anaconda3\\lib\\site-packages\\flask\\app.py\", line 2446, in wsgi_app\n",
      "    response = self.full_dispatch_request()\n",
      "  File \"C:\\Users\\admin\\Anaconda3\\lib\\site-packages\\flask\\app.py\", line 1951, in full_dispatch_request\n",
      "    rv = self.handle_user_exception(e)\n",
      "  File \"C:\\Users\\admin\\Anaconda3\\lib\\site-packages\\flask\\app.py\", line 1820, in handle_user_exception\n",
      "    reraise(exc_type, exc_value, tb)\n",
      "  File \"C:\\Users\\admin\\Anaconda3\\lib\\site-packages\\flask\\_compat.py\", line 39, in reraise\n",
      "    raise value\n",
      "  File \"C:\\Users\\admin\\Anaconda3\\lib\\site-packages\\flask\\app.py\", line 1949, in full_dispatch_request\n",
      "    rv = self.dispatch_request()\n",
      "  File \"C:\\Users\\admin\\Anaconda3\\lib\\site-packages\\flask\\app.py\", line 1935, in dispatch_request\n",
      "    return self.view_functions[rule.endpoint](**req.view_args)\n",
      "  File \"C:\\Users\\admin\\Anaconda3\\lib\\site-packages\\dash\\dash.py\", line 1079, in dispatch\n",
      "    response.set_data(func(*args, outputs_list=outputs_list))\n",
      "  File \"C:\\Users\\admin\\Anaconda3\\lib\\site-packages\\dash\\dash.py\", line 1010, in add_context\n",
      "    output_value = func(*args, **kwargs)  # %% callback invoked %%\n",
      "  File \"<ipython-input-19-a827d4c88365>\", line 43, in bar_graph_age\n",
      "    fig = px.bar(data1, x=data1.middle, y=data1.qty, template = 'plotly_dark', text = data1.qty)\n",
      "  File \"C:\\Users\\admin\\Anaconda3\\lib\\site-packages\\plotly\\express\\_chart_types.py\", line 354, in bar\n",
      "    layout_patch=dict(barmode=barmode),\n",
      "  File \"C:\\Users\\admin\\Anaconda3\\lib\\site-packages\\plotly\\express\\_core.py\", line 1861, in make_figure\n",
      "    args = build_dataframe(args, constructor)\n",
      "  File \"C:\\Users\\admin\\Anaconda3\\lib\\site-packages\\plotly\\express\\_core.py\", line 1300, in build_dataframe\n",
      "    \"Cannot accept list of column references or list of columns for both `x` and `y`.\"\n",
      "ValueError: Cannot accept list of column references or list of columns for both `x` and `y`.\n",
      "Exception on /_dash-update-component [POST]\n",
      "Traceback (most recent call last):\n",
      "  File \"C:\\Users\\admin\\Anaconda3\\lib\\site-packages\\flask\\app.py\", line 2446, in wsgi_app\n",
      "    response = self.full_dispatch_request()\n",
      "  File \"C:\\Users\\admin\\Anaconda3\\lib\\site-packages\\flask\\app.py\", line 1951, in full_dispatch_request\n",
      "    rv = self.handle_user_exception(e)\n",
      "  File \"C:\\Users\\admin\\Anaconda3\\lib\\site-packages\\flask\\app.py\", line 1820, in handle_user_exception\n",
      "    reraise(exc_type, exc_value, tb)\n",
      "  File \"C:\\Users\\admin\\Anaconda3\\lib\\site-packages\\flask\\_compat.py\", line 39, in reraise\n",
      "    raise value\n",
      "  File \"C:\\Users\\admin\\Anaconda3\\lib\\site-packages\\flask\\app.py\", line 1949, in full_dispatch_request\n",
      "    rv = self.dispatch_request()\n",
      "  File \"C:\\Users\\admin\\Anaconda3\\lib\\site-packages\\flask\\app.py\", line 1935, in dispatch_request\n",
      "    return self.view_functions[rule.endpoint](**req.view_args)\n",
      "  File \"C:\\Users\\admin\\Anaconda3\\lib\\site-packages\\dash\\dash.py\", line 1079, in dispatch\n",
      "    response.set_data(func(*args, outputs_list=outputs_list))\n",
      "  File \"C:\\Users\\admin\\Anaconda3\\lib\\site-packages\\dash\\dash.py\", line 1010, in add_context\n",
      "    output_value = func(*args, **kwargs)  # %% callback invoked %%\n",
      "  File \"<ipython-input-19-a827d4c88365>\", line 43, in bar_graph_age\n",
      "    fig = px.bar(data1, x=data1.middle, y=data1.qty, template = 'plotly_dark', text = data1.qty)\n",
      "  File \"C:\\Users\\admin\\Anaconda3\\lib\\site-packages\\plotly\\express\\_chart_types.py\", line 354, in bar\n",
      "    layout_patch=dict(barmode=barmode),\n",
      "  File \"C:\\Users\\admin\\Anaconda3\\lib\\site-packages\\plotly\\express\\_core.py\", line 1861, in make_figure\n",
      "    args = build_dataframe(args, constructor)\n",
      "  File \"C:\\Users\\admin\\Anaconda3\\lib\\site-packages\\plotly\\express\\_core.py\", line 1300, in build_dataframe\n",
      "    \"Cannot accept list of column references or list of columns for both `x` and `y`.\"\n",
      "ValueError: Cannot accept list of column references or list of columns for both `x` and `y`.\n",
      "Exception on /_dash-update-component [POST]\n",
      "Traceback (most recent call last):\n",
      "  File \"C:\\Users\\admin\\Anaconda3\\lib\\site-packages\\flask\\app.py\", line 2446, in wsgi_app\n",
      "    response = self.full_dispatch_request()\n",
      "  File \"C:\\Users\\admin\\Anaconda3\\lib\\site-packages\\flask\\app.py\", line 1951, in full_dispatch_request\n",
      "    rv = self.handle_user_exception(e)\n",
      "  File \"C:\\Users\\admin\\Anaconda3\\lib\\site-packages\\flask\\app.py\", line 1820, in handle_user_exception\n",
      "    reraise(exc_type, exc_value, tb)\n",
      "  File \"C:\\Users\\admin\\Anaconda3\\lib\\site-packages\\flask\\_compat.py\", line 39, in reraise\n",
      "    raise value\n",
      "  File \"C:\\Users\\admin\\Anaconda3\\lib\\site-packages\\flask\\app.py\", line 1949, in full_dispatch_request\n",
      "    rv = self.dispatch_request()\n",
      "  File \"C:\\Users\\admin\\Anaconda3\\lib\\site-packages\\flask\\app.py\", line 1935, in dispatch_request\n",
      "    return self.view_functions[rule.endpoint](**req.view_args)\n",
      "  File \"C:\\Users\\admin\\Anaconda3\\lib\\site-packages\\dash\\dash.py\", line 1079, in dispatch\n",
      "    response.set_data(func(*args, outputs_list=outputs_list))\n",
      "  File \"C:\\Users\\admin\\Anaconda3\\lib\\site-packages\\dash\\dash.py\", line 1010, in add_context\n",
      "    output_value = func(*args, **kwargs)  # %% callback invoked %%\n",
      "  File \"<ipython-input-19-a827d4c88365>\", line 74, in bar_graph_sex\n",
      "    fig = px.bar(data1, x=data1.middle, y=data1.qty, template = 'plotly_dark', text = data1.qty)\n",
      "  File \"C:\\Users\\admin\\Anaconda3\\lib\\site-packages\\plotly\\express\\_chart_types.py\", line 354, in bar\n",
      "    layout_patch=dict(barmode=barmode),\n",
      "  File \"C:\\Users\\admin\\Anaconda3\\lib\\site-packages\\plotly\\express\\_core.py\", line 1861, in make_figure\n",
      "    args = build_dataframe(args, constructor)\n",
      "  File \"C:\\Users\\admin\\Anaconda3\\lib\\site-packages\\plotly\\express\\_core.py\", line 1300, in build_dataframe\n",
      "    \"Cannot accept list of column references or list of columns for both `x` and `y`.\"\n",
      "ValueError: Cannot accept list of column references or list of columns for both `x` and `y`.\n",
      "Exception on /_dash-update-component [POST]\n",
      "Traceback (most recent call last):\n",
      "  File \"C:\\Users\\admin\\Anaconda3\\lib\\site-packages\\flask\\app.py\", line 2446, in wsgi_app\n",
      "    response = self.full_dispatch_request()\n",
      "  File \"C:\\Users\\admin\\Anaconda3\\lib\\site-packages\\flask\\app.py\", line 1951, in full_dispatch_request\n",
      "    rv = self.handle_user_exception(e)\n",
      "  File \"C:\\Users\\admin\\Anaconda3\\lib\\site-packages\\flask\\app.py\", line 1820, in handle_user_exception\n",
      "    reraise(exc_type, exc_value, tb)\n",
      "  File \"C:\\Users\\admin\\Anaconda3\\lib\\site-packages\\flask\\_compat.py\", line 39, in reraise\n",
      "    raise value\n",
      "  File \"C:\\Users\\admin\\Anaconda3\\lib\\site-packages\\flask\\app.py\", line 1949, in full_dispatch_request\n",
      "    rv = self.dispatch_request()\n",
      "  File \"C:\\Users\\admin\\Anaconda3\\lib\\site-packages\\flask\\app.py\", line 1935, in dispatch_request\n",
      "    return self.view_functions[rule.endpoint](**req.view_args)\n",
      "  File \"C:\\Users\\admin\\Anaconda3\\lib\\site-packages\\dash\\dash.py\", line 1079, in dispatch\n",
      "    response.set_data(func(*args, outputs_list=outputs_list))\n",
      "  File \"C:\\Users\\admin\\Anaconda3\\lib\\site-packages\\dash\\dash.py\", line 1010, in add_context\n",
      "    output_value = func(*args, **kwargs)  # %% callback invoked %%\n",
      "  File \"<ipython-input-19-a827d4c88365>\", line 43, in bar_graph_age\n",
      "    fig = px.bar(data1, x=data1.middle, y=data1.qty, template = 'plotly_dark', text = data1.qty)\n",
      "  File \"C:\\Users\\admin\\Anaconda3\\lib\\site-packages\\plotly\\express\\_chart_types.py\", line 354, in bar\n",
      "    layout_patch=dict(barmode=barmode),\n",
      "  File \"C:\\Users\\admin\\Anaconda3\\lib\\site-packages\\plotly\\express\\_core.py\", line 1861, in make_figure\n",
      "    args = build_dataframe(args, constructor)\n",
      "  File \"C:\\Users\\admin\\Anaconda3\\lib\\site-packages\\plotly\\express\\_core.py\", line 1300, in build_dataframe\n",
      "    \"Cannot accept list of column references or list of columns for both `x` and `y`.\"\n",
      "ValueError: Cannot accept list of column references or list of columns for both `x` and `y`.\n",
      "Exception on /_dash-update-component [POST]\n",
      "Traceback (most recent call last):\n",
      "  File \"C:\\Users\\admin\\Anaconda3\\lib\\site-packages\\flask\\app.py\", line 2446, in wsgi_app\n",
      "    response = self.full_dispatch_request()\n",
      "  File \"C:\\Users\\admin\\Anaconda3\\lib\\site-packages\\flask\\app.py\", line 1951, in full_dispatch_request\n",
      "    rv = self.handle_user_exception(e)\n",
      "  File \"C:\\Users\\admin\\Anaconda3\\lib\\site-packages\\flask\\app.py\", line 1820, in handle_user_exception\n",
      "    reraise(exc_type, exc_value, tb)\n",
      "  File \"C:\\Users\\admin\\Anaconda3\\lib\\site-packages\\flask\\_compat.py\", line 39, in reraise\n",
      "    raise value\n",
      "  File \"C:\\Users\\admin\\Anaconda3\\lib\\site-packages\\flask\\app.py\", line 1949, in full_dispatch_request\n",
      "    rv = self.dispatch_request()\n",
      "  File \"C:\\Users\\admin\\Anaconda3\\lib\\site-packages\\flask\\app.py\", line 1935, in dispatch_request\n",
      "    return self.view_functions[rule.endpoint](**req.view_args)\n",
      "  File \"C:\\Users\\admin\\Anaconda3\\lib\\site-packages\\dash\\dash.py\", line 1079, in dispatch\n",
      "    response.set_data(func(*args, outputs_list=outputs_list))\n",
      "  File \"C:\\Users\\admin\\Anaconda3\\lib\\site-packages\\dash\\dash.py\", line 1010, in add_context\n",
      "    output_value = func(*args, **kwargs)  # %% callback invoked %%\n",
      "  File \"<ipython-input-19-a827d4c88365>\", line 74, in bar_graph_sex\n",
      "    fig = px.bar(data1, x=data1.middle, y=data1.qty, template = 'plotly_dark', text = data1.qty)\n",
      "  File \"C:\\Users\\admin\\Anaconda3\\lib\\site-packages\\plotly\\express\\_chart_types.py\", line 354, in bar\n",
      "    layout_patch=dict(barmode=barmode),\n",
      "  File \"C:\\Users\\admin\\Anaconda3\\lib\\site-packages\\plotly\\express\\_core.py\", line 1861, in make_figure\n",
      "    args = build_dataframe(args, constructor)\n",
      "  File \"C:\\Users\\admin\\Anaconda3\\lib\\site-packages\\plotly\\express\\_core.py\", line 1300, in build_dataframe\n",
      "    \"Cannot accept list of column references or list of columns for both `x` and `y`.\"\n",
      "ValueError: Cannot accept list of column references or list of columns for both `x` and `y`.\n",
      "Exception on /_dash-update-component [POST]\n",
      "Traceback (most recent call last):\n",
      "  File \"C:\\Users\\admin\\Anaconda3\\lib\\site-packages\\flask\\app.py\", line 2446, in wsgi_app\n",
      "    response = self.full_dispatch_request()\n",
      "  File \"C:\\Users\\admin\\Anaconda3\\lib\\site-packages\\flask\\app.py\", line 1951, in full_dispatch_request\n",
      "    rv = self.handle_user_exception(e)\n",
      "  File \"C:\\Users\\admin\\Anaconda3\\lib\\site-packages\\flask\\app.py\", line 1820, in handle_user_exception\n",
      "    reraise(exc_type, exc_value, tb)\n",
      "  File \"C:\\Users\\admin\\Anaconda3\\lib\\site-packages\\flask\\_compat.py\", line 39, in reraise\n",
      "    raise value\n",
      "  File \"C:\\Users\\admin\\Anaconda3\\lib\\site-packages\\flask\\app.py\", line 1949, in full_dispatch_request\n",
      "    rv = self.dispatch_request()\n",
      "  File \"C:\\Users\\admin\\Anaconda3\\lib\\site-packages\\flask\\app.py\", line 1935, in dispatch_request\n",
      "    return self.view_functions[rule.endpoint](**req.view_args)\n",
      "  File \"C:\\Users\\admin\\Anaconda3\\lib\\site-packages\\dash\\dash.py\", line 1079, in dispatch\n",
      "    response.set_data(func(*args, outputs_list=outputs_list))\n",
      "  File \"C:\\Users\\admin\\Anaconda3\\lib\\site-packages\\dash\\dash.py\", line 1010, in add_context\n",
      "    output_value = func(*args, **kwargs)  # %% callback invoked %%\n",
      "  File \"<ipython-input-19-a827d4c88365>\", line 43, in bar_graph_age\n",
      "    fig = px.bar(data1, x=data1.middle, y=data1.qty, template = 'plotly_dark', text = data1.qty)\n",
      "  File \"C:\\Users\\admin\\Anaconda3\\lib\\site-packages\\plotly\\express\\_chart_types.py\", line 354, in bar\n",
      "    layout_patch=dict(barmode=barmode),\n",
      "  File \"C:\\Users\\admin\\Anaconda3\\lib\\site-packages\\plotly\\express\\_core.py\", line 1861, in make_figure\n",
      "    args = build_dataframe(args, constructor)\n",
      "  File \"C:\\Users\\admin\\Anaconda3\\lib\\site-packages\\plotly\\express\\_core.py\", line 1300, in build_dataframe\n",
      "    \"Cannot accept list of column references or list of columns for both `x` and `y`.\"\n",
      "ValueError: Cannot accept list of column references or list of columns for both `x` and `y`.\n",
      "Exception on /_dash-update-component [POST]\n",
      "Traceback (most recent call last):\n",
      "  File \"C:\\Users\\admin\\Anaconda3\\lib\\site-packages\\flask\\app.py\", line 2446, in wsgi_app\n",
      "    response = self.full_dispatch_request()\n",
      "  File \"C:\\Users\\admin\\Anaconda3\\lib\\site-packages\\flask\\app.py\", line 1951, in full_dispatch_request\n",
      "    rv = self.handle_user_exception(e)\n",
      "  File \"C:\\Users\\admin\\Anaconda3\\lib\\site-packages\\flask\\app.py\", line 1820, in handle_user_exception\n",
      "    reraise(exc_type, exc_value, tb)\n",
      "  File \"C:\\Users\\admin\\Anaconda3\\lib\\site-packages\\flask\\_compat.py\", line 39, in reraise\n",
      "    raise value\n",
      "  File \"C:\\Users\\admin\\Anaconda3\\lib\\site-packages\\flask\\app.py\", line 1949, in full_dispatch_request\n",
      "    rv = self.dispatch_request()\n",
      "  File \"C:\\Users\\admin\\Anaconda3\\lib\\site-packages\\flask\\app.py\", line 1935, in dispatch_request\n",
      "    return self.view_functions[rule.endpoint](**req.view_args)\n",
      "  File \"C:\\Users\\admin\\Anaconda3\\lib\\site-packages\\dash\\dash.py\", line 1079, in dispatch\n",
      "    response.set_data(func(*args, outputs_list=outputs_list))\n",
      "  File \"C:\\Users\\admin\\Anaconda3\\lib\\site-packages\\dash\\dash.py\", line 1010, in add_context\n",
      "    output_value = func(*args, **kwargs)  # %% callback invoked %%\n",
      "  File \"<ipython-input-19-a827d4c88365>\", line 74, in bar_graph_sex\n",
      "    fig = px.bar(data1, x=data1.middle, y=data1.qty, template = 'plotly_dark', text = data1.qty)\n",
      "  File \"C:\\Users\\admin\\Anaconda3\\lib\\site-packages\\plotly\\express\\_chart_types.py\", line 354, in bar\n",
      "    layout_patch=dict(barmode=barmode),\n",
      "  File \"C:\\Users\\admin\\Anaconda3\\lib\\site-packages\\plotly\\express\\_core.py\", line 1861, in make_figure\n",
      "    args = build_dataframe(args, constructor)\n",
      "  File \"C:\\Users\\admin\\Anaconda3\\lib\\site-packages\\plotly\\express\\_core.py\", line 1300, in build_dataframe\n",
      "    \"Cannot accept list of column references or list of columns for both `x` and `y`.\"\n",
      "ValueError: Cannot accept list of column references or list of columns for both `x` and `y`.\n"
     ]
    },
    {
     "name": "stderr",
     "output_type": "stream",
     "text": [
      "192.168.0.129 - - [03/Jun/2021 16:29:58] \"POST /_dash-update-component HTTP/1.1\" 500 -\n"
     ]
    },
    {
     "name": "stdout",
     "output_type": "stream",
     "text": [
      "Exception on /_dash-update-component [POST]\n",
      "Traceback (most recent call last):\n",
      "  File \"C:\\Users\\admin\\Anaconda3\\lib\\site-packages\\flask\\app.py\", line 2446, in wsgi_app\n",
      "    response = self.full_dispatch_request()\n",
      "  File \"C:\\Users\\admin\\Anaconda3\\lib\\site-packages\\flask\\app.py\", line 1951, in full_dispatch_request\n",
      "    rv = self.handle_user_exception(e)\n",
      "  File \"C:\\Users\\admin\\Anaconda3\\lib\\site-packages\\flask\\app.py\", line 1820, in handle_user_exception\n",
      "    reraise(exc_type, exc_value, tb)\n",
      "  File \"C:\\Users\\admin\\Anaconda3\\lib\\site-packages\\flask\\_compat.py\", line 39, in reraise\n",
      "    raise value\n",
      "  File \"C:\\Users\\admin\\Anaconda3\\lib\\site-packages\\flask\\app.py\", line 1949, in full_dispatch_request\n",
      "    rv = self.dispatch_request()\n",
      "  File \"C:\\Users\\admin\\Anaconda3\\lib\\site-packages\\flask\\app.py\", line 1935, in dispatch_request\n",
      "    return self.view_functions[rule.endpoint](**req.view_args)\n",
      "  File \"C:\\Users\\admin\\Anaconda3\\lib\\site-packages\\dash\\dash.py\", line 1079, in dispatch\n",
      "    response.set_data(func(*args, outputs_list=outputs_list))\n",
      "  File \"C:\\Users\\admin\\Anaconda3\\lib\\site-packages\\dash\\dash.py\", line 1010, in add_context\n",
      "    output_value = func(*args, **kwargs)  # %% callback invoked %%\n",
      "  File \"<ipython-input-19-a827d4c88365>\", line 74, in bar_graph_sex\n",
      "    fig = px.bar(data1, x=data1.middle, y=data1.qty, template = 'plotly_dark', text = data1.qty)\n",
      "  File \"C:\\Users\\admin\\Anaconda3\\lib\\site-packages\\plotly\\express\\_chart_types.py\", line 354, in bar\n",
      "    layout_patch=dict(barmode=barmode),\n",
      "  File \"C:\\Users\\admin\\Anaconda3\\lib\\site-packages\\plotly\\express\\_core.py\", line 1861, in make_figure\n",
      "    args = build_dataframe(args, constructor)\n",
      "  File \"C:\\Users\\admin\\Anaconda3\\lib\\site-packages\\plotly\\express\\_core.py\", line 1300, in build_dataframe\n",
      "    \"Cannot accept list of column references or list of columns for both `x` and `y`.\"\n",
      "ValueError: Cannot accept list of column references or list of columns for both `x` and `y`.\n",
      "Exception on /_dash-update-component [POST]\n",
      "Traceback (most recent call last):\n",
      "  File \"C:\\Users\\admin\\Anaconda3\\lib\\site-packages\\flask\\app.py\", line 2446, in wsgi_app\n",
      "    response = self.full_dispatch_request()\n",
      "  File \"C:\\Users\\admin\\Anaconda3\\lib\\site-packages\\flask\\app.py\", line 1951, in full_dispatch_request\n",
      "    rv = self.handle_user_exception(e)\n",
      "  File \"C:\\Users\\admin\\Anaconda3\\lib\\site-packages\\flask\\app.py\", line 1820, in handle_user_exception\n",
      "    reraise(exc_type, exc_value, tb)\n",
      "  File \"C:\\Users\\admin\\Anaconda3\\lib\\site-packages\\flask\\_compat.py\", line 39, in reraise\n",
      "    raise value\n",
      "  File \"C:\\Users\\admin\\Anaconda3\\lib\\site-packages\\flask\\app.py\", line 1949, in full_dispatch_request\n",
      "    rv = self.dispatch_request()\n",
      "  File \"C:\\Users\\admin\\Anaconda3\\lib\\site-packages\\flask\\app.py\", line 1935, in dispatch_request\n",
      "    return self.view_functions[rule.endpoint](**req.view_args)\n",
      "  File \"C:\\Users\\admin\\Anaconda3\\lib\\site-packages\\dash\\dash.py\", line 1079, in dispatch\n",
      "    response.set_data(func(*args, outputs_list=outputs_list))\n",
      "  File \"C:\\Users\\admin\\Anaconda3\\lib\\site-packages\\dash\\dash.py\", line 1010, in add_context\n",
      "    output_value = func(*args, **kwargs)  # %% callback invoked %%\n",
      "  File \"<ipython-input-19-a827d4c88365>\", line 74, in bar_graph_sex\n",
      "    fig = px.bar(data1, x=data1.middle, y=data1.qty, template = 'plotly_dark', text = data1.qty)\n",
      "  File \"C:\\Users\\admin\\Anaconda3\\lib\\site-packages\\plotly\\express\\_chart_types.py\", line 354, in bar\n",
      "    layout_patch=dict(barmode=barmode),\n",
      "  File \"C:\\Users\\admin\\Anaconda3\\lib\\site-packages\\plotly\\express\\_core.py\", line 1861, in make_figure\n",
      "    args = build_dataframe(args, constructor)\n",
      "  File \"C:\\Users\\admin\\Anaconda3\\lib\\site-packages\\plotly\\express\\_core.py\", line 1300, in build_dataframe\n",
      "    \"Cannot accept list of column references or list of columns for both `x` and `y`.\"\n",
      "ValueError: Cannot accept list of column references or list of columns for both `x` and `y`.\n"
     ]
    },
    {
     "name": "stderr",
     "output_type": "stream",
     "text": [
      "192.168.0.129 - - [03/Jun/2021 16:29:58] \"POST /_dash-update-component HTTP/1.1\" 500 -\n"
     ]
    },
    {
     "name": "stdout",
     "output_type": "stream",
     "text": [
      "Exception on /_dash-update-component [POST]\n",
      "Traceback (most recent call last):\n",
      "  File \"C:\\Users\\admin\\Anaconda3\\lib\\site-packages\\flask\\app.py\", line 2446, in wsgi_app\n",
      "    response = self.full_dispatch_request()\n",
      "  File \"C:\\Users\\admin\\Anaconda3\\lib\\site-packages\\flask\\app.py\", line 1951, in full_dispatch_request\n",
      "    rv = self.handle_user_exception(e)\n",
      "  File \"C:\\Users\\admin\\Anaconda3\\lib\\site-packages\\flask\\app.py\", line 1820, in handle_user_exception\n",
      "    reraise(exc_type, exc_value, tb)\n",
      "  File \"C:\\Users\\admin\\Anaconda3\\lib\\site-packages\\flask\\_compat.py\", line 39, in reraise\n",
      "    raise value\n",
      "  File \"C:\\Users\\admin\\Anaconda3\\lib\\site-packages\\flask\\app.py\", line 1949, in full_dispatch_request\n",
      "    rv = self.dispatch_request()\n",
      "  File \"C:\\Users\\admin\\Anaconda3\\lib\\site-packages\\flask\\app.py\", line 1935, in dispatch_request\n",
      "    return self.view_functions[rule.endpoint](**req.view_args)\n",
      "  File \"C:\\Users\\admin\\Anaconda3\\lib\\site-packages\\dash\\dash.py\", line 1079, in dispatch\n",
      "    response.set_data(func(*args, outputs_list=outputs_list))\n",
      "  File \"C:\\Users\\admin\\Anaconda3\\lib\\site-packages\\dash\\dash.py\", line 1010, in add_context\n",
      "    output_value = func(*args, **kwargs)  # %% callback invoked %%\n",
      "  File \"<ipython-input-19-a827d4c88365>\", line 111, in pie_graph_product\n",
      "    data3.columns = ['판매량','여부']\n",
      "  File \"C:\\Users\\admin\\Anaconda3\\lib\\site-packages\\pandas\\core\\generic.py\", line 5192, in __setattr__\n",
      "    return object.__setattr__(self, name, value)\n",
      "  File \"pandas\\_libs\\properties.pyx\", line 67, in pandas._libs.properties.AxisProperty.__set__\n",
      "  File \"C:\\Users\\admin\\Anaconda3\\lib\\site-packages\\pandas\\core\\generic.py\", line 690, in _set_axis\n",
      "    self._data.set_axis(axis, labels)\n",
      "  File \"C:\\Users\\admin\\Anaconda3\\lib\\site-packages\\pandas\\core\\internals\\managers.py\", line 183, in set_axis\n",
      "    \"values have {new} elements\".format(old=old_len, new=new_len)\n",
      "ValueError: Length mismatch: Expected axis has 1 elements, new values have 2 elements\n",
      "Exception on /_dash-update-component [POST]\n",
      "Traceback (most recent call last):\n",
      "  File \"C:\\Users\\admin\\Anaconda3\\lib\\site-packages\\flask\\app.py\", line 2446, in wsgi_app\n",
      "    response = self.full_dispatch_request()\n",
      "  File \"C:\\Users\\admin\\Anaconda3\\lib\\site-packages\\flask\\app.py\", line 1951, in full_dispatch_request\n",
      "    rv = self.handle_user_exception(e)\n",
      "  File \"C:\\Users\\admin\\Anaconda3\\lib\\site-packages\\flask\\app.py\", line 1820, in handle_user_exception\n",
      "    reraise(exc_type, exc_value, tb)\n",
      "  File \"C:\\Users\\admin\\Anaconda3\\lib\\site-packages\\flask\\_compat.py\", line 39, in reraise\n",
      "    raise value\n",
      "  File \"C:\\Users\\admin\\Anaconda3\\lib\\site-packages\\flask\\app.py\", line 1949, in full_dispatch_request\n",
      "    rv = self.dispatch_request()\n",
      "  File \"C:\\Users\\admin\\Anaconda3\\lib\\site-packages\\flask\\app.py\", line 1935, in dispatch_request\n",
      "    return self.view_functions[rule.endpoint](**req.view_args)\n",
      "  File \"C:\\Users\\admin\\Anaconda3\\lib\\site-packages\\dash\\dash.py\", line 1079, in dispatch\n",
      "    response.set_data(func(*args, outputs_list=outputs_list))\n",
      "  File \"C:\\Users\\admin\\Anaconda3\\lib\\site-packages\\dash\\dash.py\", line 1010, in add_context\n",
      "    output_value = func(*args, **kwargs)  # %% callback invoked %%\n",
      "  File \"<ipython-input-19-a827d4c88365>\", line 111, in pie_graph_product\n",
      "    data3.columns = ['판매량','여부']\n",
      "  File \"C:\\Users\\admin\\Anaconda3\\lib\\site-packages\\pandas\\core\\generic.py\", line 5192, in __setattr__\n",
      "    return object.__setattr__(self, name, value)\n",
      "  File \"pandas\\_libs\\properties.pyx\", line 67, in pandas._libs.properties.AxisProperty.__set__\n",
      "  File \"C:\\Users\\admin\\Anaconda3\\lib\\site-packages\\pandas\\core\\generic.py\", line 690, in _set_axis\n",
      "    self._data.set_axis(axis, labels)\n",
      "  File \"C:\\Users\\admin\\Anaconda3\\lib\\site-packages\\pandas\\core\\internals\\managers.py\", line 183, in set_axis\n",
      "    \"values have {new} elements\".format(old=old_len, new=new_len)\n",
      "ValueError: Length mismatch: Expected axis has 1 elements, new values have 2 elements\n",
      "Exception on /_dash-update-component [POST]\n",
      "Traceback (most recent call last):\n",
      "  File \"C:\\Users\\admin\\Anaconda3\\lib\\site-packages\\flask\\app.py\", line 2446, in wsgi_app\n",
      "    response = self.full_dispatch_request()\n",
      "  File \"C:\\Users\\admin\\Anaconda3\\lib\\site-packages\\flask\\app.py\", line 1951, in full_dispatch_request\n",
      "    rv = self.handle_user_exception(e)\n",
      "  File \"C:\\Users\\admin\\Anaconda3\\lib\\site-packages\\flask\\app.py\", line 1820, in handle_user_exception\n",
      "    reraise(exc_type, exc_value, tb)\n",
      "  File \"C:\\Users\\admin\\Anaconda3\\lib\\site-packages\\flask\\_compat.py\", line 39, in reraise\n",
      "    raise value\n",
      "  File \"C:\\Users\\admin\\Anaconda3\\lib\\site-packages\\flask\\app.py\", line 1949, in full_dispatch_request\n",
      "    rv = self.dispatch_request()\n",
      "  File \"C:\\Users\\admin\\Anaconda3\\lib\\site-packages\\flask\\app.py\", line 1935, in dispatch_request\n",
      "    return self.view_functions[rule.endpoint](**req.view_args)\n",
      "  File \"C:\\Users\\admin\\Anaconda3\\lib\\site-packages\\dash\\dash.py\", line 1079, in dispatch\n",
      "    response.set_data(func(*args, outputs_list=outputs_list))\n",
      "  File \"C:\\Users\\admin\\Anaconda3\\lib\\site-packages\\dash\\dash.py\", line 1010, in add_context\n",
      "    output_value = func(*args, **kwargs)  # %% callback invoked %%\n",
      "  File \"<ipython-input-19-a827d4c88365>\", line 111, in pie_graph_product\n",
      "    data3.columns = ['판매량','여부']\n",
      "  File \"C:\\Users\\admin\\Anaconda3\\lib\\site-packages\\pandas\\core\\generic.py\", line 5192, in __setattr__\n",
      "    return object.__setattr__(self, name, value)\n",
      "  File \"pandas\\_libs\\properties.pyx\", line 67, in pandas._libs.properties.AxisProperty.__set__\n",
      "  File \"C:\\Users\\admin\\Anaconda3\\lib\\site-packages\\pandas\\core\\generic.py\", line 690, in _set_axis\n",
      "    self._data.set_axis(axis, labels)\n",
      "  File \"C:\\Users\\admin\\Anaconda3\\lib\\site-packages\\pandas\\core\\internals\\managers.py\", line 183, in set_axis\n",
      "    \"values have {new} elements\".format(old=old_len, new=new_len)\n",
      "ValueError: Length mismatch: Expected axis has 1 elements, new values have 2 elements\n",
      "Exception on /_dash-update-component [POST]\n",
      "Traceback (most recent call last):\n",
      "  File \"C:\\Users\\admin\\Anaconda3\\lib\\site-packages\\flask\\app.py\", line 2446, in wsgi_app\n",
      "    response = self.full_dispatch_request()\n",
      "  File \"C:\\Users\\admin\\Anaconda3\\lib\\site-packages\\flask\\app.py\", line 1951, in full_dispatch_request\n",
      "    rv = self.handle_user_exception(e)\n",
      "  File \"C:\\Users\\admin\\Anaconda3\\lib\\site-packages\\flask\\app.py\", line 1820, in handle_user_exception\n",
      "    reraise(exc_type, exc_value, tb)\n",
      "  File \"C:\\Users\\admin\\Anaconda3\\lib\\site-packages\\flask\\_compat.py\", line 39, in reraise\n",
      "    raise value\n",
      "  File \"C:\\Users\\admin\\Anaconda3\\lib\\site-packages\\flask\\app.py\", line 1949, in full_dispatch_request\n",
      "    rv = self.dispatch_request()\n",
      "  File \"C:\\Users\\admin\\Anaconda3\\lib\\site-packages\\flask\\app.py\", line 1935, in dispatch_request\n",
      "    return self.view_functions[rule.endpoint](**req.view_args)\n",
      "  File \"C:\\Users\\admin\\Anaconda3\\lib\\site-packages\\dash\\dash.py\", line 1079, in dispatch\n",
      "    response.set_data(func(*args, outputs_list=outputs_list))\n",
      "  File \"C:\\Users\\admin\\Anaconda3\\lib\\site-packages\\dash\\dash.py\", line 1010, in add_context\n",
      "    output_value = func(*args, **kwargs)  # %% callback invoked %%\n",
      "  File \"<ipython-input-19-a827d4c88365>\", line 111, in pie_graph_product\n",
      "    data3.columns = ['판매량','여부']\n",
      "  File \"C:\\Users\\admin\\Anaconda3\\lib\\site-packages\\pandas\\core\\generic.py\", line 5192, in __setattr__\n",
      "    return object.__setattr__(self, name, value)\n",
      "  File \"pandas\\_libs\\properties.pyx\", line 67, in pandas._libs.properties.AxisProperty.__set__\n",
      "  File \"C:\\Users\\admin\\Anaconda3\\lib\\site-packages\\pandas\\core\\generic.py\", line 690, in _set_axis\n",
      "    self._data.set_axis(axis, labels)\n",
      "  File \"C:\\Users\\admin\\Anaconda3\\lib\\site-packages\\pandas\\core\\internals\\managers.py\", line 183, in set_axis\n",
      "    \"values have {new} elements\".format(old=old_len, new=new_len)\n",
      "ValueError: Length mismatch: Expected axis has 1 elements, new values have 2 elements\n",
      "Exception on /_dash-update-component [POST]\n",
      "Traceback (most recent call last):\n",
      "  File \"C:\\Users\\admin\\Anaconda3\\lib\\site-packages\\flask\\app.py\", line 2446, in wsgi_app\n",
      "    response = self.full_dispatch_request()\n",
      "  File \"C:\\Users\\admin\\Anaconda3\\lib\\site-packages\\flask\\app.py\", line 1951, in full_dispatch_request\n",
      "    rv = self.handle_user_exception(e)\n",
      "  File \"C:\\Users\\admin\\Anaconda3\\lib\\site-packages\\flask\\app.py\", line 1820, in handle_user_exception\n",
      "    reraise(exc_type, exc_value, tb)\n",
      "  File \"C:\\Users\\admin\\Anaconda3\\lib\\site-packages\\flask\\_compat.py\", line 39, in reraise\n",
      "    raise value\n",
      "  File \"C:\\Users\\admin\\Anaconda3\\lib\\site-packages\\flask\\app.py\", line 1949, in full_dispatch_request\n",
      "    rv = self.dispatch_request()\n",
      "  File \"C:\\Users\\admin\\Anaconda3\\lib\\site-packages\\flask\\app.py\", line 1935, in dispatch_request\n",
      "    return self.view_functions[rule.endpoint](**req.view_args)\n",
      "  File \"C:\\Users\\admin\\Anaconda3\\lib\\site-packages\\dash\\dash.py\", line 1079, in dispatch\n",
      "    response.set_data(func(*args, outputs_list=outputs_list))\n",
      "  File \"C:\\Users\\admin\\Anaconda3\\lib\\site-packages\\dash\\dash.py\", line 1010, in add_context\n",
      "    output_value = func(*args, **kwargs)  # %% callback invoked %%\n",
      "  File \"<ipython-input-19-a827d4c88365>\", line 111, in pie_graph_product\n",
      "    data3.columns = ['판매량','여부']\n",
      "  File \"C:\\Users\\admin\\Anaconda3\\lib\\site-packages\\pandas\\core\\generic.py\", line 5192, in __setattr__\n",
      "    return object.__setattr__(self, name, value)\n",
      "  File \"pandas\\_libs\\properties.pyx\", line 67, in pandas._libs.properties.AxisProperty.__set__\n",
      "  File \"C:\\Users\\admin\\Anaconda3\\lib\\site-packages\\pandas\\core\\generic.py\", line 690, in _set_axis\n",
      "    self._data.set_axis(axis, labels)\n",
      "  File \"C:\\Users\\admin\\Anaconda3\\lib\\site-packages\\pandas\\core\\internals\\managers.py\", line 183, in set_axis\n",
      "    \"values have {new} elements\".format(old=old_len, new=new_len)\n",
      "ValueError: Length mismatch: Expected axis has 1 elements, new values have 2 elements\n"
     ]
    },
    {
     "name": "stderr",
     "output_type": "stream",
     "text": [
      "192.168.0.129 - - [03/Jun/2021 16:29:58] \"POST /_dash-update-component HTTP/1.1\" 500 -\n",
      "192.168.0.129 - - [03/Jun/2021 16:30:01] \"POST /_dash-update-component HTTP/1.1\" 200 -\n"
     ]
    },
    {
     "name": "stdout",
     "output_type": "stream",
     "text": [
      "Exception on /_dash-update-component [POST]\n",
      "Traceback (most recent call last):\n",
      "  File \"C:\\Users\\admin\\Anaconda3\\lib\\site-packages\\flask\\app.py\", line 2446, in wsgi_app\n",
      "    response = self.full_dispatch_request()\n",
      "  File \"C:\\Users\\admin\\Anaconda3\\lib\\site-packages\\flask\\app.py\", line 1951, in full_dispatch_request\n",
      "    rv = self.handle_user_exception(e)\n",
      "  File \"C:\\Users\\admin\\Anaconda3\\lib\\site-packages\\flask\\app.py\", line 1820, in handle_user_exception\n",
      "    reraise(exc_type, exc_value, tb)\n",
      "  File \"C:\\Users\\admin\\Anaconda3\\lib\\site-packages\\flask\\_compat.py\", line 39, in reraise\n",
      "    raise value\n",
      "  File \"C:\\Users\\admin\\Anaconda3\\lib\\site-packages\\flask\\app.py\", line 1949, in full_dispatch_request\n",
      "    rv = self.dispatch_request()\n",
      "  File \"C:\\Users\\admin\\Anaconda3\\lib\\site-packages\\flask\\app.py\", line 1935, in dispatch_request\n",
      "    return self.view_functions[rule.endpoint](**req.view_args)\n",
      "  File \"C:\\Users\\admin\\Anaconda3\\lib\\site-packages\\dash\\dash.py\", line 1079, in dispatch\n",
      "    response.set_data(func(*args, outputs_list=outputs_list))\n",
      "  File \"C:\\Users\\admin\\Anaconda3\\lib\\site-packages\\dash\\dash.py\", line 1010, in add_context\n",
      "    output_value = func(*args, **kwargs)  # %% callback invoked %%\n",
      "  File \"<ipython-input-19-a827d4c88365>\", line 43, in bar_graph_age\n",
      "    fig = px.bar(data1, x=data1.middle, y=data1.qty, template = 'plotly_dark', text = data1.qty)\n",
      "  File \"C:\\Users\\admin\\Anaconda3\\lib\\site-packages\\plotly\\express\\_chart_types.py\", line 354, in bar\n",
      "    layout_patch=dict(barmode=barmode),\n",
      "  File \"C:\\Users\\admin\\Anaconda3\\lib\\site-packages\\plotly\\express\\_core.py\", line 1861, in make_figure\n",
      "    args = build_dataframe(args, constructor)\n",
      "  File \"C:\\Users\\admin\\Anaconda3\\lib\\site-packages\\plotly\\express\\_core.py\", line 1300, in build_dataframe\n",
      "    \"Cannot accept list of column references or list of columns for both `x` and `y`.\"\n",
      "ValueError: Cannot accept list of column references or list of columns for both `x` and `y`.\n",
      "Exception on /_dash-update-component [POST]\n",
      "Traceback (most recent call last):\n",
      "  File \"C:\\Users\\admin\\Anaconda3\\lib\\site-packages\\flask\\app.py\", line 2446, in wsgi_app\n",
      "    response = self.full_dispatch_request()\n",
      "  File \"C:\\Users\\admin\\Anaconda3\\lib\\site-packages\\flask\\app.py\", line 1951, in full_dispatch_request\n",
      "    rv = self.handle_user_exception(e)\n",
      "  File \"C:\\Users\\admin\\Anaconda3\\lib\\site-packages\\flask\\app.py\", line 1820, in handle_user_exception\n",
      "    reraise(exc_type, exc_value, tb)\n",
      "  File \"C:\\Users\\admin\\Anaconda3\\lib\\site-packages\\flask\\_compat.py\", line 39, in reraise\n",
      "    raise value\n",
      "  File \"C:\\Users\\admin\\Anaconda3\\lib\\site-packages\\flask\\app.py\", line 1949, in full_dispatch_request\n",
      "    rv = self.dispatch_request()\n",
      "  File \"C:\\Users\\admin\\Anaconda3\\lib\\site-packages\\flask\\app.py\", line 1935, in dispatch_request\n",
      "    return self.view_functions[rule.endpoint](**req.view_args)\n",
      "  File \"C:\\Users\\admin\\Anaconda3\\lib\\site-packages\\dash\\dash.py\", line 1079, in dispatch\n",
      "    response.set_data(func(*args, outputs_list=outputs_list))\n",
      "  File \"C:\\Users\\admin\\Anaconda3\\lib\\site-packages\\dash\\dash.py\", line 1010, in add_context\n",
      "    output_value = func(*args, **kwargs)  # %% callback invoked %%\n",
      "  File \"<ipython-input-19-a827d4c88365>\", line 43, in bar_graph_age\n",
      "    fig = px.bar(data1, x=data1.middle, y=data1.qty, template = 'plotly_dark', text = data1.qty)\n",
      "  File \"C:\\Users\\admin\\Anaconda3\\lib\\site-packages\\plotly\\express\\_chart_types.py\", line 354, in bar\n",
      "    layout_patch=dict(barmode=barmode),\n",
      "  File \"C:\\Users\\admin\\Anaconda3\\lib\\site-packages\\plotly\\express\\_core.py\", line 1861, in make_figure\n",
      "    args = build_dataframe(args, constructor)\n",
      "  File \"C:\\Users\\admin\\Anaconda3\\lib\\site-packages\\plotly\\express\\_core.py\", line 1300, in build_dataframe\n",
      "    \"Cannot accept list of column references or list of columns for both `x` and `y`.\"\n",
      "ValueError: Cannot accept list of column references or list of columns for both `x` and `y`.\n",
      "Exception on /_dash-update-component [POST]\n",
      "Traceback (most recent call last):\n",
      "  File \"C:\\Users\\admin\\Anaconda3\\lib\\site-packages\\flask\\app.py\", line 2446, in wsgi_app\n",
      "    response = self.full_dispatch_request()\n",
      "  File \"C:\\Users\\admin\\Anaconda3\\lib\\site-packages\\flask\\app.py\", line 1951, in full_dispatch_request\n",
      "    rv = self.handle_user_exception(e)\n",
      "  File \"C:\\Users\\admin\\Anaconda3\\lib\\site-packages\\flask\\app.py\", line 1820, in handle_user_exception\n",
      "    reraise(exc_type, exc_value, tb)\n",
      "  File \"C:\\Users\\admin\\Anaconda3\\lib\\site-packages\\flask\\_compat.py\", line 39, in reraise\n",
      "    raise value\n",
      "  File \"C:\\Users\\admin\\Anaconda3\\lib\\site-packages\\flask\\app.py\", line 1949, in full_dispatch_request\n",
      "    rv = self.dispatch_request()\n",
      "  File \"C:\\Users\\admin\\Anaconda3\\lib\\site-packages\\flask\\app.py\", line 1935, in dispatch_request\n",
      "    return self.view_functions[rule.endpoint](**req.view_args)\n",
      "  File \"C:\\Users\\admin\\Anaconda3\\lib\\site-packages\\dash\\dash.py\", line 1079, in dispatch\n",
      "    response.set_data(func(*args, outputs_list=outputs_list))\n",
      "  File \"C:\\Users\\admin\\Anaconda3\\lib\\site-packages\\dash\\dash.py\", line 1010, in add_context\n",
      "    output_value = func(*args, **kwargs)  # %% callback invoked %%\n",
      "  File \"<ipython-input-19-a827d4c88365>\", line 74, in bar_graph_sex\n",
      "    fig = px.bar(data1, x=data1.middle, y=data1.qty, template = 'plotly_dark', text = data1.qty)\n",
      "  File \"C:\\Users\\admin\\Anaconda3\\lib\\site-packages\\plotly\\express\\_chart_types.py\", line 354, in bar\n",
      "    layout_patch=dict(barmode=barmode),\n",
      "  File \"C:\\Users\\admin\\Anaconda3\\lib\\site-packages\\plotly\\express\\_core.py\", line 1861, in make_figure\n",
      "    args = build_dataframe(args, constructor)\n",
      "  File \"C:\\Users\\admin\\Anaconda3\\lib\\site-packages\\plotly\\express\\_core.py\", line 1300, in build_dataframe\n",
      "    \"Cannot accept list of column references or list of columns for both `x` and `y`.\"\n",
      "ValueError: Cannot accept list of column references or list of columns for both `x` and `y`.\n",
      "Exception on /_dash-update-component [POST]\n",
      "Traceback (most recent call last):\n",
      "  File \"C:\\Users\\admin\\Anaconda3\\lib\\site-packages\\flask\\app.py\", line 2446, in wsgi_app\n",
      "    response = self.full_dispatch_request()\n",
      "  File \"C:\\Users\\admin\\Anaconda3\\lib\\site-packages\\flask\\app.py\", line 1951, in full_dispatch_request\n",
      "    rv = self.handle_user_exception(e)\n",
      "  File \"C:\\Users\\admin\\Anaconda3\\lib\\site-packages\\flask\\app.py\", line 1820, in handle_user_exception\n",
      "    reraise(exc_type, exc_value, tb)\n",
      "  File \"C:\\Users\\admin\\Anaconda3\\lib\\site-packages\\flask\\_compat.py\", line 39, in reraise\n",
      "    raise value\n",
      "  File \"C:\\Users\\admin\\Anaconda3\\lib\\site-packages\\flask\\app.py\", line 1949, in full_dispatch_request\n",
      "    rv = self.dispatch_request()\n",
      "  File \"C:\\Users\\admin\\Anaconda3\\lib\\site-packages\\flask\\app.py\", line 1935, in dispatch_request\n",
      "    return self.view_functions[rule.endpoint](**req.view_args)\n",
      "  File \"C:\\Users\\admin\\Anaconda3\\lib\\site-packages\\dash\\dash.py\", line 1079, in dispatch\n",
      "    response.set_data(func(*args, outputs_list=outputs_list))\n",
      "  File \"C:\\Users\\admin\\Anaconda3\\lib\\site-packages\\dash\\dash.py\", line 1010, in add_context\n",
      "    output_value = func(*args, **kwargs)  # %% callback invoked %%\n",
      "  File \"<ipython-input-19-a827d4c88365>\", line 43, in bar_graph_age\n",
      "    fig = px.bar(data1, x=data1.middle, y=data1.qty, template = 'plotly_dark', text = data1.qty)\n",
      "  File \"C:\\Users\\admin\\Anaconda3\\lib\\site-packages\\plotly\\express\\_chart_types.py\", line 354, in bar\n",
      "    layout_patch=dict(barmode=barmode),\n",
      "  File \"C:\\Users\\admin\\Anaconda3\\lib\\site-packages\\plotly\\express\\_core.py\", line 1861, in make_figure\n",
      "    args = build_dataframe(args, constructor)\n",
      "  File \"C:\\Users\\admin\\Anaconda3\\lib\\site-packages\\plotly\\express\\_core.py\", line 1300, in build_dataframe\n",
      "    \"Cannot accept list of column references or list of columns for both `x` and `y`.\"\n",
      "ValueError: Cannot accept list of column references or list of columns for both `x` and `y`.\n",
      "Exception on /_dash-update-component [POST]\n",
      "Traceback (most recent call last):\n",
      "  File \"C:\\Users\\admin\\Anaconda3\\lib\\site-packages\\flask\\app.py\", line 2446, in wsgi_app\n",
      "    response = self.full_dispatch_request()\n",
      "  File \"C:\\Users\\admin\\Anaconda3\\lib\\site-packages\\flask\\app.py\", line 1951, in full_dispatch_request\n",
      "    rv = self.handle_user_exception(e)\n",
      "  File \"C:\\Users\\admin\\Anaconda3\\lib\\site-packages\\flask\\app.py\", line 1820, in handle_user_exception\n",
      "    reraise(exc_type, exc_value, tb)\n",
      "  File \"C:\\Users\\admin\\Anaconda3\\lib\\site-packages\\flask\\_compat.py\", line 39, in reraise\n",
      "    raise value\n",
      "  File \"C:\\Users\\admin\\Anaconda3\\lib\\site-packages\\flask\\app.py\", line 1949, in full_dispatch_request\n",
      "    rv = self.dispatch_request()\n",
      "  File \"C:\\Users\\admin\\Anaconda3\\lib\\site-packages\\flask\\app.py\", line 1935, in dispatch_request\n",
      "    return self.view_functions[rule.endpoint](**req.view_args)\n",
      "  File \"C:\\Users\\admin\\Anaconda3\\lib\\site-packages\\dash\\dash.py\", line 1079, in dispatch\n",
      "    response.set_data(func(*args, outputs_list=outputs_list))\n",
      "  File \"C:\\Users\\admin\\Anaconda3\\lib\\site-packages\\dash\\dash.py\", line 1010, in add_context\n",
      "    output_value = func(*args, **kwargs)  # %% callback invoked %%\n",
      "  File \"<ipython-input-19-a827d4c88365>\", line 74, in bar_graph_sex\n",
      "    fig = px.bar(data1, x=data1.middle, y=data1.qty, template = 'plotly_dark', text = data1.qty)\n",
      "  File \"C:\\Users\\admin\\Anaconda3\\lib\\site-packages\\plotly\\express\\_chart_types.py\", line 354, in bar\n",
      "    layout_patch=dict(barmode=barmode),\n",
      "  File \"C:\\Users\\admin\\Anaconda3\\lib\\site-packages\\plotly\\express\\_core.py\", line 1861, in make_figure\n",
      "    args = build_dataframe(args, constructor)\n",
      "  File \"C:\\Users\\admin\\Anaconda3\\lib\\site-packages\\plotly\\express\\_core.py\", line 1300, in build_dataframe\n",
      "    \"Cannot accept list of column references or list of columns for both `x` and `y`.\"\n",
      "ValueError: Cannot accept list of column references or list of columns for both `x` and `y`.\n",
      "Exception on /_dash-update-component [POST]\n",
      "Traceback (most recent call last):\n",
      "  File \"C:\\Users\\admin\\Anaconda3\\lib\\site-packages\\flask\\app.py\", line 2446, in wsgi_app\n",
      "    response = self.full_dispatch_request()\n",
      "  File \"C:\\Users\\admin\\Anaconda3\\lib\\site-packages\\flask\\app.py\", line 1951, in full_dispatch_request\n",
      "    rv = self.handle_user_exception(e)\n",
      "  File \"C:\\Users\\admin\\Anaconda3\\lib\\site-packages\\flask\\app.py\", line 1820, in handle_user_exception\n",
      "    reraise(exc_type, exc_value, tb)\n",
      "  File \"C:\\Users\\admin\\Anaconda3\\lib\\site-packages\\flask\\_compat.py\", line 39, in reraise\n",
      "    raise value\n",
      "  File \"C:\\Users\\admin\\Anaconda3\\lib\\site-packages\\flask\\app.py\", line 1949, in full_dispatch_request\n",
      "    rv = self.dispatch_request()\n",
      "  File \"C:\\Users\\admin\\Anaconda3\\lib\\site-packages\\flask\\app.py\", line 1935, in dispatch_request\n",
      "    return self.view_functions[rule.endpoint](**req.view_args)\n",
      "  File \"C:\\Users\\admin\\Anaconda3\\lib\\site-packages\\dash\\dash.py\", line 1079, in dispatch\n",
      "    response.set_data(func(*args, outputs_list=outputs_list))\n",
      "  File \"C:\\Users\\admin\\Anaconda3\\lib\\site-packages\\dash\\dash.py\", line 1010, in add_context\n",
      "    output_value = func(*args, **kwargs)  # %% callback invoked %%\n",
      "  File \"<ipython-input-19-a827d4c88365>\", line 43, in bar_graph_age\n",
      "    fig = px.bar(data1, x=data1.middle, y=data1.qty, template = 'plotly_dark', text = data1.qty)\n",
      "  File \"C:\\Users\\admin\\Anaconda3\\lib\\site-packages\\plotly\\express\\_chart_types.py\", line 354, in bar\n",
      "    layout_patch=dict(barmode=barmode),\n",
      "  File \"C:\\Users\\admin\\Anaconda3\\lib\\site-packages\\plotly\\express\\_core.py\", line 1861, in make_figure\n",
      "    args = build_dataframe(args, constructor)\n",
      "  File \"C:\\Users\\admin\\Anaconda3\\lib\\site-packages\\plotly\\express\\_core.py\", line 1300, in build_dataframe\n",
      "    \"Cannot accept list of column references or list of columns for both `x` and `y`.\"\n",
      "ValueError: Cannot accept list of column references or list of columns for both `x` and `y`.\n",
      "Exception on /_dash-update-component [POST]\n",
      "Traceback (most recent call last):\n",
      "  File \"C:\\Users\\admin\\Anaconda3\\lib\\site-packages\\flask\\app.py\", line 2446, in wsgi_app\n",
      "    response = self.full_dispatch_request()\n",
      "  File \"C:\\Users\\admin\\Anaconda3\\lib\\site-packages\\flask\\app.py\", line 1951, in full_dispatch_request\n",
      "    rv = self.handle_user_exception(e)\n",
      "  File \"C:\\Users\\admin\\Anaconda3\\lib\\site-packages\\flask\\app.py\", line 1820, in handle_user_exception\n",
      "    reraise(exc_type, exc_value, tb)\n",
      "  File \"C:\\Users\\admin\\Anaconda3\\lib\\site-packages\\flask\\_compat.py\", line 39, in reraise\n",
      "    raise value\n",
      "  File \"C:\\Users\\admin\\Anaconda3\\lib\\site-packages\\flask\\app.py\", line 1949, in full_dispatch_request\n",
      "    rv = self.dispatch_request()\n",
      "  File \"C:\\Users\\admin\\Anaconda3\\lib\\site-packages\\flask\\app.py\", line 1935, in dispatch_request\n",
      "    return self.view_functions[rule.endpoint](**req.view_args)\n",
      "  File \"C:\\Users\\admin\\Anaconda3\\lib\\site-packages\\dash\\dash.py\", line 1079, in dispatch\n",
      "    response.set_data(func(*args, outputs_list=outputs_list))\n",
      "  File \"C:\\Users\\admin\\Anaconda3\\lib\\site-packages\\dash\\dash.py\", line 1010, in add_context\n",
      "    output_value = func(*args, **kwargs)  # %% callback invoked %%\n",
      "  File \"<ipython-input-19-a827d4c88365>\", line 74, in bar_graph_sex\n",
      "    fig = px.bar(data1, x=data1.middle, y=data1.qty, template = 'plotly_dark', text = data1.qty)\n",
      "  File \"C:\\Users\\admin\\Anaconda3\\lib\\site-packages\\plotly\\express\\_chart_types.py\", line 354, in bar\n",
      "    layout_patch=dict(barmode=barmode),\n",
      "  File \"C:\\Users\\admin\\Anaconda3\\lib\\site-packages\\plotly\\express\\_core.py\", line 1861, in make_figure\n",
      "    args = build_dataframe(args, constructor)\n",
      "  File \"C:\\Users\\admin\\Anaconda3\\lib\\site-packages\\plotly\\express\\_core.py\", line 1300, in build_dataframe\n",
      "    \"Cannot accept list of column references or list of columns for both `x` and `y`.\"\n",
      "ValueError: Cannot accept list of column references or list of columns for both `x` and `y`.\n",
      "Exception on /_dash-update-component [POST]\n",
      "Traceback (most recent call last):\n",
      "  File \"C:\\Users\\admin\\Anaconda3\\lib\\site-packages\\flask\\app.py\", line 2446, in wsgi_app\n",
      "    response = self.full_dispatch_request()\n",
      "  File \"C:\\Users\\admin\\Anaconda3\\lib\\site-packages\\flask\\app.py\", line 1951, in full_dispatch_request\n",
      "    rv = self.handle_user_exception(e)\n",
      "  File \"C:\\Users\\admin\\Anaconda3\\lib\\site-packages\\flask\\app.py\", line 1820, in handle_user_exception\n",
      "    reraise(exc_type, exc_value, tb)\n",
      "  File \"C:\\Users\\admin\\Anaconda3\\lib\\site-packages\\flask\\_compat.py\", line 39, in reraise\n",
      "    raise value\n",
      "  File \"C:\\Users\\admin\\Anaconda3\\lib\\site-packages\\flask\\app.py\", line 1949, in full_dispatch_request\n",
      "    rv = self.dispatch_request()\n",
      "  File \"C:\\Users\\admin\\Anaconda3\\lib\\site-packages\\flask\\app.py\", line 1935, in dispatch_request\n",
      "    return self.view_functions[rule.endpoint](**req.view_args)\n",
      "  File \"C:\\Users\\admin\\Anaconda3\\lib\\site-packages\\dash\\dash.py\", line 1079, in dispatch\n",
      "    response.set_data(func(*args, outputs_list=outputs_list))\n",
      "  File \"C:\\Users\\admin\\Anaconda3\\lib\\site-packages\\dash\\dash.py\", line 1010, in add_context\n",
      "    output_value = func(*args, **kwargs)  # %% callback invoked %%\n",
      "  File \"<ipython-input-19-a827d4c88365>\", line 43, in bar_graph_age\n",
      "    fig = px.bar(data1, x=data1.middle, y=data1.qty, template = 'plotly_dark', text = data1.qty)\n",
      "  File \"C:\\Users\\admin\\Anaconda3\\lib\\site-packages\\plotly\\express\\_chart_types.py\", line 354, in bar\n",
      "    layout_patch=dict(barmode=barmode),\n",
      "  File \"C:\\Users\\admin\\Anaconda3\\lib\\site-packages\\plotly\\express\\_core.py\", line 1861, in make_figure\n",
      "    args = build_dataframe(args, constructor)\n",
      "  File \"C:\\Users\\admin\\Anaconda3\\lib\\site-packages\\plotly\\express\\_core.py\", line 1300, in build_dataframe\n",
      "    \"Cannot accept list of column references or list of columns for both `x` and `y`.\"\n",
      "ValueError: Cannot accept list of column references or list of columns for both `x` and `y`.\n",
      "Exception on /_dash-update-component [POST]\n",
      "Traceback (most recent call last):\n",
      "  File \"C:\\Users\\admin\\Anaconda3\\lib\\site-packages\\flask\\app.py\", line 2446, in wsgi_app\n",
      "    response = self.full_dispatch_request()\n",
      "  File \"C:\\Users\\admin\\Anaconda3\\lib\\site-packages\\flask\\app.py\", line 1951, in full_dispatch_request\n",
      "    rv = self.handle_user_exception(e)\n",
      "  File \"C:\\Users\\admin\\Anaconda3\\lib\\site-packages\\flask\\app.py\", line 1820, in handle_user_exception\n",
      "    reraise(exc_type, exc_value, tb)\n",
      "  File \"C:\\Users\\admin\\Anaconda3\\lib\\site-packages\\flask\\_compat.py\", line 39, in reraise\n",
      "    raise value\n",
      "  File \"C:\\Users\\admin\\Anaconda3\\lib\\site-packages\\flask\\app.py\", line 1949, in full_dispatch_request\n",
      "    rv = self.dispatch_request()\n",
      "  File \"C:\\Users\\admin\\Anaconda3\\lib\\site-packages\\flask\\app.py\", line 1935, in dispatch_request\n",
      "    return self.view_functions[rule.endpoint](**req.view_args)\n",
      "  File \"C:\\Users\\admin\\Anaconda3\\lib\\site-packages\\dash\\dash.py\", line 1079, in dispatch\n",
      "    response.set_data(func(*args, outputs_list=outputs_list))\n",
      "  File \"C:\\Users\\admin\\Anaconda3\\lib\\site-packages\\dash\\dash.py\", line 1010, in add_context\n",
      "    output_value = func(*args, **kwargs)  # %% callback invoked %%\n",
      "  File \"<ipython-input-19-a827d4c88365>\", line 74, in bar_graph_sex\n",
      "    fig = px.bar(data1, x=data1.middle, y=data1.qty, template = 'plotly_dark', text = data1.qty)\n",
      "  File \"C:\\Users\\admin\\Anaconda3\\lib\\site-packages\\plotly\\express\\_chart_types.py\", line 354, in bar\n",
      "    layout_patch=dict(barmode=barmode),\n",
      "  File \"C:\\Users\\admin\\Anaconda3\\lib\\site-packages\\plotly\\express\\_core.py\", line 1861, in make_figure\n",
      "    args = build_dataframe(args, constructor)\n",
      "  File \"C:\\Users\\admin\\Anaconda3\\lib\\site-packages\\plotly\\express\\_core.py\", line 1300, in build_dataframe\n",
      "    \"Cannot accept list of column references or list of columns for both `x` and `y`.\"\n",
      "ValueError: Cannot accept list of column references or list of columns for both `x` and `y`.\n"
     ]
    },
    {
     "name": "stderr",
     "output_type": "stream",
     "text": [
      "192.168.0.129 - - [03/Jun/2021 16:30:01] \"POST /_dash-update-component HTTP/1.1\" 500 -\n"
     ]
    },
    {
     "name": "stdout",
     "output_type": "stream",
     "text": [
      "Exception on /_dash-update-component [POST]\n",
      "Traceback (most recent call last):\n",
      "  File \"C:\\Users\\admin\\Anaconda3\\lib\\site-packages\\flask\\app.py\", line 2446, in wsgi_app\n",
      "    response = self.full_dispatch_request()\n",
      "  File \"C:\\Users\\admin\\Anaconda3\\lib\\site-packages\\flask\\app.py\", line 1951, in full_dispatch_request\n",
      "    rv = self.handle_user_exception(e)\n",
      "  File \"C:\\Users\\admin\\Anaconda3\\lib\\site-packages\\flask\\app.py\", line 1820, in handle_user_exception\n",
      "    reraise(exc_type, exc_value, tb)\n",
      "  File \"C:\\Users\\admin\\Anaconda3\\lib\\site-packages\\flask\\_compat.py\", line 39, in reraise\n",
      "    raise value\n",
      "  File \"C:\\Users\\admin\\Anaconda3\\lib\\site-packages\\flask\\app.py\", line 1949, in full_dispatch_request\n",
      "    rv = self.dispatch_request()\n",
      "  File \"C:\\Users\\admin\\Anaconda3\\lib\\site-packages\\flask\\app.py\", line 1935, in dispatch_request\n",
      "    return self.view_functions[rule.endpoint](**req.view_args)\n",
      "  File \"C:\\Users\\admin\\Anaconda3\\lib\\site-packages\\dash\\dash.py\", line 1079, in dispatch\n",
      "    response.set_data(func(*args, outputs_list=outputs_list))\n",
      "  File \"C:\\Users\\admin\\Anaconda3\\lib\\site-packages\\dash\\dash.py\", line 1010, in add_context\n",
      "    output_value = func(*args, **kwargs)  # %% callback invoked %%\n",
      "  File \"<ipython-input-19-a827d4c88365>\", line 74, in bar_graph_sex\n",
      "    fig = px.bar(data1, x=data1.middle, y=data1.qty, template = 'plotly_dark', text = data1.qty)\n",
      "  File \"C:\\Users\\admin\\Anaconda3\\lib\\site-packages\\plotly\\express\\_chart_types.py\", line 354, in bar\n",
      "    layout_patch=dict(barmode=barmode),\n",
      "  File \"C:\\Users\\admin\\Anaconda3\\lib\\site-packages\\plotly\\express\\_core.py\", line 1861, in make_figure\n",
      "    args = build_dataframe(args, constructor)\n",
      "  File \"C:\\Users\\admin\\Anaconda3\\lib\\site-packages\\plotly\\express\\_core.py\", line 1300, in build_dataframe\n",
      "    \"Cannot accept list of column references or list of columns for both `x` and `y`.\"\n",
      "ValueError: Cannot accept list of column references or list of columns for both `x` and `y`.\n"
     ]
    },
    {
     "name": "stderr",
     "output_type": "stream",
     "text": [
      "192.168.0.129 - - [03/Jun/2021 16:30:01] \"POST /_dash-update-component HTTP/1.1\" 500 -\n"
     ]
    },
    {
     "name": "stdout",
     "output_type": "stream",
     "text": [
      "Exception on /_dash-update-component [POST]\n",
      "Traceback (most recent call last):\n",
      "  File \"C:\\Users\\admin\\Anaconda3\\lib\\site-packages\\flask\\app.py\", line 2446, in wsgi_app\n",
      "    response = self.full_dispatch_request()\n",
      "  File \"C:\\Users\\admin\\Anaconda3\\lib\\site-packages\\flask\\app.py\", line 1951, in full_dispatch_request\n",
      "    rv = self.handle_user_exception(e)\n",
      "  File \"C:\\Users\\admin\\Anaconda3\\lib\\site-packages\\flask\\app.py\", line 1820, in handle_user_exception\n",
      "    reraise(exc_type, exc_value, tb)\n",
      "  File \"C:\\Users\\admin\\Anaconda3\\lib\\site-packages\\flask\\_compat.py\", line 39, in reraise\n",
      "    raise value\n",
      "  File \"C:\\Users\\admin\\Anaconda3\\lib\\site-packages\\flask\\app.py\", line 1949, in full_dispatch_request\n",
      "    rv = self.dispatch_request()\n",
      "  File \"C:\\Users\\admin\\Anaconda3\\lib\\site-packages\\flask\\app.py\", line 1935, in dispatch_request\n",
      "    return self.view_functions[rule.endpoint](**req.view_args)\n",
      "  File \"C:\\Users\\admin\\Anaconda3\\lib\\site-packages\\dash\\dash.py\", line 1079, in dispatch\n",
      "    response.set_data(func(*args, outputs_list=outputs_list))\n",
      "  File \"C:\\Users\\admin\\Anaconda3\\lib\\site-packages\\dash\\dash.py\", line 1010, in add_context\n",
      "    output_value = func(*args, **kwargs)  # %% callback invoked %%\n",
      "  File \"<ipython-input-19-a827d4c88365>\", line 111, in pie_graph_product\n",
      "    data3.columns = ['판매량','여부']\n",
      "  File \"C:\\Users\\admin\\Anaconda3\\lib\\site-packages\\pandas\\core\\generic.py\", line 5192, in __setattr__\n",
      "    return object.__setattr__(self, name, value)\n",
      "  File \"pandas\\_libs\\properties.pyx\", line 67, in pandas._libs.properties.AxisProperty.__set__\n",
      "  File \"C:\\Users\\admin\\Anaconda3\\lib\\site-packages\\pandas\\core\\generic.py\", line 690, in _set_axis\n",
      "    self._data.set_axis(axis, labels)\n",
      "  File \"C:\\Users\\admin\\Anaconda3\\lib\\site-packages\\pandas\\core\\internals\\managers.py\", line 183, in set_axis\n",
      "    \"values have {new} elements\".format(old=old_len, new=new_len)\n",
      "ValueError: Length mismatch: Expected axis has 1 elements, new values have 2 elements\n",
      "Exception on /_dash-update-component [POST]\n",
      "Traceback (most recent call last):\n",
      "  File \"C:\\Users\\admin\\Anaconda3\\lib\\site-packages\\flask\\app.py\", line 2446, in wsgi_app\n",
      "    response = self.full_dispatch_request()\n",
      "  File \"C:\\Users\\admin\\Anaconda3\\lib\\site-packages\\flask\\app.py\", line 1951, in full_dispatch_request\n",
      "    rv = self.handle_user_exception(e)\n",
      "  File \"C:\\Users\\admin\\Anaconda3\\lib\\site-packages\\flask\\app.py\", line 1820, in handle_user_exception\n",
      "    reraise(exc_type, exc_value, tb)\n",
      "  File \"C:\\Users\\admin\\Anaconda3\\lib\\site-packages\\flask\\_compat.py\", line 39, in reraise\n",
      "    raise value\n",
      "  File \"C:\\Users\\admin\\Anaconda3\\lib\\site-packages\\flask\\app.py\", line 1949, in full_dispatch_request\n",
      "    rv = self.dispatch_request()\n",
      "  File \"C:\\Users\\admin\\Anaconda3\\lib\\site-packages\\flask\\app.py\", line 1935, in dispatch_request\n",
      "    return self.view_functions[rule.endpoint](**req.view_args)\n",
      "  File \"C:\\Users\\admin\\Anaconda3\\lib\\site-packages\\dash\\dash.py\", line 1079, in dispatch\n",
      "    response.set_data(func(*args, outputs_list=outputs_list))\n",
      "  File \"C:\\Users\\admin\\Anaconda3\\lib\\site-packages\\dash\\dash.py\", line 1010, in add_context\n",
      "    output_value = func(*args, **kwargs)  # %% callback invoked %%\n",
      "  File \"<ipython-input-19-a827d4c88365>\", line 111, in pie_graph_product\n",
      "    data3.columns = ['판매량','여부']\n",
      "  File \"C:\\Users\\admin\\Anaconda3\\lib\\site-packages\\pandas\\core\\generic.py\", line 5192, in __setattr__\n",
      "    return object.__setattr__(self, name, value)\n",
      "  File \"pandas\\_libs\\properties.pyx\", line 67, in pandas._libs.properties.AxisProperty.__set__\n",
      "  File \"C:\\Users\\admin\\Anaconda3\\lib\\site-packages\\pandas\\core\\generic.py\", line 690, in _set_axis\n",
      "    self._data.set_axis(axis, labels)\n",
      "  File \"C:\\Users\\admin\\Anaconda3\\lib\\site-packages\\pandas\\core\\internals\\managers.py\", line 183, in set_axis\n",
      "    \"values have {new} elements\".format(old=old_len, new=new_len)\n",
      "ValueError: Length mismatch: Expected axis has 1 elements, new values have 2 elements\n",
      "Exception on /_dash-update-component [POST]\n",
      "Traceback (most recent call last):\n",
      "  File \"C:\\Users\\admin\\Anaconda3\\lib\\site-packages\\flask\\app.py\", line 2446, in wsgi_app\n",
      "    response = self.full_dispatch_request()\n",
      "  File \"C:\\Users\\admin\\Anaconda3\\lib\\site-packages\\flask\\app.py\", line 1951, in full_dispatch_request\n",
      "    rv = self.handle_user_exception(e)\n",
      "  File \"C:\\Users\\admin\\Anaconda3\\lib\\site-packages\\flask\\app.py\", line 1820, in handle_user_exception\n",
      "    reraise(exc_type, exc_value, tb)\n",
      "  File \"C:\\Users\\admin\\Anaconda3\\lib\\site-packages\\flask\\_compat.py\", line 39, in reraise\n",
      "    raise value\n",
      "  File \"C:\\Users\\admin\\Anaconda3\\lib\\site-packages\\flask\\app.py\", line 1949, in full_dispatch_request\n",
      "    rv = self.dispatch_request()\n",
      "  File \"C:\\Users\\admin\\Anaconda3\\lib\\site-packages\\flask\\app.py\", line 1935, in dispatch_request\n",
      "    return self.view_functions[rule.endpoint](**req.view_args)\n",
      "  File \"C:\\Users\\admin\\Anaconda3\\lib\\site-packages\\dash\\dash.py\", line 1079, in dispatch\n",
      "    response.set_data(func(*args, outputs_list=outputs_list))\n",
      "  File \"C:\\Users\\admin\\Anaconda3\\lib\\site-packages\\dash\\dash.py\", line 1010, in add_context\n",
      "    output_value = func(*args, **kwargs)  # %% callback invoked %%\n",
      "  File \"<ipython-input-19-a827d4c88365>\", line 111, in pie_graph_product\n",
      "    data3.columns = ['판매량','여부']\n",
      "  File \"C:\\Users\\admin\\Anaconda3\\lib\\site-packages\\pandas\\core\\generic.py\", line 5192, in __setattr__\n",
      "    return object.__setattr__(self, name, value)\n",
      "  File \"pandas\\_libs\\properties.pyx\", line 67, in pandas._libs.properties.AxisProperty.__set__\n",
      "  File \"C:\\Users\\admin\\Anaconda3\\lib\\site-packages\\pandas\\core\\generic.py\", line 690, in _set_axis\n",
      "    self._data.set_axis(axis, labels)\n",
      "  File \"C:\\Users\\admin\\Anaconda3\\lib\\site-packages\\pandas\\core\\internals\\managers.py\", line 183, in set_axis\n",
      "    \"values have {new} elements\".format(old=old_len, new=new_len)\n",
      "ValueError: Length mismatch: Expected axis has 1 elements, new values have 2 elements\n",
      "Exception on /_dash-update-component [POST]\n",
      "Traceback (most recent call last):\n",
      "  File \"C:\\Users\\admin\\Anaconda3\\lib\\site-packages\\flask\\app.py\", line 2446, in wsgi_app\n",
      "    response = self.full_dispatch_request()\n",
      "  File \"C:\\Users\\admin\\Anaconda3\\lib\\site-packages\\flask\\app.py\", line 1951, in full_dispatch_request\n",
      "    rv = self.handle_user_exception(e)\n",
      "  File \"C:\\Users\\admin\\Anaconda3\\lib\\site-packages\\flask\\app.py\", line 1820, in handle_user_exception\n",
      "    reraise(exc_type, exc_value, tb)\n",
      "  File \"C:\\Users\\admin\\Anaconda3\\lib\\site-packages\\flask\\_compat.py\", line 39, in reraise\n",
      "    raise value\n",
      "  File \"C:\\Users\\admin\\Anaconda3\\lib\\site-packages\\flask\\app.py\", line 1949, in full_dispatch_request\n",
      "    rv = self.dispatch_request()\n",
      "  File \"C:\\Users\\admin\\Anaconda3\\lib\\site-packages\\flask\\app.py\", line 1935, in dispatch_request\n",
      "    return self.view_functions[rule.endpoint](**req.view_args)\n",
      "  File \"C:\\Users\\admin\\Anaconda3\\lib\\site-packages\\dash\\dash.py\", line 1079, in dispatch\n",
      "    response.set_data(func(*args, outputs_list=outputs_list))\n",
      "  File \"C:\\Users\\admin\\Anaconda3\\lib\\site-packages\\dash\\dash.py\", line 1010, in add_context\n",
      "    output_value = func(*args, **kwargs)  # %% callback invoked %%\n",
      "  File \"<ipython-input-19-a827d4c88365>\", line 111, in pie_graph_product\n",
      "    data3.columns = ['판매량','여부']\n",
      "  File \"C:\\Users\\admin\\Anaconda3\\lib\\site-packages\\pandas\\core\\generic.py\", line 5192, in __setattr__\n",
      "    return object.__setattr__(self, name, value)\n",
      "  File \"pandas\\_libs\\properties.pyx\", line 67, in pandas._libs.properties.AxisProperty.__set__\n",
      "  File \"C:\\Users\\admin\\Anaconda3\\lib\\site-packages\\pandas\\core\\generic.py\", line 690, in _set_axis\n",
      "    self._data.set_axis(axis, labels)\n",
      "  File \"C:\\Users\\admin\\Anaconda3\\lib\\site-packages\\pandas\\core\\internals\\managers.py\", line 183, in set_axis\n",
      "    \"values have {new} elements\".format(old=old_len, new=new_len)\n",
      "ValueError: Length mismatch: Expected axis has 1 elements, new values have 2 elements\n",
      "Exception on /_dash-update-component [POST]\n",
      "Traceback (most recent call last):\n",
      "  File \"C:\\Users\\admin\\Anaconda3\\lib\\site-packages\\flask\\app.py\", line 2446, in wsgi_app\n",
      "    response = self.full_dispatch_request()\n",
      "  File \"C:\\Users\\admin\\Anaconda3\\lib\\site-packages\\flask\\app.py\", line 1951, in full_dispatch_request\n",
      "    rv = self.handle_user_exception(e)\n",
      "  File \"C:\\Users\\admin\\Anaconda3\\lib\\site-packages\\flask\\app.py\", line 1820, in handle_user_exception\n",
      "    reraise(exc_type, exc_value, tb)\n",
      "  File \"C:\\Users\\admin\\Anaconda3\\lib\\site-packages\\flask\\_compat.py\", line 39, in reraise\n",
      "    raise value\n",
      "  File \"C:\\Users\\admin\\Anaconda3\\lib\\site-packages\\flask\\app.py\", line 1949, in full_dispatch_request\n",
      "    rv = self.dispatch_request()\n",
      "  File \"C:\\Users\\admin\\Anaconda3\\lib\\site-packages\\flask\\app.py\", line 1935, in dispatch_request\n",
      "    return self.view_functions[rule.endpoint](**req.view_args)\n",
      "  File \"C:\\Users\\admin\\Anaconda3\\lib\\site-packages\\dash\\dash.py\", line 1079, in dispatch\n",
      "    response.set_data(func(*args, outputs_list=outputs_list))\n",
      "  File \"C:\\Users\\admin\\Anaconda3\\lib\\site-packages\\dash\\dash.py\", line 1010, in add_context\n",
      "    output_value = func(*args, **kwargs)  # %% callback invoked %%\n",
      "  File \"<ipython-input-19-a827d4c88365>\", line 111, in pie_graph_product\n",
      "    data3.columns = ['판매량','여부']\n",
      "  File \"C:\\Users\\admin\\Anaconda3\\lib\\site-packages\\pandas\\core\\generic.py\", line 5192, in __setattr__\n",
      "    return object.__setattr__(self, name, value)\n",
      "  File \"pandas\\_libs\\properties.pyx\", line 67, in pandas._libs.properties.AxisProperty.__set__\n",
      "  File \"C:\\Users\\admin\\Anaconda3\\lib\\site-packages\\pandas\\core\\generic.py\", line 690, in _set_axis\n",
      "    self._data.set_axis(axis, labels)\n",
      "  File \"C:\\Users\\admin\\Anaconda3\\lib\\site-packages\\pandas\\core\\internals\\managers.py\", line 183, in set_axis\n",
      "    \"values have {new} elements\".format(old=old_len, new=new_len)\n",
      "ValueError: Length mismatch: Expected axis has 1 elements, new values have 2 elements\n"
     ]
    },
    {
     "name": "stderr",
     "output_type": "stream",
     "text": [
      "192.168.0.129 - - [03/Jun/2021 16:30:02] \"POST /_dash-update-component HTTP/1.1\" 500 -\n"
     ]
    },
    {
     "name": "stdout",
     "output_type": "stream",
     "text": [
      "Exception on /_dash-update-component [POST]\n",
      "Traceback (most recent call last):\n",
      "  File \"C:\\Users\\admin\\Anaconda3\\lib\\site-packages\\flask\\app.py\", line 2446, in wsgi_app\n",
      "    response = self.full_dispatch_request()\n",
      "  File \"C:\\Users\\admin\\Anaconda3\\lib\\site-packages\\flask\\app.py\", line 1951, in full_dispatch_request\n",
      "    rv = self.handle_user_exception(e)\n",
      "  File \"C:\\Users\\admin\\Anaconda3\\lib\\site-packages\\flask\\app.py\", line 1820, in handle_user_exception\n",
      "    reraise(exc_type, exc_value, tb)\n",
      "  File \"C:\\Users\\admin\\Anaconda3\\lib\\site-packages\\flask\\_compat.py\", line 39, in reraise\n",
      "    raise value\n",
      "  File \"C:\\Users\\admin\\Anaconda3\\lib\\site-packages\\flask\\app.py\", line 1949, in full_dispatch_request\n",
      "    rv = self.dispatch_request()\n",
      "  File \"C:\\Users\\admin\\Anaconda3\\lib\\site-packages\\flask\\app.py\", line 1935, in dispatch_request\n",
      "    return self.view_functions[rule.endpoint](**req.view_args)\n",
      "  File \"C:\\Users\\admin\\Anaconda3\\lib\\site-packages\\dash\\dash.py\", line 1079, in dispatch\n",
      "    response.set_data(func(*args, outputs_list=outputs_list))\n",
      "  File \"C:\\Users\\admin\\Anaconda3\\lib\\site-packages\\dash\\dash.py\", line 1010, in add_context\n",
      "    output_value = func(*args, **kwargs)  # %% callback invoked %%\n",
      "  File \"<ipython-input-19-a827d4c88365>\", line 43, in bar_graph_age\n",
      "    fig = px.bar(data1, x=data1.middle, y=data1.qty, template = 'plotly_dark', text = data1.qty)\n",
      "  File \"C:\\Users\\admin\\Anaconda3\\lib\\site-packages\\plotly\\express\\_chart_types.py\", line 354, in bar\n",
      "    layout_patch=dict(barmode=barmode),\n",
      "  File \"C:\\Users\\admin\\Anaconda3\\lib\\site-packages\\plotly\\express\\_core.py\", line 1861, in make_figure\n",
      "    args = build_dataframe(args, constructor)\n",
      "  File \"C:\\Users\\admin\\Anaconda3\\lib\\site-packages\\plotly\\express\\_core.py\", line 1300, in build_dataframe\n",
      "    \"Cannot accept list of column references or list of columns for both `x` and `y`.\"\n",
      "ValueError: Cannot accept list of column references or list of columns for both `x` and `y`.\n",
      "Exception on /_dash-update-component [POST]\n",
      "Traceback (most recent call last):\n",
      "  File \"C:\\Users\\admin\\Anaconda3\\lib\\site-packages\\flask\\app.py\", line 2446, in wsgi_app\n",
      "    response = self.full_dispatch_request()\n",
      "  File \"C:\\Users\\admin\\Anaconda3\\lib\\site-packages\\flask\\app.py\", line 1951, in full_dispatch_request\n",
      "    rv = self.handle_user_exception(e)\n",
      "  File \"C:\\Users\\admin\\Anaconda3\\lib\\site-packages\\flask\\app.py\", line 1820, in handle_user_exception\n",
      "    reraise(exc_type, exc_value, tb)\n",
      "  File \"C:\\Users\\admin\\Anaconda3\\lib\\site-packages\\flask\\_compat.py\", line 39, in reraise\n",
      "    raise value\n",
      "  File \"C:\\Users\\admin\\Anaconda3\\lib\\site-packages\\flask\\app.py\", line 1949, in full_dispatch_request\n",
      "    rv = self.dispatch_request()\n",
      "  File \"C:\\Users\\admin\\Anaconda3\\lib\\site-packages\\flask\\app.py\", line 1935, in dispatch_request\n",
      "    return self.view_functions[rule.endpoint](**req.view_args)\n",
      "  File \"C:\\Users\\admin\\Anaconda3\\lib\\site-packages\\dash\\dash.py\", line 1079, in dispatch\n",
      "    response.set_data(func(*args, outputs_list=outputs_list))\n",
      "  File \"C:\\Users\\admin\\Anaconda3\\lib\\site-packages\\dash\\dash.py\", line 1010, in add_context\n",
      "    output_value = func(*args, **kwargs)  # %% callback invoked %%\n",
      "  File \"<ipython-input-19-a827d4c88365>\", line 43, in bar_graph_age\n",
      "    fig = px.bar(data1, x=data1.middle, y=data1.qty, template = 'plotly_dark', text = data1.qty)\n",
      "  File \"C:\\Users\\admin\\Anaconda3\\lib\\site-packages\\plotly\\express\\_chart_types.py\", line 354, in bar\n",
      "    layout_patch=dict(barmode=barmode),\n",
      "  File \"C:\\Users\\admin\\Anaconda3\\lib\\site-packages\\plotly\\express\\_core.py\", line 1861, in make_figure\n",
      "    args = build_dataframe(args, constructor)\n",
      "  File \"C:\\Users\\admin\\Anaconda3\\lib\\site-packages\\plotly\\express\\_core.py\", line 1300, in build_dataframe\n",
      "    \"Cannot accept list of column references or list of columns for both `x` and `y`.\"\n",
      "ValueError: Cannot accept list of column references or list of columns for both `x` and `y`.\n"
     ]
    },
    {
     "name": "stderr",
     "output_type": "stream",
     "text": [
      "192.168.0.129 - - [03/Jun/2021 16:30:03] \"POST /_dash-update-component HTTP/1.1\" 200 -\n"
     ]
    },
    {
     "name": "stdout",
     "output_type": "stream",
     "text": [
      "Exception on /_dash-update-component [POST]\n",
      "Traceback (most recent call last):\n",
      "  File \"C:\\Users\\admin\\Anaconda3\\lib\\site-packages\\flask\\app.py\", line 2446, in wsgi_app\n",
      "    response = self.full_dispatch_request()\n",
      "  File \"C:\\Users\\admin\\Anaconda3\\lib\\site-packages\\flask\\app.py\", line 1951, in full_dispatch_request\n",
      "    rv = self.handle_user_exception(e)\n",
      "  File \"C:\\Users\\admin\\Anaconda3\\lib\\site-packages\\flask\\app.py\", line 1820, in handle_user_exception\n",
      "    reraise(exc_type, exc_value, tb)\n",
      "  File \"C:\\Users\\admin\\Anaconda3\\lib\\site-packages\\flask\\_compat.py\", line 39, in reraise\n",
      "    raise value\n",
      "  File \"C:\\Users\\admin\\Anaconda3\\lib\\site-packages\\flask\\app.py\", line 1949, in full_dispatch_request\n",
      "    rv = self.dispatch_request()\n",
      "  File \"C:\\Users\\admin\\Anaconda3\\lib\\site-packages\\flask\\app.py\", line 1935, in dispatch_request\n",
      "    return self.view_functions[rule.endpoint](**req.view_args)\n",
      "  File \"C:\\Users\\admin\\Anaconda3\\lib\\site-packages\\dash\\dash.py\", line 1079, in dispatch\n",
      "    response.set_data(func(*args, outputs_list=outputs_list))\n",
      "  File \"C:\\Users\\admin\\Anaconda3\\lib\\site-packages\\dash\\dash.py\", line 1010, in add_context\n",
      "    output_value = func(*args, **kwargs)  # %% callback invoked %%\n",
      "  File \"<ipython-input-19-a827d4c88365>\", line 43, in bar_graph_age\n",
      "    fig = px.bar(data1, x=data1.middle, y=data1.qty, template = 'plotly_dark', text = data1.qty)\n",
      "  File \"C:\\Users\\admin\\Anaconda3\\lib\\site-packages\\plotly\\express\\_chart_types.py\", line 354, in bar\n",
      "    layout_patch=dict(barmode=barmode),\n",
      "  File \"C:\\Users\\admin\\Anaconda3\\lib\\site-packages\\plotly\\express\\_core.py\", line 1861, in make_figure\n",
      "    args = build_dataframe(args, constructor)\n",
      "  File \"C:\\Users\\admin\\Anaconda3\\lib\\site-packages\\plotly\\express\\_core.py\", line 1300, in build_dataframe\n",
      "    \"Cannot accept list of column references or list of columns for both `x` and `y`.\"\n",
      "ValueError: Cannot accept list of column references or list of columns for both `x` and `y`.\n",
      "Exception on /_dash-update-component [POST]\n",
      "Traceback (most recent call last):\n",
      "  File \"C:\\Users\\admin\\Anaconda3\\lib\\site-packages\\flask\\app.py\", line 2446, in wsgi_app\n",
      "    response = self.full_dispatch_request()\n",
      "  File \"C:\\Users\\admin\\Anaconda3\\lib\\site-packages\\flask\\app.py\", line 1951, in full_dispatch_request\n",
      "    rv = self.handle_user_exception(e)\n",
      "  File \"C:\\Users\\admin\\Anaconda3\\lib\\site-packages\\flask\\app.py\", line 1820, in handle_user_exception\n",
      "    reraise(exc_type, exc_value, tb)\n",
      "  File \"C:\\Users\\admin\\Anaconda3\\lib\\site-packages\\flask\\_compat.py\", line 39, in reraise\n",
      "    raise value\n",
      "  File \"C:\\Users\\admin\\Anaconda3\\lib\\site-packages\\flask\\app.py\", line 1949, in full_dispatch_request\n",
      "    rv = self.dispatch_request()\n",
      "  File \"C:\\Users\\admin\\Anaconda3\\lib\\site-packages\\flask\\app.py\", line 1935, in dispatch_request\n",
      "    return self.view_functions[rule.endpoint](**req.view_args)\n",
      "  File \"C:\\Users\\admin\\Anaconda3\\lib\\site-packages\\dash\\dash.py\", line 1079, in dispatch\n",
      "    response.set_data(func(*args, outputs_list=outputs_list))\n",
      "  File \"C:\\Users\\admin\\Anaconda3\\lib\\site-packages\\dash\\dash.py\", line 1010, in add_context\n",
      "    output_value = func(*args, **kwargs)  # %% callback invoked %%\n",
      "  File \"<ipython-input-19-a827d4c88365>\", line 43, in bar_graph_age\n",
      "    fig = px.bar(data1, x=data1.middle, y=data1.qty, template = 'plotly_dark', text = data1.qty)\n",
      "  File \"C:\\Users\\admin\\Anaconda3\\lib\\site-packages\\plotly\\express\\_chart_types.py\", line 354, in bar\n",
      "    layout_patch=dict(barmode=barmode),\n",
      "  File \"C:\\Users\\admin\\Anaconda3\\lib\\site-packages\\plotly\\express\\_core.py\", line 1861, in make_figure\n",
      "    args = build_dataframe(args, constructor)\n",
      "  File \"C:\\Users\\admin\\Anaconda3\\lib\\site-packages\\plotly\\express\\_core.py\", line 1300, in build_dataframe\n",
      "    \"Cannot accept list of column references or list of columns for both `x` and `y`.\"\n",
      "ValueError: Cannot accept list of column references or list of columns for both `x` and `y`.\n",
      "Exception on /_dash-update-component [POST]\n",
      "Traceback (most recent call last):\n",
      "  File \"C:\\Users\\admin\\Anaconda3\\lib\\site-packages\\flask\\app.py\", line 2446, in wsgi_app\n",
      "    response = self.full_dispatch_request()\n",
      "  File \"C:\\Users\\admin\\Anaconda3\\lib\\site-packages\\flask\\app.py\", line 1951, in full_dispatch_request\n",
      "    rv = self.handle_user_exception(e)\n",
      "  File \"C:\\Users\\admin\\Anaconda3\\lib\\site-packages\\flask\\app.py\", line 1820, in handle_user_exception\n",
      "    reraise(exc_type, exc_value, tb)\n",
      "  File \"C:\\Users\\admin\\Anaconda3\\lib\\site-packages\\flask\\_compat.py\", line 39, in reraise\n",
      "    raise value\n",
      "  File \"C:\\Users\\admin\\Anaconda3\\lib\\site-packages\\flask\\app.py\", line 1949, in full_dispatch_request\n",
      "    rv = self.dispatch_request()\n",
      "  File \"C:\\Users\\admin\\Anaconda3\\lib\\site-packages\\flask\\app.py\", line 1935, in dispatch_request\n",
      "    return self.view_functions[rule.endpoint](**req.view_args)\n",
      "  File \"C:\\Users\\admin\\Anaconda3\\lib\\site-packages\\dash\\dash.py\", line 1079, in dispatch\n",
      "    response.set_data(func(*args, outputs_list=outputs_list))\n",
      "  File \"C:\\Users\\admin\\Anaconda3\\lib\\site-packages\\dash\\dash.py\", line 1010, in add_context\n",
      "    output_value = func(*args, **kwargs)  # %% callback invoked %%\n",
      "  File \"<ipython-input-19-a827d4c88365>\", line 43, in bar_graph_age\n",
      "    fig = px.bar(data1, x=data1.middle, y=data1.qty, template = 'plotly_dark', text = data1.qty)\n",
      "  File \"C:\\Users\\admin\\Anaconda3\\lib\\site-packages\\plotly\\express\\_chart_types.py\", line 354, in bar\n",
      "    layout_patch=dict(barmode=barmode),\n",
      "  File \"C:\\Users\\admin\\Anaconda3\\lib\\site-packages\\plotly\\express\\_core.py\", line 1861, in make_figure\n",
      "    args = build_dataframe(args, constructor)\n",
      "  File \"C:\\Users\\admin\\Anaconda3\\lib\\site-packages\\plotly\\express\\_core.py\", line 1300, in build_dataframe\n",
      "    \"Cannot accept list of column references or list of columns for both `x` and `y`.\"\n",
      "ValueError: Cannot accept list of column references or list of columns for both `x` and `y`.\n"
     ]
    },
    {
     "name": "stderr",
     "output_type": "stream",
     "text": [
      "192.168.0.129 - - [03/Jun/2021 16:30:03] \"POST /_dash-update-component HTTP/1.1\" 500 -\n",
      "192.168.0.129 - - [03/Jun/2021 16:30:04] \"POST /_dash-update-component HTTP/1.1\" 200 -\n"
     ]
    },
    {
     "name": "stdout",
     "output_type": "stream",
     "text": [
      "Exception on /_dash-update-component [POST]\n",
      "Traceback (most recent call last):\n",
      "  File \"C:\\Users\\admin\\Anaconda3\\lib\\site-packages\\flask\\app.py\", line 2446, in wsgi_app\n",
      "    response = self.full_dispatch_request()\n",
      "  File \"C:\\Users\\admin\\Anaconda3\\lib\\site-packages\\flask\\app.py\", line 1951, in full_dispatch_request\n",
      "    rv = self.handle_user_exception(e)\n",
      "  File \"C:\\Users\\admin\\Anaconda3\\lib\\site-packages\\flask\\app.py\", line 1820, in handle_user_exception\n",
      "    reraise(exc_type, exc_value, tb)\n",
      "  File \"C:\\Users\\admin\\Anaconda3\\lib\\site-packages\\flask\\_compat.py\", line 39, in reraise\n",
      "    raise value\n",
      "  File \"C:\\Users\\admin\\Anaconda3\\lib\\site-packages\\flask\\app.py\", line 1949, in full_dispatch_request\n",
      "    rv = self.dispatch_request()\n",
      "  File \"C:\\Users\\admin\\Anaconda3\\lib\\site-packages\\flask\\app.py\", line 1935, in dispatch_request\n",
      "    return self.view_functions[rule.endpoint](**req.view_args)\n",
      "  File \"C:\\Users\\admin\\Anaconda3\\lib\\site-packages\\dash\\dash.py\", line 1079, in dispatch\n",
      "    response.set_data(func(*args, outputs_list=outputs_list))\n",
      "  File \"C:\\Users\\admin\\Anaconda3\\lib\\site-packages\\dash\\dash.py\", line 1010, in add_context\n",
      "    output_value = func(*args, **kwargs)  # %% callback invoked %%\n",
      "  File \"<ipython-input-19-a827d4c88365>\", line 74, in bar_graph_sex\n",
      "    fig = px.bar(data1, x=data1.middle, y=data1.qty, template = 'plotly_dark', text = data1.qty)\n",
      "  File \"C:\\Users\\admin\\Anaconda3\\lib\\site-packages\\plotly\\express\\_chart_types.py\", line 354, in bar\n",
      "    layout_patch=dict(barmode=barmode),\n",
      "  File \"C:\\Users\\admin\\Anaconda3\\lib\\site-packages\\plotly\\express\\_core.py\", line 1861, in make_figure\n",
      "    args = build_dataframe(args, constructor)\n",
      "  File \"C:\\Users\\admin\\Anaconda3\\lib\\site-packages\\plotly\\express\\_core.py\", line 1300, in build_dataframe\n",
      "    \"Cannot accept list of column references or list of columns for both `x` and `y`.\"\n",
      "ValueError: Cannot accept list of column references or list of columns for both `x` and `y`.\n",
      "Exception on /_dash-update-component [POST]\n",
      "Traceback (most recent call last):\n",
      "  File \"C:\\Users\\admin\\Anaconda3\\lib\\site-packages\\flask\\app.py\", line 2446, in wsgi_app\n",
      "    response = self.full_dispatch_request()\n",
      "  File \"C:\\Users\\admin\\Anaconda3\\lib\\site-packages\\flask\\app.py\", line 1951, in full_dispatch_request\n",
      "    rv = self.handle_user_exception(e)\n",
      "  File \"C:\\Users\\admin\\Anaconda3\\lib\\site-packages\\flask\\app.py\", line 1820, in handle_user_exception\n",
      "    reraise(exc_type, exc_value, tb)\n",
      "  File \"C:\\Users\\admin\\Anaconda3\\lib\\site-packages\\flask\\_compat.py\", line 39, in reraise\n",
      "    raise value\n",
      "  File \"C:\\Users\\admin\\Anaconda3\\lib\\site-packages\\flask\\app.py\", line 1949, in full_dispatch_request\n",
      "    rv = self.dispatch_request()\n",
      "  File \"C:\\Users\\admin\\Anaconda3\\lib\\site-packages\\flask\\app.py\", line 1935, in dispatch_request\n",
      "    return self.view_functions[rule.endpoint](**req.view_args)\n",
      "  File \"C:\\Users\\admin\\Anaconda3\\lib\\site-packages\\dash\\dash.py\", line 1079, in dispatch\n",
      "    response.set_data(func(*args, outputs_list=outputs_list))\n",
      "  File \"C:\\Users\\admin\\Anaconda3\\lib\\site-packages\\dash\\dash.py\", line 1010, in add_context\n",
      "    output_value = func(*args, **kwargs)  # %% callback invoked %%\n",
      "  File \"<ipython-input-19-a827d4c88365>\", line 74, in bar_graph_sex\n",
      "    fig = px.bar(data1, x=data1.middle, y=data1.qty, template = 'plotly_dark', text = data1.qty)\n",
      "  File \"C:\\Users\\admin\\Anaconda3\\lib\\site-packages\\plotly\\express\\_chart_types.py\", line 354, in bar\n",
      "    layout_patch=dict(barmode=barmode),\n",
      "  File \"C:\\Users\\admin\\Anaconda3\\lib\\site-packages\\plotly\\express\\_core.py\", line 1861, in make_figure\n",
      "    args = build_dataframe(args, constructor)\n",
      "  File \"C:\\Users\\admin\\Anaconda3\\lib\\site-packages\\plotly\\express\\_core.py\", line 1300, in build_dataframe\n",
      "    \"Cannot accept list of column references or list of columns for both `x` and `y`.\"\n",
      "ValueError: Cannot accept list of column references or list of columns for both `x` and `y`.\n",
      "Exception on /_dash-update-component [POST]\n",
      "Traceback (most recent call last):\n",
      "  File \"C:\\Users\\admin\\Anaconda3\\lib\\site-packages\\flask\\app.py\", line 2446, in wsgi_app\n",
      "    response = self.full_dispatch_request()\n",
      "  File \"C:\\Users\\admin\\Anaconda3\\lib\\site-packages\\flask\\app.py\", line 1951, in full_dispatch_request\n",
      "    rv = self.handle_user_exception(e)\n",
      "  File \"C:\\Users\\admin\\Anaconda3\\lib\\site-packages\\flask\\app.py\", line 1820, in handle_user_exception\n",
      "    reraise(exc_type, exc_value, tb)\n",
      "  File \"C:\\Users\\admin\\Anaconda3\\lib\\site-packages\\flask\\_compat.py\", line 39, in reraise\n",
      "    raise value\n",
      "  File \"C:\\Users\\admin\\Anaconda3\\lib\\site-packages\\flask\\app.py\", line 1949, in full_dispatch_request\n",
      "    rv = self.dispatch_request()\n",
      "  File \"C:\\Users\\admin\\Anaconda3\\lib\\site-packages\\flask\\app.py\", line 1935, in dispatch_request\n",
      "    return self.view_functions[rule.endpoint](**req.view_args)\n",
      "  File \"C:\\Users\\admin\\Anaconda3\\lib\\site-packages\\dash\\dash.py\", line 1079, in dispatch\n",
      "    response.set_data(func(*args, outputs_list=outputs_list))\n",
      "  File \"C:\\Users\\admin\\Anaconda3\\lib\\site-packages\\dash\\dash.py\", line 1010, in add_context\n",
      "    output_value = func(*args, **kwargs)  # %% callback invoked %%\n",
      "  File \"<ipython-input-19-a827d4c88365>\", line 74, in bar_graph_sex\n",
      "    fig = px.bar(data1, x=data1.middle, y=data1.qty, template = 'plotly_dark', text = data1.qty)\n",
      "  File \"C:\\Users\\admin\\Anaconda3\\lib\\site-packages\\plotly\\express\\_chart_types.py\", line 354, in bar\n",
      "    layout_patch=dict(barmode=barmode),\n",
      "  File \"C:\\Users\\admin\\Anaconda3\\lib\\site-packages\\plotly\\express\\_core.py\", line 1861, in make_figure\n",
      "    args = build_dataframe(args, constructor)\n",
      "  File \"C:\\Users\\admin\\Anaconda3\\lib\\site-packages\\plotly\\express\\_core.py\", line 1300, in build_dataframe\n",
      "    \"Cannot accept list of column references or list of columns for both `x` and `y`.\"\n",
      "ValueError: Cannot accept list of column references or list of columns for both `x` and `y`.\n",
      "Exception on /_dash-update-component [POST]\n",
      "Traceback (most recent call last):\n",
      "  File \"C:\\Users\\admin\\Anaconda3\\lib\\site-packages\\flask\\app.py\", line 2446, in wsgi_app\n",
      "    response = self.full_dispatch_request()\n",
      "  File \"C:\\Users\\admin\\Anaconda3\\lib\\site-packages\\flask\\app.py\", line 1951, in full_dispatch_request\n",
      "    rv = self.handle_user_exception(e)\n",
      "  File \"C:\\Users\\admin\\Anaconda3\\lib\\site-packages\\flask\\app.py\", line 1820, in handle_user_exception\n",
      "    reraise(exc_type, exc_value, tb)\n",
      "  File \"C:\\Users\\admin\\Anaconda3\\lib\\site-packages\\flask\\_compat.py\", line 39, in reraise\n",
      "    raise value\n",
      "  File \"C:\\Users\\admin\\Anaconda3\\lib\\site-packages\\flask\\app.py\", line 1949, in full_dispatch_request\n",
      "    rv = self.dispatch_request()\n",
      "  File \"C:\\Users\\admin\\Anaconda3\\lib\\site-packages\\flask\\app.py\", line 1935, in dispatch_request\n",
      "    return self.view_functions[rule.endpoint](**req.view_args)\n",
      "  File \"C:\\Users\\admin\\Anaconda3\\lib\\site-packages\\dash\\dash.py\", line 1079, in dispatch\n",
      "    response.set_data(func(*args, outputs_list=outputs_list))\n",
      "  File \"C:\\Users\\admin\\Anaconda3\\lib\\site-packages\\dash\\dash.py\", line 1010, in add_context\n",
      "    output_value = func(*args, **kwargs)  # %% callback invoked %%\n",
      "  File \"<ipython-input-19-a827d4c88365>\", line 74, in bar_graph_sex\n",
      "    fig = px.bar(data1, x=data1.middle, y=data1.qty, template = 'plotly_dark', text = data1.qty)\n",
      "  File \"C:\\Users\\admin\\Anaconda3\\lib\\site-packages\\plotly\\express\\_chart_types.py\", line 354, in bar\n",
      "    layout_patch=dict(barmode=barmode),\n",
      "  File \"C:\\Users\\admin\\Anaconda3\\lib\\site-packages\\plotly\\express\\_core.py\", line 1861, in make_figure\n",
      "    args = build_dataframe(args, constructor)\n",
      "  File \"C:\\Users\\admin\\Anaconda3\\lib\\site-packages\\plotly\\express\\_core.py\", line 1300, in build_dataframe\n",
      "    \"Cannot accept list of column references or list of columns for both `x` and `y`.\"\n",
      "ValueError: Cannot accept list of column references or list of columns for both `x` and `y`.\n",
      "Exception on /_dash-update-component [POST]\n",
      "Traceback (most recent call last):\n",
      "  File \"C:\\Users\\admin\\Anaconda3\\lib\\site-packages\\flask\\app.py\", line 2446, in wsgi_app\n",
      "    response = self.full_dispatch_request()\n",
      "  File \"C:\\Users\\admin\\Anaconda3\\lib\\site-packages\\flask\\app.py\", line 1951, in full_dispatch_request\n",
      "    rv = self.handle_user_exception(e)\n",
      "  File \"C:\\Users\\admin\\Anaconda3\\lib\\site-packages\\flask\\app.py\", line 1820, in handle_user_exception\n",
      "    reraise(exc_type, exc_value, tb)\n",
      "  File \"C:\\Users\\admin\\Anaconda3\\lib\\site-packages\\flask\\_compat.py\", line 39, in reraise\n",
      "    raise value\n",
      "  File \"C:\\Users\\admin\\Anaconda3\\lib\\site-packages\\flask\\app.py\", line 1949, in full_dispatch_request\n",
      "    rv = self.dispatch_request()\n",
      "  File \"C:\\Users\\admin\\Anaconda3\\lib\\site-packages\\flask\\app.py\", line 1935, in dispatch_request\n",
      "    return self.view_functions[rule.endpoint](**req.view_args)\n",
      "  File \"C:\\Users\\admin\\Anaconda3\\lib\\site-packages\\dash\\dash.py\", line 1079, in dispatch\n",
      "    response.set_data(func(*args, outputs_list=outputs_list))\n",
      "  File \"C:\\Users\\admin\\Anaconda3\\lib\\site-packages\\dash\\dash.py\", line 1010, in add_context\n",
      "    output_value = func(*args, **kwargs)  # %% callback invoked %%\n",
      "  File \"<ipython-input-19-a827d4c88365>\", line 74, in bar_graph_sex\n",
      "    fig = px.bar(data1, x=data1.middle, y=data1.qty, template = 'plotly_dark', text = data1.qty)\n",
      "  File \"C:\\Users\\admin\\Anaconda3\\lib\\site-packages\\plotly\\express\\_chart_types.py\", line 354, in bar\n",
      "    layout_patch=dict(barmode=barmode),\n",
      "  File \"C:\\Users\\admin\\Anaconda3\\lib\\site-packages\\plotly\\express\\_core.py\", line 1861, in make_figure\n",
      "    args = build_dataframe(args, constructor)\n",
      "  File \"C:\\Users\\admin\\Anaconda3\\lib\\site-packages\\plotly\\express\\_core.py\", line 1300, in build_dataframe\n",
      "    \"Cannot accept list of column references or list of columns for both `x` and `y`.\"\n",
      "ValueError: Cannot accept list of column references or list of columns for both `x` and `y`.\n"
     ]
    },
    {
     "name": "stderr",
     "output_type": "stream",
     "text": [
      "192.168.0.129 - - [03/Jun/2021 16:30:04] \"POST /_dash-update-component HTTP/1.1\" 500 -\n",
      "192.168.0.129 - - [03/Jun/2021 16:30:05] \"POST /_dash-update-component HTTP/1.1\" 200 -\n",
      "192.168.0.129 - - [03/Jun/2021 16:30:05] \"POST /_dash-update-component HTTP/1.1\" 200 -\n",
      "192.168.0.129 - - [03/Jun/2021 16:30:05] \"POST /_dash-update-component HTTP/1.1\" 200 -\n"
     ]
    }
   ],
   "source": [
    "app.run_server(host='192.168.0.129',port='7777')"
   ]
  },
  {
   "cell_type": "code",
   "execution_count": null,
   "id": "7c14cf5c",
   "metadata": {},
   "outputs": [],
   "source": []
  },
  {
   "cell_type": "code",
   "execution_count": null,
   "id": "623ce18f",
   "metadata": {},
   "outputs": [],
   "source": []
  }
 ],
 "metadata": {
  "kernelspec": {
   "display_name": "Python 3 (ipykernel)",
   "language": "python",
   "name": "python3"
  },
  "language_info": {
   "codemirror_mode": {
    "name": "ipython",
    "version": 3
   },
   "file_extension": ".py",
   "mimetype": "text/x-python",
   "name": "python",
   "nbconvert_exporter": "python",
   "pygments_lexer": "ipython3",
   "version": "3.9.7"
  }
 },
 "nbformat": 4,
 "nbformat_minor": 5
}
